Workbook

Sheet 읽는 법
A1: 2일차 엑셀 검산본 — 실습 확인표를 엑셀 수식으로 다시 계산
A3: 무엇 | B3: 실습 A 확인표(슬라이드 d2-70) 여섯 줄을 사람이 엑셀만으로 계산했다면 어떻게 나오는지 보여 주는 완성본입니다. 확인표_B 시트는 실습 B 확인표(d2-73)의 30일 창 · 바이어 수를 같은 방법으로 셉니다.
A4: 왜 | B4: AI(Claude Code)가 스크립트로 만든 d2_buyers_clean.csv · d2_end_features.csv의 숫자를 코드가 아닌 다른 길로 한 번 더 확인하는 기준입니다. 정답지가 아닙니다 — 다르면 어느 규칙에서 갈렸는지 찾는 것이 실습입니다. 엑셀을 직접 만들 필요는 없습니다.
A5: 칸 색 | B5: 노란 칸 = 수식(칸을 누르면 수식 막대에 수식이 보입니다) · 회색 칸 = d2_start.xlsx의 원래 값 그대로 · 흰 칸 = 내가 적는 칸(선택).
A6: 어떻게 만들었나 | B6: buyers_원본 · 환율_기준일 · 뉴스_앞100행 시트에 공개 파일(d2_start.xlsx · d2_news.csv)의 값을 고치지 않고 옮기고, 나머지는 모두 수식입니다. 기준일 2026-08-31, 환율은 그날 값(엔화는 100엔당 값이라 ÷100). 검산에 쓰지 않는 열(결제방식 · 국가 · 연령 구간 일부 · 재무 외 열)은 옮기지 않았습니다.
A7: 시트 | B7: B001_손계산 — 인쇄 단계 05의 'B001 손계산'을 수식으로 · B009(글자 섞인 칸) · B072(단위 의심)도 확인표_A — 실습 A 확인표 여섯 줄 + 통화 표기 9가지 → 표준 4종 확인표_B — 실습 B의 30일 창 (2026-08-01, 2026-08-31] 기사 · 바이어 수 buyers_원본 · 환율_기준일 · 뉴스_앞100행 — 원래 값과 보조 열(노란 칸)
A8: 엑셀이 못 하는 것 | B8: 글자가 섞인 금액 13칸(' 195900 ' · 'CNY 317,000' · '47.0k' …)은 수식으로 숫자를 만들지 않고 '글자 섞임'으로만 표시합니다. 엑셀로는 이 칸을 사람이 하나씩 고쳐야 합니다 — 그래서 규칙을 문서로 정하고 스크립트로 고칩니다.
A9: 주의 | B9: 이 파일은 고치지 말고 읽기만 합니다(필요하면 사본을 만들어 씁니다). 숫자가 내 결과와 다르면 '어느 규칙에서 갈렸나'를 AI에게 먼저 묻습니다.
A10: 데이터 | B10: (가상) 한빛정밀(주)의 합성 데이터 · CC BY 4.0. 환율은 미국 연준 H.10 환율(FRED 제공) · Public Domain: Citation Requested.

Sheet B001_손계산
A1: B001 손계산 — 인쇄 단계 05의 'B001 손계산'을 대신하는 완성본
A2: 노란 칸을 눌러 수식을 봅니다. 원하면 흰 칸(B13)에 =18100*1589.5/1368.25 를 한 번 직접 쳐 봅니다(1분).
A4: 항목 | B4: 값 | C4: 어디서 · 수식 | D4: 메모
A5: B001 잔액(원래 통화) | B5: ='buyers_원본'!C2 -> 18100 | C5: buyers_원본 C2 | D5: ='buyers_원본'!B2 -> EUR
A6: 기준일 EUR 환율(원) | B6: ='환율_기준일'!E5 -> 1589.5 | C6: 환율_기준일 E5(2026-08-31)
A7: 기준일 USD 환율(원) | B7: ='환율_기준일'!E4 -> 1368.25 | C7: 환율_기준일 E4(2026-08-31)
A8: B001 ar_balance_usd | B8: =ROUND(B5*B6/B7,2) -> 21026.82 | C8: 수식: ROUND(잔액 × EUR ÷ USD, 2) | D8: 확인표: 21,026.82
A9: 확인표 기대값(인쇄 d2-70) | B9: 21026.82
A10: 같음? | B10: =IF(ABS(B8-B9)<0.005,"같음","다름") -> 같음
A12: 내 CSV의 B001 ar_balance_usd(직접 적기 · 선택) | C12: =IF(B12="","",IF(ABS(B12-B8)<0.005,"엑셀과 같음","엑셀과 다름 — 어느 규칙에서 갈렸나?"))
A13: 직접 쳐 보기(선택 · 1분) | C13: 이 행의 흰 칸 B13에 =18100*1589.5/1368.25 를 칩니다
A15: B009 — 글자가 섞인 칸
A16: 원래 칸(글자) | B16: ='buyers_원본'!C10 -> CNY 317,000 | C16: buyers_원본 C10 — 수식으로는 숫자가 되지 않는다
A17: 사람이 읽은 숫자 | B17: 317000 | C17: 규칙 2칸: 통화 글자 · 쉼표를 지우고 숫자로(사람이 정한 규칙)
A18: 기준일 CNY 환율(원) | B18: ='환율_기준일'!E6 -> 203.62 | C18: 환율_기준일 E6
A19: B009 ar_balance_usd | B19: =ROUND(B17*B18/B7,2) -> 47175.25 | C19: 수식: ROUND(숫자 × CNY ÷ USD, 2) | D19: 47,175.25
A21: B072 — 단위 의심(잔액 > 신용한도 × 10)
A22: 원래 잔액 | B22: ='buyers_원본'!C73 -> 8320000 | C22: buyers_원본 C73 | D22: ='buyers_원본'!B73 -> euro
A23: 신용한도(USD) | B23: ='buyers_원본'!F73 -> 10000 | C23: buyers_원본 F73
A24: USD 환산(그대로) | B24: =ROUND(B22*B6/B7,2) -> 9665368.2 | C24: 수식: ROUND(잔액 × EUR ÷ USD, 2)
A25: 한도 × 10 | B25: =B23*10 -> 100000 | C25: 규칙 4칸의 기준
A26: 단위 의심? | B26: =IF(B24>B25,"단위 의심 → ÷1,000","정상") -> 단위 의심 → ÷1,000 | C26: 환산한 뒤 한도와 비교(통화가 다르면 환산 먼저)
A27: ÷1,000 후 ar_balance_usd | B27: =ROUND(B24/1000,2) -> 9665.37 | C27: 확인표: 9,665.37

Sheet 확인표_A
A1: 실습 A 확인표(슬라이드 d2-70)를 엑셀 수식으로
A2: 노란 칸 = 수식 · 회색 칸 = 인쇄된 기대값 · 흰 칸 = 내 CSV 값을 적는 칸(선택). 엑셀 값은 대체(채우기) 전 150행 기준입니다.
A4: 1. 통화 표기 9가지 → 표준 4종(대응표 = buyers_원본 N열의 VLOOKUP이 쓰는 표)
A5: 원래 표기 | B5: 표준 코드 | C5: 칸 수(대소문자 구분 — EXACT)
A6: USD | B6: USD | C6: =SUMPRODUCT(--EXACT('buyers_원본'!$B$2:$B$151,A6)) -> 81
A7: US$ | B7: USD | C7: =SUMPRODUCT(--EXACT('buyers_원본'!$B$2:$B$151,A7)) -> 15
A8: usd | B8: USD | C8: =SUMPRODUCT(--EXACT('buyers_원본'!$B$2:$B$151,A8)) -> 14
A9: EUR | B9: EUR | C9: =SUMPRODUCT(--EXACT('buyers_원본'!$B$2:$B$151,A9)) -> 18
A10: euro | B10: EUR | C10: =SUMPRODUCT(--EXACT('buyers_원본'!$B$2:$B$151,A10)) -> 5
A11: JPY | B11: JPY | C11: =SUMPRODUCT(--EXACT('buyers_원본'!$B$2:$B$151,A11)) -> 8
A12: yen | B12: JPY | C12: =SUMPRODUCT(--EXACT('buyers_원본'!$B$2:$B$151,A12)) -> 2
A13: CNY | B13: CNY | C13: =SUMPRODUCT(--EXACT('buyers_원본'!$B$2:$B$151,A13)) -> 5
A14: RMB | B14: CNY | C14: =SUMPRODUCT(--EXACT('buyers_원본'!$B$2:$B$151,A14)) -> 2
A15: 합계 | C15: =SUM(C6:C14) -> 150
A16: 표준 4종이 아닌 칸(정제 전) | C16: =C15-(C6+C9+C11+C13) -> 38
A18: 표준 코드 | B18: 바이어 수(수식) | C18: 확인표 기대값 | D18: 같음?
A19: USD | B19: =COUNTIF('buyers_원본'!$N$2:$N$151,A19) -> 110 | C19: 110 | D19: =IF(B19=C19,"같음","다름") -> 같음
A20: EUR | B20: =COUNTIF('buyers_원본'!$N$2:$N$151,A20) -> 23 | C20: 23 | D20: =IF(B20=C20,"같음","다름") -> 같음
A21: JPY | B21: =COUNTIF('buyers_원본'!$N$2:$N$151,A21) -> 10 | C21: 10 | D21: =IF(B21=C21,"같음","다름") -> 같음
A22: CNY | B22: =COUNTIF('buyers_원본'!$N$2:$N$151,A22) -> 7 | C22: 7 | D22: =IF(B22=C22,"같음","다름") -> 같음
A24: 2. 확인표 여섯 줄
A25: # | B25: 확인 | C25: 확인표 기대값(인쇄) | D25: 엑셀 검산(수식) | E25: 같음? | F25: 내 CSV 값(직접 적기 · 선택) | G25: 엑셀이 쓴 규칙
A26: 1 | B26: 통화 정리 | C26: USD 110 · EUR 23 · JPY 10 · CNY 7 | D26: ="USD "&B19&" · EUR "&B20&" · JPY "&B21&" · CNY "&B22 -> USD 110 · EUR 23 · JPY 10 · CNY 7 | E26: =IF(D26=C26,"같음","다름") -> 같음 | G26: 9가지 표기 → 4종(위 대응표)
A27: 2 | B27: B001 잔액(USD) | C27: 21026.82 | D27: ='B001_손계산'!B8 -> 21026.82 | E27: =IF(ABS(D27-C27)<0.005,"같음","다름") -> 같음 | G27: 기준일 2026-08-31 환율로 환산
A28: 3 | B28: 단위 의심 — 바이어 | C28: B072 | D28: =INDEX('buyers_원본'!$A$2:$A$151,MATCH(1,'buyers_원본'!$W$2:$W$151,0)) -> B072 | E28: =IF(D28=C28,"같음","다름") -> 같음 | G28: USD 환산 뒤 잔액 > 한도 × 10(글자 섞인 칸은 판정 안 함)
A29: 3 | B29: 단위 의심 — 곳 수(숫자 칸) | C29: 1 | D29: =SUM('buyers_원본'!$W$2:$W$151) -> 1 | E29: =IF(ABS(D29-C29)<0.5,"같음","다름") -> 같음
A30: 3 | B30: 단위 의심 — ÷1,000 후 USD | C30: 9665.37 | D30: ='B001_손계산'!B27 -> 9665.37 | E30: =IF(ABS(D30-C30)<0.005,"같음","다름") -> 같음
A31: 4 | B31: 자본잠식 — 곳 수 | C31: 2 | D31: =SUM('buyers_원본'!$Q$2:$Q$151) -> 2 | E31: =IF(ABS(D31-C31)<0.5,"같음","다름") -> 같음 | G31: 자기자본 ≤ 0 → 부채비율 빈칸
A32: 4 | B32: 자본잠식 — 첫째 | C32: B013 | D32: =INDEX('buyers_원본'!$A$2:$A$151,MATCH(1,'buyers_원본'!$X$2:$X$151,0)) -> B013 | E32: =IF(D32=C32,"같음","다름") -> 같음
A33: 4 | B33: 자본잠식 — 둘째 | C33: B048 | D33: =INDEX('buyers_원본'!$A$2:$A$151,MATCH(2,'buyers_원본'!$X$2:$X$151,0)) -> B048 | E33: =IF(D33=C33,"같음","다름") -> 같음
A34: 5 | B34: 결측 플래그 fin_missing | C34: 47 | D34: =SUM('buyers_원본'!$P$2:$P$151) -> 47 | E34: =IF(ABS(D34-C34)<0.5,"같음","다름") -> 같음 | G34: 유동자산·유동부채·총부채·자기자본·매출 중 하나라도 빈칸
A35: 5 | B35: 중앙값 current_ratio | C35: 1.4218 | D35: =ROUND(MEDIAN('buyers_원본'!$R$2:$R$151),4) -> 1.4218 | E35: =IF(ABS(D35-C35)<5e-05,"같음","다름") -> 같음 | G35: 대체 전 150행 · 빈칸 제외
A36: 5 | B36: 중앙값 debt_to_equity | C36: 1.4579 | D36: =ROUND(MEDIAN('buyers_원본'!$S$2:$S$151),4) -> 1.4579 | E36: =IF(ABS(D36-C36)<5e-05,"같음","다름") -> 같음 | G36: 자본잠식 2곳은 빈칸
A37: 5 | B37: 중앙값 dso_buyer | C37: 66.44 | D37: =ROUND(MEDIAN('buyers_원본'!$T$2:$T$151),2) -> 66.44 | E37: =IF(ABS(D37-C37)<0.005,"같음","다름") -> 같음 | G37: 매출채권 ÷ 매출 × 365
A38: 5 | B38: 중앙값 op_margin | C38: 0.0654 | D38: =ROUND(MEDIAN('buyers_원본'!$U$2:$U$151),4) -> 0.0654 | E38: =IF(ABS(D38-C38)<5e-05,"같음","다름") -> 같음 | G38: 영업이익 ÷ 매출
A39: 6 | B39: 기록 | C39: 테스트 통과 · 스케일 비교 표 · 커밋 2개+ · PR 1개(Closes #n) | D39: 엑셀로 보지 않는다 | G39: 터미널 uv run pytest -q · GitHub PR에서 확인
A41: 덧 | B41: 글자가 섞인 금액 칸(정제 전) | C41: 13 | D41: =SUM('buyers_원본'!$O$2:$O$151) -> 13 | E41: =IF(ABS(D41-C41)<0.5,"같음","다름") -> 같음 | G41: ar_balance 9 · ar_current 2 · ar_1_30 2 — 엑셀로는 사람이 하나씩 고쳐야 한다
B42: B009 ar_balance_usd(CNY 317,000) | C42: 47175.25 | D42: ='B001_손계산'!B19 -> 47175.25 | E42: =IF(ABS(D42-C42)<0.005,"같음","다름") -> 같음 | G42: 글자 섞인 칸 — 사람이 읽은 숫자로 계산(B001_손계산 시트)

Sheet 확인표_B
A1: 실습 B 확인표(슬라이드 d2-73) — 30일 창 (2026-08-01, 2026-08-31]의 기사 · 바이어 수
A2: d2_news.csv 앞 100행(실습 B가 채점하는 행)의 날짜로 셉니다. 점수 평균 · 평가 숫자는 사람마다 달라 엑셀로 보지 않습니다.
A4: 확인 | B4: 엑셀 검산(수식) | C4: 확인표 기대값 | D4: 같음? | E4: 내 결과(직접 적기 · 선택) | F4: 엑셀이 쓴 규칙
A5: 앞 100행의 가장 이른 날짜 | B5: =MIN('뉴스_앞100행'!$C$2:$C$101) -> 46195 | C5: 2026-06-22 | F5: 최신순 파일의 100번째 행
A6: 앞 100행의 가장 늦은 날짜 | B6: =MAX('뉴스_앞100행'!$C$2:$C$101) -> 46295 | C6: 2026-09-30
A7: 창 안 기사 수 | B7: =SUM('뉴스_앞100행'!$E$2:$E$101) -> 46 | C7: 46 | D7: =IF(ABS(B7-C7)<0.5,"같음","다름") -> 같음 | F7: date > 2026-08-01 이고 date ≤ 2026-08-31(8월 1일 빼고 31일 넣고)
A8: 창 안 바이어 수 | B8: =SUM('뉴스_앞100행'!$F$2:$F$101) -> 37 | C8: 37 | D8: =IF(ABS(B8-C8)<0.5,"같음","다름") -> 같음 | F8: 창 안 기사의 buyer_id 첫 등장만 센다
A9: 9월 기사(창 밖 — 특성에 들어가면 안 된다) | B9: =SUM('뉴스_앞100행'!$G$2:$G$101) -> 40 | C9: 40 | D9: =IF(ABS(B9-C9)<0.5,"같음","다름") -> 같음 | F9: 기준일 뒤 정보 — 특성표에는 0건이어야 한다
A10: 10월 이후 기사 | B10: =COUNTIF('뉴스_앞100행'!$C$2:$C$101,">"&DATE(2026,9,30)) -> 0 | C10: 0 | D10: =IF(ABS(B10-C10)<0.5,"같음","다름") -> 같음
A11: 뉴스 없는 바이어(150 − 창 안 바이어) | B11: =150-B8 -> 113 | C11: 113 | D11: =IF(ABS(B11-C11)<0.5,"같음","다름") -> 같음 | F11: LEFT JOIN 뒤 평균 5 + no_news_flag=1로 채운다
A12: B001 창 안 기사 수 | B12: =COUNTIFS('뉴스_앞100행'!$B$2:$B$101,"B001",'뉴스_앞100행'!$E$2:$E$101,1) -> 0 | C12: 0 | D12: =IF(ABS(B12-C12)<0.5,"같음","다름") -> 같음 | F12: 0건 → 평균 5.0 · no_news_flag 1
A14: 결합 뒤 행 수 | B14: 150(LEFT JOIN — 왼쪽 표 그대로) | F14: 150이 아니면 뉴스를 바이어별로 먼저 집계하지 않고 붙인 것(1:N)

Sheet buyers_원본
A1: buyer_id | B1: currency | C1: ar_balance | D1: ar_current | E1: ar_1_30 | F1: credit_limit_usd | G1: current_assets | H1: current_liabilities | I1: total_liabilities | J1: equity | K1: accounts_receivable | L1: revenue | M1: operating_income | N1: 통화_표준 | O1: 글자칸_수 | P1: fin_missing | Q1: neg_equity | R1: current_ratio | S1: debt_to_equity | T1: dso_buyer | U1: op_margin | V1: ar_balance_usd | W1: unit_flag | X1: neg_순번
A2: B001 | B2: EUR | C2: 18100 | D2: 18100 | E2: 0 | F2: 20000 | G2: 1618000 | H2: 992000 | I2: 1226000 | J2: 2041000 | K2: 652000 | L2: 6846000 | M2: 810000 | N2: =IFERROR(VLOOKUP(TRIM(B2),'확인표_A'!$A$6:$B$14,2,FALSE),"확인 필요") -> EUR | O2: =SUMPRODUCT(--ISTEXT(C2:E2)) -> 0 | P2: =IF(OR(G2="",H2="",I2="",J2="",L2=""),1,0) -> 0 | Q2: =IF(AND(J2<>"",J2<=0),1,0) -> 0 | R2: =IF(OR(G2="",H2=""),"",G2/H2) -> 1.6310484 | S2: =IF(OR(I2="",J2="",Q2=1),"",I2/J2) -> 0.60068594 | T2: =IF(OR(K2="",L2=""),"",K2/L2*365) -> 34.761905 | U2: =IF(OR(M2="",L2=""),"",M2/L2) -> 0.11831727 | V2: =IF(ISTEXT(C2),"글자 섞임",ROUND(C2*VLOOKUP(N2,'환율_기준일'!$A$4:$E$7,5,FALSE)/'환율_기준일'!$E$4,2)) -> 21026.82 | W2: =IF(ISNUMBER(V2),IF(V2>F2*10,1,0),"") -> 0 | X2: =IF(Q2=1,COUNTIF($Q$2:Q2,1),"")
A3: B002 | B3: usd | C3: 9170 | D3: 9170 | E3: 0 | F3: 20000 | G3: 2591000 | H3: 1462000 | I3: 2419000 | J3: 2364000 | K3: 935000 | L3: 8185000 | M3: 550000 | N3: =IFERROR(VLOOKUP(TRIM(B3),'확인표_A'!$A$6:$B$14,2,FALSE),"확인 필요") -> USD | O3: =SUMPRODUCT(--ISTEXT(C3:E3)) -> 0 | P3: =IF(OR(G3="",H3="",I3="",J3="",L3=""),1,0) -> 0 | Q3: =IF(AND(J3<>"",J3<=0),1,0) -> 0 | R3: =IF(OR(G3="",H3=""),"",G3/H3) -> 1.7722298 | S3: =IF(OR(I3="",J3="",Q3=1),"",I3/J3) -> 1.0232657 | T3: =IF(OR(K3="",L3=""),"",K3/L3*365) -> 41.695174 | U3: =IF(OR(M3="",L3=""),"",M3/L3) -> 0.06719609 | V3: =IF(ISTEXT(C3),"글자 섞임",ROUND(C3*VLOOKUP(N3,'환율_기준일'!$A$4:$E$7,5,FALSE)/'환율_기준일'!$E$4,2)) -> 9170 | W3: =IF(ISNUMBER(V3),IF(V3>F3*10,1,0),"") -> 0 | X3: =IF(Q3=1,COUNTIF($Q$2:Q3,1),"")
A4: B003 | B4: USD | C4: 0 | D4: 0 | E4: 0 | F4: 20000 | G4: 2451000 | H4: 1695000 | I4: 3638000 | K4: 1181000 | L4: 5343000 | M4: -278000 | N4: =IFERROR(VLOOKUP(TRIM(B4),'확인표_A'!$A$6:$B$14,2,FALSE),"확인 필요") -> USD | O4: =SUMPRODUCT(--ISTEXT(C4:E4)) -> 0 | P4: =IF(OR(G4="",H4="",I4="",J4="",L4=""),1,0) -> 1 | Q4: =IF(AND(J4<>"",J4<=0),1,0) -> 0 | R4: =IF(OR(G4="",H4=""),"",G4/H4) -> 1.4460177 | S4: =IF(OR(I4="",J4="",Q4=1),"",I4/J4) | T4: =IF(OR(K4="",L4=""),"",K4/L4*365) -> 80.678458 | U4: =IF(OR(M4="",L4=""),"",M4/L4) -> -0.052030694 | V4: =IF(ISTEXT(C4),"글자 섞임",ROUND(C4*VLOOKUP(N4,'환율_기준일'!$A$4:$E$7,5,FALSE)/'환율_기준일'!$E$4,2)) -> 0 | W4: =IF(ISNUMBER(V4),IF(V4>F4*10,1,0),"") -> 0 | X4: =IF(Q4=1,COUNTIF($Q$2:Q4,1),"")
A5: B004 | B5: USD | C5: 0 | D5: 0 | E5: 0 | F5: 10000 | G5: 18128000 | H5: 8321000 | I5: 15234000 | J5: 11515000 | K5: 6139000 | L5: 73932000 | M5: 5344000 | N5: =IFERROR(VLOOKUP(TRIM(B5),'확인표_A'!$A$6:$B$14,2,FALSE),"확인 필요") -> USD | O5: =SUMPRODUCT(--ISTEXT(C5:E5)) -> 0 | P5: =IF(OR(G5="",H5="",I5="",J5="",L5=""),1,0) -> 0 | Q5: =IF(AND(J5<>"",J5<=0),1,0) -> 0 | R5: =IF(OR(G5="",H5=""),"",G5/H5) -> 2.1785843 | S5: =IF(OR(I5="",J5="",Q5=1),"",I5/J5) -> 1.32297 | T5: =IF(OR(K5="",L5=""),"",K5/L5*365) -> 30.308053 | U5: =IF(OR(M5="",L5=""),"",M5/L5) -> 0.072282638 | V5: =IF(ISTEXT(C5),"글자 섞임",ROUND(C5*VLOOKUP(N5,'환율_기준일'!$A$4:$E$7,5,FALSE)/'환율_기준일'!$E$4,2)) -> 0 | W5: =IF(ISNUMBER(V5),IF(V5>F5*10,1,0),"") -> 0 | X5: =IF(Q5=1,COUNTIF($Q$2:Q5,1),"")
A6: B005 | B6: USD | C6: 195900 | D6: 173020 | E6: 22880 | F6: 200000 | G6: 51211000 | I6: 39364000 | J6: 40519000 | K6: 17583000 | L6: 204875000 | M6: 27396000 | N6: =IFERROR(VLOOKUP(TRIM(B6),'확인표_A'!$A$6:$B$14,2,FALSE),"확인 필요") -> USD | O6: =SUMPRODUCT(--ISTEXT(C6:E6)) -> 1 | P6: =IF(OR(G6="",H6="",I6="",J6="",L6=""),1,0) -> 1 | Q6: =IF(AND(J6<>"",J6<=0),1,0) -> 0 | R6: =IF(OR(G6="",H6=""),"",G6/H6) | S6: =IF(OR(I6="",J6="",Q6=1),"",I6/J6) -> 0.97149485 | T6: =IF(OR(K6="",L6=""),"",K6/L6*365) -> 31.325418 | U6: =IF(OR(M6="",L6=""),"",M6/L6) -> 0.13372056 | V6: =IF(ISTEXT(C6),"글자 섞임",ROUND(C6*VLOOKUP(N6,'환율_기준일'!$A$4:$E$7,5,FALSE)/'환율_기준일'!$E$4,2)) -> 글자 섞임 | W6: =IF(ISNUMBER(V6),IF(V6>F6*10,1,0),"") | X6: =IF(Q6=1,COUNTIF($Q$2:Q6,1),"")
A7: B006 | B7: USD | C7: 0 | D7: 0 | E7: 0 | F7: 10000 | N7: =IFERROR(VLOOKUP(TRIM(B7),'확인표_A'!$A$6:$B$14,2,FALSE),"확인 필요") -> USD | O7: =SUMPRODUCT(--ISTEXT(C7:E7)) -> 0 | P7: =IF(OR(G7="",H7="",I7="",J7="",L7=""),1,0) -> 1 | Q7: =IF(AND(J7<>"",J7<=0),1,0) -> 0 | R7: =IF(OR(G7="",H7=""),"",G7/H7) | S7: =IF(OR(I7="",J7="",Q7=1),"",I7/J7) | T7: =IF(OR(K7="",L7=""),"",K7/L7*365) | U7: =IF(OR(M7="",L7=""),"",M7/L7) | V7: =IF(ISTEXT(C7),"글자 섞임",ROUND(C7*VLOOKUP(N7,'환율_기준일'!$A$4:$E$7,5,FALSE)/'환율_기준일'!$E$4,2)) -> 0 | W7: =IF(ISNUMBER(V7),IF(V7>F7*10,1,0),"") -> 0 | X7: =IF(Q7=1,COUNTIF($Q$2:Q7,1),"")
A8: B007 | B8: EUR | C8: 2650 | D8: 2650 | E8: 0 | F8: 20000 | G8: 12383000 | H8: 5217000 | I8: 7416000 | J8: 15094000 | K8: 4161000 | L8: 27528000 | M8: 1737000 | N8: =IFERROR(VLOOKUP(TRIM(B8),'확인표_A'!$A$6:$B$14,2,FALSE),"확인 필요") -> EUR | O8: =SUMPRODUCT(--ISTEXT(C8:E8)) -> 0 | P8: =IF(OR(G8="",H8="",I8="",J8="",L8=""),1,0) -> 0 | Q8: =IF(AND(J8<>"",J8<=0),1,0) -> 0 | R8: =IF(OR(G8="",H8=""),"",G8/H8) -> 2.3735864 | S8: =IF(OR(I8="",J8="",Q8=1),"",I8/J8) -> 0.49132105 | T8: =IF(OR(K8="",L8=""),"",K8/L8*365) -> 55.171643 | U8: =IF(OR(M8="",L8=""),"",M8/L8) -> 0.06309939 | V8: =IF(ISTEXT(C8),"글자 섞임",ROUND(C8*VLOOKUP(N8,'환율_기준일'!$A$4:$E$7,5,FALSE)/'환율_기준일'!$E$4,2)) -> 3078.51 | W8: =IF(ISNUMBER(V8),IF(V8>F8*10,1,0),"") -> 0 | X8: =IF(Q8=1,COUNTIF($Q$2:Q8,1),"")
A9: B008 | B9: EUR | C9: 8080 | D9: 1230 | E9: 6,850 | F9: 10000 | G9: 4257000 | H9: 3189000 | I9: 5300000 | J9: 3217000 | K9: 2183000 | L9: 14083000 | M9: 1177000 | N9: =IFERROR(VLOOKUP(TRIM(B9),'확인표_A'!$A$6:$B$14,2,FALSE),"확인 필요") -> EUR | O9: =SUMPRODUCT(--ISTEXT(C9:E9)) -> 1 | P9: =IF(OR(G9="",H9="",I9="",J9="",L9=""),1,0) -> 0 | Q9: =IF(AND(J9<>"",J9<=0),1,0) -> 0 | R9: =IF(OR(G9="",H9=""),"",G9/H9) -> 1.3349012 | S9: =IF(OR(I9="",J9="",Q9=1),"",I9/J9) -> 1.6474977 | T9: =IF(OR(K9="",L9=""),"",K9/L9*365) -> 56.578499 | U9: =IF(OR(M9="",L9=""),"",M9/L9) -> 0.083575943 | V9: =IF(ISTEXT(C9),"글자 섞임",ROUND(C9*VLOOKUP(N9,'환율_기준일'!$A$4:$E$7,5,FALSE)/'환율_기준일'!$E$4,2)) -> 9386.56 | W9: =IF(ISNUMBER(V9),IF(V9>F9*10,1,0),"") -> 0 | X9: =IF(Q9=1,COUNTIF($Q$2:Q9,1),"")
A10: B009 | B10: CNY | C10: CNY 317,000 | D10: 317000 | E10: 0 | F10: 60000 | G10: 10718000 | H10: 10331000 | I10: 17835000 | J10: 3095000 | K10: 5644000 | L10: 25116000 | M10: 593000 | N10: =IFERROR(VLOOKUP(TRIM(B10),'확인표_A'!$A$6:$B$14,2,FALSE),"확인 필요") -> CNY | O10: =SUMPRODUCT(--ISTEXT(C10:E10)) -> 1 | P10: =IF(OR(G10="",H10="",I10="",J10="",L10=""),1,0) -> 0 | Q10: =IF(AND(J10<>"",J10<=0),1,0) -> 0 | R10: =IF(OR(G10="",H10=""),"",G10/H10) -> 1.0374601 | S10: =IF(OR(I10="",J10="",Q10=1),"",I10/J10) -> 5.7625202 | T10: =IF(OR(K10="",L10=""),"",K10/L10*365) -> 82.021819 | U10: =IF(OR(M10="",L10=""),"",M10/L10) -> 0.023610448 | V10: =IF(ISTEXT(C10),"글자 섞임",ROUND(C10*VLOOKUP(N10,'환율_기준일'!$A$4:$E$7,5,FALSE)/'환율_기준일'!$E$4,2)) -> 글자 섞임 | W10: =IF(ISNUMBER(V10),IF(V10>F10*10,1,0),"") | X10: =IF(Q10=1,COUNTIF($Q$2:Q10,1),"")
A11: B010 | B11: EUR | C11: 0 | D11: 0 | E11: 0 | F11: 10000 | G11: 2497000 | H11: 2165000 | I11: 3623000 | J11: 1311000 | K11: 1151000 | L11: 5926000 | M11: 21000 | N11: =IFERROR(VLOOKUP(TRIM(B11),'확인표_A'!$A$6:$B$14,2,FALSE),"확인 필요") -> EUR | O11: =SUMPRODUCT(--ISTEXT(C11:E11)) -> 0 | P11: =IF(OR(G11="",H11="",I11="",J11="",L11=""),1,0) -> 0 | Q11: =IF(AND(J11<>"",J11<=0),1,0) -> 0 | R11: =IF(OR(G11="",H11=""),"",G11/H11) -> 1.1533487 | S11: =IF(OR(I11="",J11="",Q11=1),"",I11/J11) -> 2.7635393 | T11: =IF(OR(K11="",L11=""),"",K11/L11*365) -> 70.89352 | U11: =IF(OR(M11="",L11=""),"",M11/L11) -> 0.0035437057 | V11: =IF(ISTEXT(C11),"글자 섞임",ROUND(C11*VLOOKUP(N11,'환율_기준일'!$A$4:$E$7,5,FALSE)/'환율_기준일'!$E$4,2)) -> 0 | W11: =IF(ISNUMBER(V11),IF(V11>F11*10,1,0),"") -> 0 | X11: =IF(Q11=1,COUNTIF($Q$2:Q11,1),"")
A12: B011 | B12: USD | C12: 0 | D12: 0 | E12: 0 | F12: 10000 | G12: 5142000 | H12: 4346000 | I12: 5716000 | J12: 1183000 | L12: 7731000 | N12: =IFERROR(VLOOKUP(TRIM(B12),'확인표_A'!$A$6:$B$14,2,FALSE),"확인 필요") -> USD | O12: =SUMPRODUCT(--ISTEXT(C12:E12)) -> 0 | P12: =IF(OR(G12="",H12="",I12="",J12="",L12=""),1,0) -> 0 | Q12: =IF(AND(J12<>"",J12<=0),1,0) -> 0 | R12: =IF(OR(G12="",H12=""),"",G12/H12) -> 1.1831569 | S12: =IF(OR(I12="",J12="",Q12=1),"",I12/J12) -> 4.8317836 | T12: =IF(OR(K12="",L12=""),"",K12/L12*365) | U12: =IF(OR(M12="",L12=""),"",M12/L12) | V12: =IF(ISTEXT(C12),"글자 섞임",ROUND(C12*VLOOKUP(N12,'환율_기준일'!$A$4:$E$7,5,FALSE)/'환율_기준일'!$E$4,2)) -> 0 | W12: =IF(ISNUMBER(V12),IF(V12>F12*10,1,0),"") -> 0 | X12: =IF(Q12=1,COUNTIF($Q$2:Q12,1),"")
A13: B012 | B13: USD | C13: 0 | D13: 0 | E13: 0 | F13: 10000 | G13: 11541000 | H13: 12002000 | I13: 19711000 | J13: 7448000 | L13: 10451000 | M13: -1021000 | N13: =IFERROR(VLOOKUP(TRIM(B13),'확인표_A'!$A$6:$B$14,2,FALSE),"확인 필요") -> USD | O13: =SUMPRODUCT(--ISTEXT(C13:E13)) -> 0 | P13: =IF(OR(G13="",H13="",I13="",J13="",L13=""),1,0) -> 0 | Q13: =IF(AND(J13<>"",J13<=0),1,0) -> 0 | R13: =IF(OR(G13="",H13=""),"",G13/H13) -> 0.96158974 | S13: =IF(OR(I13="",J13="",Q13=1),"",I13/J13) -> 2.6464823 | T13: =IF(OR(K13="",L13=""),"",K13/L13*365) | U13: =IF(OR(M13="",L13=""),"",M13/L13) -> -0.097694001 | V13: =IF(ISTEXT(C13),"글자 섞임",ROUND(C13*VLOOKUP(N13,'환율_기준일'!$A$4:$E$7,5,FALSE)/'환율_기준일'!$E$4,2)) -> 0 | W13: =IF(ISNUMBER(V13),IF(V13>F13*10,1,0),"") -> 0 | X13: =IF(Q13=1,COUNTIF($Q$2:Q13,1),"")
A14: B013 | B14: USD | C14: 0 | D14: 0 | E14: 0 | F14: 20000 | G14: 22496000 | H14: 62489000 | I14: 109262000 | J14: -15126000 | K14: 10957000 | L14: 46504000 | M14: -11565000 | N14: =IFERROR(VLOOKUP(TRIM(B14),'확인표_A'!$A$6:$B$14,2,FALSE),"확인 필요") -> USD | O14: =SUMPRODUCT(--ISTEXT(C14:E14)) -> 0 | P14: =IF(OR(G14="",H14="",I14="",J14="",L14=""),1,0) -> 0 | Q14: =IF(AND(J14<>"",J14<=0),1,0) -> 1 | R14: =IF(OR(G14="",H14=""),"",G14/H14) -> 0.35999936 | S14: =IF(OR(I14="",J14="",Q14=1),"",I14/J14) | T14: =IF(OR(K14="",L14=""),"",K14/L14*365) -> 85.999161 | U14: =IF(OR(M14="",L14=""),"",M14/L14) -> -0.24868828 | V14: =IF(ISTEXT(C14),"글자 섞임",ROUND(C14*VLOOKUP(N14,'환율_기준일'!$A$4:$E$7,5,FALSE)/'환율_기준일'!$E$4,2)) -> 0 | W14: =IF(ISNUMBER(V14),IF(V14>F14*10,1,0),"") -> 0 | X14: =IF(Q14=1,COUNTIF($Q$2:Q14,1),"") -> 1
A15: B014 | B15: USD | C15: 29910 | D15: 29910 | E15: 0 | F15: 50000 | G15: 47876000 | H15: 28567000 | I15: 39898000 | J15: 71277000 | K15: 20957000 | L15: 148025000 | M15: 11168000 | N15: =IFERROR(VLOOKUP(TRIM(B15),'확인표_A'!$A$6:$B$14,2,FALSE),"확인 필요") -> USD | O15: =SUMPRODUCT(--ISTEXT(C15:E15)) -> 0 | P15: =IF(OR(G15="",H15="",I15="",J15="",L15=""),1,0) -> 0 | Q15: =IF(AND(J15<>"",J15<=0),1,0) -> 0 | R15: =IF(OR(G15="",H15=""),"",G15/H15) -> 1.6759198 | S15: =IF(OR(I15="",J15="",Q15=1),"",I15/J15) -> 0.55975981 | T15: =IF(OR(K15="",L15=""),"",K15/L15*365) -> 51.675764 | U15: =IF(OR(M15="",L15=""),"",M15/L15) -> 0.075446715 | V15: =IF(ISTEXT(C15),"글자 섞임",ROUND(C15*VLOOKUP(N15,'환율_기준일'!$A$4:$E$7,5,FALSE)/'환율_기준일'!$E$4,2)) -> 29910 | W15: =IF(ISNUMBER(V15),IF(V15>F15*10,1,0),"") -> 0 | X15: =IF(Q15=1,COUNTIF($Q$2:Q15,1),"")
A16: B015 | B16: USD | C16: 7,680 | D16: 7680 | E16: 0 | F16: 20000 | G16: 5353000 | H16: 3765000 | I16: 8130000 | J16: 8104000 | K16: 2203000 | L16: 16500000 | M16: 564000 | N16: =IFERROR(VLOOKUP(TRIM(B16),'확인표_A'!$A$6:$B$14,2,FALSE),"확인 필요") -> USD | O16: =SUMPRODUCT(--ISTEXT(C16:E16)) -> 1 | P16: =IF(OR(G16="",H16="",I16="",J16="",L16=""),1,0) -> 0 | Q16: =IF(AND(J16<>"",J16<=0),1,0) -> 0 | R16: =IF(OR(G16="",H16=""),"",G16/H16) -> 1.4217795 | S16: =IF(OR(I16="",J16="",Q16=1),"",I16/J16) -> 1.0032083 | T16: =IF(OR(K16="",L16=""),"",K16/L16*365) -> 48.73303 | U16: =IF(OR(M16="",L16=""),"",M16/L16) -> 0.034181818 | V16: =IF(ISTEXT(C16),"글자 섞임",ROUND(C16*VLOOKUP(N16,'환율_기준일'!$A$4:$E$7,5,FALSE)/'환율_기준일'!$E$4,2)) -> 글자 섞임 | W16: =IF(ISNUMBER(V16),IF(V16>F16*10,1,0),"") | X16: =IF(Q16=1,COUNTIF($Q$2:Q16,1),"")
A17: B016 | B17: USD | C17: 0 | D17: 0 | E17: 0 | F17: 10000 | N17: =IFERROR(VLOOKUP(TRIM(B17),'확인표_A'!$A$6:$B$14,2,FALSE),"확인 필요") -> USD | O17: =SUMPRODUCT(--ISTEXT(C17:E17)) -> 0 | P17: =IF(OR(G17="",H17="",I17="",J17="",L17=""),1,0) -> 1 | Q17: =IF(AND(J17<>"",J17<=0),1,0) -> 0 | R17: =IF(OR(G17="",H17=""),"",G17/H17) | S17: =IF(OR(I17="",J17="",Q17=1),"",I17/J17) | T17: =IF(OR(K17="",L17=""),"",K17/L17*365) | U17: =IF(OR(M17="",L17=""),"",M17/L17) | V17: =IF(ISTEXT(C17),"글자 섞임",ROUND(C17*VLOOKUP(N17,'환율_기준일'!$A$4:$E$7,5,FALSE)/'환율_기준일'!$E$4,2)) -> 0 | W17: =IF(ISNUMBER(V17),IF(V17>F17*10,1,0),"") -> 0 | X17: =IF(Q17=1,COUNTIF($Q$2:Q17,1),"")
A18: B017 | B18: USD | C18: 0 | D18: 0 | E18: 0 | F18: 10000 | G18: 2309000 | H18: 1979000 | I18: 4148000 | J18: 4861000 | K18: 996000 | L18: 5495000 | N18: =IFERROR(VLOOKUP(TRIM(B18),'확인표_A'!$A$6:$B$14,2,FALSE),"확인 필요") -> USD | O18: =SUMPRODUCT(--ISTEXT(C18:E18)) -> 0 | P18: =IF(OR(G18="",H18="",I18="",J18="",L18=""),1,0) -> 0 | Q18: =IF(AND(J18<>"",J18<=0),1,0) -> 0 | R18: =IF(OR(G18="",H18=""),"",G18/H18) -> 1.1667509 | S18: =IF(OR(I18="",J18="",Q18=1),"",I18/J18) -> 0.85332236 | T18: =IF(OR(K18="",L18=""),"",K18/L18*365) -> 66.158326 | U18: =IF(OR(M18="",L18=""),"",M18/L18) | V18: =IF(ISTEXT(C18),"글자 섞임",ROUND(C18*VLOOKUP(N18,'환율_기준일'!$A$4:$E$7,5,FALSE)/'환율_기준일'!$E$4,2)) -> 0 | W18: =IF(ISNUMBER(V18),IF(V18>F18*10,1,0),"") -> 0 | X18: =IF(Q18=1,COUNTIF($Q$2:Q18,1),"")
A19: B018 | B19: EUR | C19: 0 | D19: 0 | E19: 0 | F19: 20000 | G19: 17484000 | H19: 11417000 | I19: 24384000 | J19: 13466000 | K19: 6098000 | L19: 31866000 | M19: -634000 | N19: =IFERROR(VLOOKUP(TRIM(B19),'확인표_A'!$A$6:$B$14,2,FALSE),"확인 필요") -> EUR | O19: =SUMPRODUCT(--ISTEXT(C19:E19)) -> 0 | P19: =IF(OR(G19="",H19="",I19="",J19="",L19=""),1,0) -> 0 | Q19: =IF(AND(J19<>"",J19<=0),1,0) -> 0 | R19: =IF(OR(G19="",H19=""),"",G19/H19) -> 1.5314005 | S19: =IF(OR(I19="",J19="",Q19=1),"",I19/J19) -> 1.8107827 | T19: =IF(OR(K19="",L19=""),"",K19/L19*365) -> 69.8478 | U19: =IF(OR(M19="",L19=""),"",M19/L19) -> -0.019895814 | V19: =IF(ISTEXT(C19),"글자 섞임",ROUND(C19*VLOOKUP(N19,'환율_기준일'!$A$4:$E$7,5,FALSE)/'환율_기준일'!$E$4,2)) -> 0 | W19: =IF(ISNUMBER(V19),IF(V19>F19*10,1,0),"") -> 0 | X19: =IF(Q19=1,COUNTIF($Q$2:Q19,1),"")
A20: B019 | B20: USD | C20: 12250 | D20: 12250 | E20: 0 | F20: 20000 | G20: 4111000 | H20: 2178000 | I20: 3133000 | J20: 2524000 | L20: 13268000 | M20: 1653000 | N20: =IFERROR(VLOOKUP(TRIM(B20),'확인표_A'!$A$6:$B$14,2,FALSE),"확인 필요") -> USD | O20: =SUMPRODUCT(--ISTEXT(C20:E20)) -> 0 | P20: =IF(OR(G20="",H20="",I20="",J20="",L20=""),1,0) -> 0 | Q20: =IF(AND(J20<>"",J20<=0),1,0) -> 0 | R20: =IF(OR(G20="",H20=""),"",G20/H20) -> 1.8875115 | S20: =IF(OR(I20="",J20="",Q20=1),"",I20/J20) -> 1.2412837 | T20: =IF(OR(K20="",L20=""),"",K20/L20*365) | U20: =IF(OR(M20="",L20=""),"",M20/L20) -> 0.12458547 | V20: =IF(ISTEXT(C20),"글자 섞임",ROUND(C20*VLOOKUP(N20,'환율_기준일'!$A$4:$E$7,5,FALSE)/'환율_기준일'!$E$4,2)) -> 12250 | W20: =IF(ISNUMBER(V20),IF(V20>F20*10,1,0),"") -> 0 | X20: =IF(Q20=1,COUNTIF($Q$2:Q20,1),"")
A21: B020 | B21: USD | C21: 0 | D21: 0 | E21: 0 | F21: 10000 | G21: 10263000 | H21: 8905000 | I21: 17416000 | J21: 3369000 | K21: 4723000 | L21: 16153000 | M21: -1021000 | N21: =IFERROR(VLOOKUP(TRIM(B21),'확인표_A'!$A$6:$B$14,2,FALSE),"확인 필요") -> USD | O21: =SUMPRODUCT(--ISTEXT(C21:E21)) -> 0 | P21: =IF(OR(G21="",H21="",I21="",J21="",L21=""),1,0) -> 0 | Q21: =IF(AND(J21<>"",J21<=0),1,0) -> 0 | R21: =IF(OR(G21="",H21=""),"",G21/H21) -> 1.1524986 | S21: =IF(OR(I21="",J21="",Q21=1),"",I21/J21) -> 5.1694865 | T21: =IF(OR(K21="",L21=""),"",K21/L21*365) -> 106.7229 | U21: =IF(OR(M21="",L21=""),"",M21/L21) -> -0.063208073 | V21: =IF(ISTEXT(C21),"글자 섞임",ROUND(C21*VLOOKUP(N21,'환율_기준일'!$A$4:$E$7,5,FALSE)/'환율_기준일'!$E$4,2)) -> 0 | W21: =IF(ISNUMBER(V21),IF(V21>F21*10,1,0),"") -> 0 | X21: =IF(Q21=1,COUNTIF($Q$2:Q21,1),"")
A22: B021 | B22: CNY | C22: 427100 | D22: 427100 | E22: 0 | F22: 30000 | G22: 21871000 | H22: 17090000 | I22: 25868000 | J22: 31185000 | L22: 49384000 | M22: 2135000 | N22: =IFERROR(VLOOKUP(TRIM(B22),'확인표_A'!$A$6:$B$14,2,FALSE),"확인 필요") -> CNY | O22: =SUMPRODUCT(--ISTEXT(C22:E22)) -> 0 | P22: =IF(OR(G22="",H22="",I22="",J22="",L22=""),1,0) -> 0 | Q22: =IF(AND(J22<>"",J22<=0),1,0) -> 0 | R22: =IF(OR(G22="",H22=""),"",G22/H22) -> 1.2797542 | S22: =IF(OR(I22="",J22="",Q22=1),"",I22/J22) -> 0.82950136 | T22: =IF(OR(K22="",L22=""),"",K22/L22*365) | U22: =IF(OR(M22="",L22=""),"",M22/L22) -> 0.043232626 | V22: =IF(ISTEXT(C22),"글자 섞임",ROUND(C22*VLOOKUP(N22,'환율_기준일'!$A$4:$E$7,5,FALSE)/'환율_기준일'!$E$4,2)) -> 63560.1 | W22: =IF(ISNUMBER(V22),IF(V22>F22*10,1,0),"") -> 0 | X22: =IF(Q22=1,COUNTIF($Q$2:Q22,1),"")
A23: B022 | B23: US$ | C23: 95880 | D23: 91550 | E23: 4330 | F23: 50000 | G23: 36497000 | H23: 26854000 | I23: 32891000 | J23: 26270000 | K23: 16634000 | L23: 169300000 | M23: 14692000 | N23: =IFERROR(VLOOKUP(TRIM(B23),'확인표_A'!$A$6:$B$14,2,FALSE),"확인 필요") -> USD | O23: =SUMPRODUCT(--ISTEXT(C23:E23)) -> 0 | P23: =IF(OR(G23="",H23="",I23="",J23="",L23=""),1,0) -> 0 | Q23: =IF(AND(J23<>"",J23<=0),1,0) -> 0 | R23: =IF(OR(G23="",H23=""),"",G23/H23) -> 1.3590899 | S23: =IF(OR(I23="",J23="",Q23=1),"",I23/J23) -> 1.2520365 | T23: =IF(OR(K23="",L23=""),"",K23/L23*365) -> 35.861843 | U23: =IF(OR(M23="",L23=""),"",M23/L23) -> 0.086780862 | V23: =IF(ISTEXT(C23),"글자 섞임",ROUND(C23*VLOOKUP(N23,'환율_기준일'!$A$4:$E$7,5,FALSE)/'환율_기준일'!$E$4,2)) -> 95880 | W23: =IF(ISNUMBER(V23),IF(V23>F23*10,1,0),"") -> 0 | X23: =IF(Q23=1,COUNTIF($Q$2:Q23,1),"")
A24: B023 | B24: USD | C24: 26500 | D24: 22410 | E24: 4090 | F24: 50000 | N24: =IFERROR(VLOOKUP(TRIM(B24),'확인표_A'!$A$6:$B$14,2,FALSE),"확인 필요") -> USD | O24: =SUMPRODUCT(--ISTEXT(C24:E24)) -> 0 | P24: =IF(OR(G24="",H24="",I24="",J24="",L24=""),1,0) -> 1 | Q24: =IF(AND(J24<>"",J24<=0),1,0) -> 0 | R24: =IF(OR(G24="",H24=""),"",G24/H24) | S24: =IF(OR(I24="",J24="",Q24=1),"",I24/J24) | T24: =IF(OR(K24="",L24=""),"",K24/L24*365) | U24: =IF(OR(M24="",L24=""),"",M24/L24) | V24: =IF(ISTEXT(C24),"글자 섞임",ROUND(C24*VLOOKUP(N24,'환율_기준일'!$A$4:$E$7,5,FALSE)/'환율_기준일'!$E$4,2)) -> 26500 | W24: =IF(ISNUMBER(V24),IF(V24>F24*10,1,0),"") -> 0 | X24: =IF(Q24=1,COUNTIF($Q$2:Q24,1),"")
A25: B024 | B25: usd | C25: 10080 | D25: 10080 | E25: 0 | F25: 10000 | G25: 5546000 | H25: 4851000 | I25: 9481000 | J25: 3648000 | K25: 2394000 | L25: 10854000 | M25: 940000 | N25: =IFERROR(VLOOKUP(TRIM(B25),'확인표_A'!$A$6:$B$14,2,FALSE),"확인 필요") -> USD | O25: =SUMPRODUCT(--ISTEXT(C25:E25)) -> 0 | P25: =IF(OR(G25="",H25="",I25="",J25="",L25=""),1,0) -> 0 | Q25: =IF(AND(J25<>"",J25<=0),1,0) -> 0 | R25: =IF(OR(G25="",H25=""),"",G25/H25) -> 1.1432694 | S25: =IF(OR(I25="",J25="",Q25=1),"",I25/J25) -> 2.5989583 | T25: =IF(OR(K25="",L25=""),"",K25/L25*365) -> 80.505804 | U25: =IF(OR(M25="",L25=""),"",M25/L25) -> 0.086604017 | V25: =IF(ISTEXT(C25),"글자 섞임",ROUND(C25*VLOOKUP(N25,'환율_기준일'!$A$4:$E$7,5,FALSE)/'환율_기준일'!$E$4,2)) -> 10080 | W25: =IF(ISNUMBER(V25),IF(V25>F25*10,1,0),"") -> 0 | X25: =IF(Q25=1,COUNTIF($Q$2:Q25,1),"")
A26: B025 | B26: EUR | C26: 1370 | D26: 1370 | E26: 0 | F26: 10000 | G26: 1880000 | H26: 886000 | I26: 1657000 | J26: 2343000 | K26: 872000 | L26: 5387000 | N26: =IFERROR(VLOOKUP(TRIM(B26),'확인표_A'!$A$6:$B$14,2,FALSE),"확인 필요") -> EUR | O26: =SUMPRODUCT(--ISTEXT(C26:E26)) -> 0 | P26: =IF(OR(G26="",H26="",I26="",J26="",L26=""),1,0) -> 0 | Q26: =IF(AND(J26<>"",J26<=0),1,0) -> 0 | R26: =IF(OR(G26="",H26=""),"",G26/H26) -> 2.1218962 | S26: =IF(OR(I26="",J26="",Q26=1),"",I26/J26) -> 0.70721297 | T26: =IF(OR(K26="",L26=""),"",K26/L26*365) -> 59.082978 | U26: =IF(OR(M26="",L26=""),"",M26/L26) | V26: =IF(ISTEXT(C26),"글자 섞임",ROUND(C26*VLOOKUP(N26,'환율_기준일'!$A$4:$E$7,5,FALSE)/'환율_기준일'!$E$4,2)) -> 1591.53 | W26: =IF(ISNUMBER(V26),IF(V26>F26*10,1,0),"") -> 0 | X26: =IF(Q26=1,COUNTIF($Q$2:Q26,1),"")
A27: B026 | B27: US$ | C27: 50120 | D27: 50120 | E27: 0 | F27: 60000 | N27: =IFERROR(VLOOKUP(TRIM(B27),'확인표_A'!$A$6:$B$14,2,FALSE),"확인 필요") -> USD | O27: =SUMPRODUCT(--ISTEXT(C27:E27)) -> 0 | P27: =IF(OR(G27="",H27="",I27="",J27="",L27=""),1,0) -> 1 | Q27: =IF(AND(J27<>"",J27<=0),1,0) -> 0 | R27: =IF(OR(G27="",H27=""),"",G27/H27) | S27: =IF(OR(I27="",J27="",Q27=1),"",I27/J27) | T27: =IF(OR(K27="",L27=""),"",K27/L27*365) | U27: =IF(OR(M27="",L27=""),"",M27/L27) | V27: =IF(ISTEXT(C27),"글자 섞임",ROUND(C27*VLOOKUP(N27,'환율_기준일'!$A$4:$E$7,5,FALSE)/'환율_기준일'!$E$4,2)) -> 50120 | W27: =IF(ISNUMBER(V27),IF(V27>F27*10,1,0),"") -> 0 | X27: =IF(Q27=1,COUNTIF($Q$2:Q27,1),"")
A28: B027 | B28: USD | C28: 0 | D28: 0 | E28: 0 | F28: 10000 | N28: =IFERROR(VLOOKUP(TRIM(B28),'확인표_A'!$A$6:$B$14,2,FALSE),"확인 필요") -> USD | O28: =SUMPRODUCT(--ISTEXT(C28:E28)) -> 0 | P28: =IF(OR(G28="",H28="",I28="",J28="",L28=""),1,0) -> 1 | Q28: =IF(AND(J28<>"",J28<=0),1,0) -> 0 | R28: =IF(OR(G28="",H28=""),"",G28/H28) | S28: =IF(OR(I28="",J28="",Q28=1),"",I28/J28) | T28: =IF(OR(K28="",L28=""),"",K28/L28*365) | U28: =IF(OR(M28="",L28=""),"",M28/L28) | V28: =IF(ISTEXT(C28),"글자 섞임",ROUND(C28*VLOOKUP(N28,'환율_기준일'!$A$4:$E$7,5,FALSE)/'환율_기준일'!$E$4,2)) -> 0 | W28: =IF(ISNUMBER(V28),IF(V28>F28*10,1,0),"") -> 0 | X28: =IF(Q28=1,COUNTIF($Q$2:Q28,1),"")
A29: B028 | B29: JPY | C29: 32072000 | D29: 32072000 | E29: 0 | F29: 170000 | G29: 48811000 | H29: 28084000 | I29: 38949000 | J29: 69738000 | K29: 16800000 | L29: 160688000 | M29: 22088000 | N29: =IFERROR(VLOOKUP(TRIM(B29),'확인표_A'!$A$6:$B$14,2,FALSE),"확인 필요") -> JPY | O29: =SUMPRODUCT(--ISTEXT(C29:E29)) -> 0 | P29: =IF(OR(G29="",H29="",I29="",J29="",L29=""),1,0) -> 0 | Q29: =IF(AND(J29<>"",J29<=0),1,0) -> 0 | R29: =IF(OR(G29="",H29=""),"",G29/H29) -> 1.7380359 | S29: =IF(OR(I29="",J29="",Q29=1),"",I29/J29) -> 0.55850469 | T29: =IF(OR(K29="",L29=""),"",K29/L29*365) -> 38.160908 | U29: =IF(OR(M29="",L29=""),"",M29/L29) -> 0.13745893 | V29: =IF(ISTEXT(C29),"글자 섞임",ROUND(C29*VLOOKUP(N29,'환율_기준일'!$A$4:$E$7,5,FALSE)/'환율_기준일'!$E$4,2)) -> 200776.7 | W29: =IF(ISNUMBER(V29),IF(V29>F29*10,1,0),"") -> 0 | X29: =IF(Q29=1,COUNTIF($Q$2:Q29,1),"")
A30: B029 | B30: usd | C30: 60187.68 | D30: 34010 | E30: 5170 | F30: 100000 | G30: 289083000 | H30: 232878000 | I30: 327268000 | J30: 150008000 | K30: 103981000 | L30: 437297000 | M30: 44755000 | N30: =IFERROR(VLOOKUP(TRIM(B30),'확인표_A'!$A$6:$B$14,2,FALSE),"확인 필요") -> USD | O30: =SUMPRODUCT(--ISTEXT(C30:E30)) -> 0 | P30: =IF(OR(G30="",H30="",I30="",J30="",L30=""),1,0) -> 0 | Q30: =IF(AND(J30<>"",J30<=0),1,0) -> 0 | R30: =IF(OR(G30="",H30=""),"",G30/H30) -> 1.2413495 | S30: =IF(OR(I30="",J30="",Q30=1),"",I30/J30) -> 2.1816703 | T30: =IF(OR(K30="",L30=""),"",K30/L30*365) -> 86.790133 | U30: =IF(OR(M30="",L30=""),"",M30/L30) -> 0.10234463 | V30: =IF(ISTEXT(C30),"글자 섞임",ROUND(C30*VLOOKUP(N30,'환율_기준일'!$A$4:$E$7,5,FALSE)/'환율_기준일'!$E$4,2)) -> 60187.68 | W30: =IF(ISNUMBER(V30),IF(V30>F30*10,1,0),"") -> 0 | X30: =IF(Q30=1,COUNTIF($Q$2:Q30,1),"")
A31: B030 | B31: USD | C31: 21030 | D31: 21030 | E31: 0 | F31: 40000 | G31: 31198000 | H31: 42853000 | I31: 81042000 | K31: 12859000 | L31: 45005000 | M31: -3711000 | N31: =IFERROR(VLOOKUP(TRIM(B31),'확인표_A'!$A$6:$B$14,2,FALSE),"확인 필요") -> USD | O31: =SUMPRODUCT(--ISTEXT(C31:E31)) -> 0 | P31: =IF(OR(G31="",H31="",I31="",J31="",L31=""),1,0) -> 1 | Q31: =IF(AND(J31<>"",J31<=0),1,0) -> 0 | R31: =IF(OR(G31="",H31=""),"",G31/H31) -> 0.72802371 | S31: =IF(OR(I31="",J31="",Q31=1),"",I31/J31) | T31: =IF(OR(K31="",L31=""),"",K31/L31*365) -> 104.28919 | U31: =IF(OR(M31="",L31=""),"",M31/L31) -> -0.082457505 | V31: =IF(ISTEXT(C31),"글자 섞임",ROUND(C31*VLOOKUP(N31,'환율_기준일'!$A$4:$E$7,5,FALSE)/'환율_기준일'!$E$4,2)) -> 21030 | W31: =IF(ISNUMBER(V31),IF(V31>F31*10,1,0),"") -> 0 | X31: =IF(Q31=1,COUNTIF($Q$2:Q31,1),"")
A32: B031 | B32: USD | C32: 59690 | D32: 40490 | E32: 14930 | F32: 50000 | G32: 116791000 | I32: 112408000 | K32: 40333000 | L32: 243199000 | M32: 18357000 | N32: =IFERROR(VLOOKUP(TRIM(B32),'확인표_A'!$A$6:$B$14,2,FALSE),"확인 필요") -> USD | O32: =SUMPRODUCT(--ISTEXT(C32:E32)) -> 0 | P32: =IF(OR(G32="",H32="",I32="",J32="",L32=""),1,0) -> 1 | Q32: =IF(AND(J32<>"",J32<=0),1,0) -> 0 | R32: =IF(OR(G32="",H32=""),"",G32/H32) | S32: =IF(OR(I32="",J32="",Q32=1),"",I32/J32) | T32: =IF(OR(K32="",L32=""),"",K32/L32*365) -> 60.532917 | U32: =IF(OR(M32="",L32=""),"",M32/L32) -> 0.075481396 | V32: =IF(ISTEXT(C32),"글자 섞임",ROUND(C32*VLOOKUP(N32,'환율_기준일'!$A$4:$E$7,5,FALSE)/'환율_기준일'!$E$4,2)) -> 59690 | W32: =IF(ISNUMBER(V32),IF(V32>F32*10,1,0),"") -> 0 | X32: =IF(Q32=1,COUNTIF($Q$2:Q32,1),"")
A33: B032 | B33: USD | C33: 18070 | D33: 18070 | E33: 0 | F33: 10000 | G33: 90449000 | I33: 108506000 | J33: 57139000 | L33: 138829000 | N33: =IFERROR(VLOOKUP(TRIM(B33),'확인표_A'!$A$6:$B$14,2,FALSE),"확인 필요") -> USD | O33: =SUMPRODUCT(--ISTEXT(C33:E33)) -> 0 | P33: =IF(OR(G33="",H33="",I33="",J33="",L33=""),1,0) -> 1 | Q33: =IF(AND(J33<>"",J33<=0),1,0) -> 0 | R33: =IF(OR(G33="",H33=""),"",G33/H33) | S33: =IF(OR(I33="",J33="",Q33=1),"",I33/J33) -> 1.8989832 | T33: =IF(OR(K33="",L33=""),"",K33/L33*365) | U33: =IF(OR(M33="",L33=""),"",M33/L33) | V33: =IF(ISTEXT(C33),"글자 섞임",ROUND(C33*VLOOKUP(N33,'환율_기준일'!$A$4:$E$7,5,FALSE)/'환율_기준일'!$E$4,2)) -> 18070 | W33: =IF(ISNUMBER(V33),IF(V33>F33*10,1,0),"") -> 0 | X33: =IF(Q33=1,COUNTIF($Q$2:Q33,1),"")
A34: B033 | B34: USD | C34: 0 | D34: 0 | E34: 0 | F34: 10000 | G34: 8449000 | H34: 3981000 | I34: 4962000 | L34: 21381000 | N34: =IFERROR(VLOOKUP(TRIM(B34),'확인표_A'!$A$6:$B$14,2,FALSE),"확인 필요") -> USD | O34: =SUMPRODUCT(--ISTEXT(C34:E34)) -> 0 | P34: =IF(OR(G34="",H34="",I34="",J34="",L34=""),1,0) -> 1 | Q34: =IF(AND(J34<>"",J34<=0),1,0) -> 0 | R34: =IF(OR(G34="",H34=""),"",G34/H34) -> 2.1223311 | S34: =IF(OR(I34="",J34="",Q34=1),"",I34/J34) | T34: =IF(OR(K34="",L34=""),"",K34/L34*365) | U34: =IF(OR(M34="",L34=""),"",M34/L34) | V34: =IF(ISTEXT(C34),"글자 섞임",ROUND(C34*VLOOKUP(N34,'환율_기준일'!$A$4:$E$7,5,FALSE)/'환율_기준일'!$E$4,2)) -> 0 | W34: =IF(ISNUMBER(V34),IF(V34>F34*10,1,0),"") -> 0 | X34: =IF(Q34=1,COUNTIF($Q$2:Q34,1),"")
A35: B034 | B35: EUR | C35: 200,520 | D35: 200520 | E35: 0 | F35: 40000 | G35: 88454000 | H35: 40560000 | I35: 71233000 | J35: 174567000 | K35: 42666000 | L35: 359145000 | M35: 42510000 | N35: =IFERROR(VLOOKUP(TRIM(B35),'확인표_A'!$A$6:$B$14,2,FALSE),"확인 필요") -> EUR | O35: =SUMPRODUCT(--ISTEXT(C35:E35)) -> 1 | P35: =IF(OR(G35="",H35="",I35="",J35="",L35=""),1,0) -> 0 | Q35: =IF(AND(J35<>"",J35<=0),1,0) -> 0 | R35: =IF(OR(G35="",H35=""),"",G35/H35) -> 2.1808185 | S35: =IF(OR(I35="",J35="",Q35=1),"",I35/J35) -> 0.40805536 | T35: =IF(OR(K35="",L35=""),"",K35/L35*365) -> 43.361567 | U35: =IF(OR(M35="",L35=""),"",M35/L35) -> 0.11836445 | V35: =IF(ISTEXT(C35),"글자 섞임",ROUND(C35*VLOOKUP(N35,'환율_기준일'!$A$4:$E$7,5,FALSE)/'환율_기준일'!$E$4,2)) -> 글자 섞임 | W35: =IF(ISNUMBER(V35),IF(V35>F35*10,1,0),"") | X35: =IF(Q35=1,COUNTIF($Q$2:Q35,1),"")
A36: B035 | B36: US$ | C36: 0 | D36: 0 | E36: 0 | F36: 10000 | G36: 8791000 | I36: 10013000 | J36: 4693000 | K36: 3684000 | L36: 17999000 | M36: -313000 | N36: =IFERROR(VLOOKUP(TRIM(B36),'확인표_A'!$A$6:$B$14,2,FALSE),"확인 필요") -> USD | O36: =SUMPRODUCT(--ISTEXT(C36:E36)) -> 0 | P36: =IF(OR(G36="",H36="",I36="",J36="",L36=""),1,0) -> 1 | Q36: =IF(AND(J36<>"",J36<=0),1,0) -> 0 | R36: =IF(OR(G36="",H36=""),"",G36/H36) | S36: =IF(OR(I36="",J36="",Q36=1),"",I36/J36) -> 2.1336032 | T36: =IF(OR(K36="",L36=""),"",K36/L36*365) -> 74.707484 | U36: =IF(OR(M36="",L36=""),"",M36/L36) -> -0.017389855 | V36: =IF(ISTEXT(C36),"글자 섞임",ROUND(C36*VLOOKUP(N36,'환율_기준일'!$A$4:$E$7,5,FALSE)/'환율_기준일'!$E$4,2)) -> 0 | W36: =IF(ISNUMBER(V36),IF(V36>F36*10,1,0),"") -> 0 | X36: =IF(Q36=1,COUNTIF($Q$2:Q36,1),"")
A37: B036 | B37: usd | C37: 0 | D37: 0 | E37: 0 | F37: 10000 | N37: =IFERROR(VLOOKUP(TRIM(B37),'확인표_A'!$A$6:$B$14,2,FALSE),"확인 필요") -> USD | O37: =SUMPRODUCT(--ISTEXT(C37:E37)) -> 0 | P37: =IF(OR(G37="",H37="",I37="",J37="",L37=""),1,0) -> 1 | Q37: =IF(AND(J37<>"",J37<=0),1,0) -> 0 | R37: =IF(OR(G37="",H37=""),"",G37/H37) | S37: =IF(OR(I37="",J37="",Q37=1),"",I37/J37) | T37: =IF(OR(K37="",L37=""),"",K37/L37*365) | U37: =IF(OR(M37="",L37=""),"",M37/L37) | V37: =IF(ISTEXT(C37),"글자 섞임",ROUND(C37*VLOOKUP(N37,'환율_기준일'!$A$4:$E$7,5,FALSE)/'환율_기준일'!$E$4,2)) -> 0 | W37: =IF(ISNUMBER(V37),IF(V37>F37*10,1,0),"") -> 0 | X37: =IF(Q37=1,COUNTIF($Q$2:Q37,1),"")
A38: B037 | B38: USD | C38: 8690 | D38: 8690 | E38: 0 | F38: 40000 | G38: 17218000 | H38: 23499000 | I38: 38705000 | J38: 39854000 | K38: 6499000 | L38: 47961000 | M38: 3790000 | N38: =IFERROR(VLOOKUP(TRIM(B38),'확인표_A'!$A$6:$B$14,2,FALSE),"확인 필요") -> USD | O38: =SUMPRODUCT(--ISTEXT(C38:E38)) -> 0 | P38: =IF(OR(G38="",H38="",I38="",J38="",L38=""),1,0) -> 0 | Q38: =IF(AND(J38<>"",J38<=0),1,0) -> 0 | R38: =IF(OR(G38="",H38=""),"",G38/H38) -> 0.73271203 | S38: =IF(OR(I38="",J38="",Q38=1),"",I38/J38) -> 0.97116977 | T38: =IF(OR(K38="",L38=""),"",K38/L38*365) -> 49.459665 | U38: =IF(OR(M38="",L38=""),"",M38/L38) -> 0.079022539 | V38: =IF(ISTEXT(C38),"글자 섞임",ROUND(C38*VLOOKUP(N38,'환율_기준일'!$A$4:$E$7,5,FALSE)/'환율_기준일'!$E$4,2)) -> 8690 | W38: =IF(ISNUMBER(V38),IF(V38>F38*10,1,0),"") -> 0 | X38: =IF(Q38=1,COUNTIF($Q$2:Q38,1),"")
A39: B038 | B39: EUR | C39: 0 | D39: 0 | E39: 0 | F39: 10000 | G39: 4526000 | H39: 4302000 | I39: 5205000 | J39: 1129000 | K39: 1761000 | L39: 6552000 | M39: -350000 | N39: =IFERROR(VLOOKUP(TRIM(B39),'확인표_A'!$A$6:$B$14,2,FALSE),"확인 필요") -> EUR | O39: =SUMPRODUCT(--ISTEXT(C39:E39)) -> 0 | P39: =IF(OR(G39="",H39="",I39="",J39="",L39=""),1,0) -> 0 | Q39: =IF(AND(J39<>"",J39<=0),1,0) -> 0 | R39: =IF(OR(G39="",H39=""),"",G39/H39) -> 1.0520688 | S39: =IF(OR(I39="",J39="",Q39=1),"",I39/J39) -> 4.6102746 | T39: =IF(OR(K39="",L39=""),"",K39/L39*365) -> 98.102106 | U39: =IF(OR(M39="",L39=""),"",M39/L39) -> -0.053418803 | V39: =IF(ISTEXT(C39),"글자 섞임",ROUND(C39*VLOOKUP(N39,'환율_기준일'!$A$4:$E$7,5,FALSE)/'환율_기준일'!$E$4,2)) -> 0 | W39: =IF(ISNUMBER(V39),IF(V39>F39*10,1,0),"") -> 0 | X39: =IF(Q39=1,COUNTIF($Q$2:Q39,1),"")
A40: B039 | B40: USD | C40: 0 | D40: 0 | E40: 0 | F40: 10000 | G40: 3344000 | H40: 2615000 | I40: 4125000 | J40: 2017000 | L40: 7402000 | M40: 500000 | N40: =IFERROR(VLOOKUP(TRIM(B40),'확인표_A'!$A$6:$B$14,2,FALSE),"확인 필요") -> USD | O40: =SUMPRODUCT(--ISTEXT(C40:E40)) -> 0 | P40: =IF(OR(G40="",H40="",I40="",J40="",L40=""),1,0) -> 0 | Q40: =IF(AND(J40<>"",J40<=0),1,0) -> 0 | R40: =IF(OR(G40="",H40=""),"",G40/H40) -> 1.2787763 | S40: =IF(OR(I40="",J40="",Q40=1),"",I40/J40) -> 2.0451165 | T40: =IF(OR(K40="",L40=""),"",K40/L40*365) | U40: =IF(OR(M40="",L40=""),"",M40/L40) -> 0.067549311 | V40: =IF(ISTEXT(C40),"글자 섞임",ROUND(C40*VLOOKUP(N40,'환율_기준일'!$A$4:$E$7,5,FALSE)/'환율_기준일'!$E$4,2)) -> 0 | W40: =IF(ISNUMBER(V40),IF(V40>F40*10,1,0),"") -> 0 | X40: =IF(Q40=1,COUNTIF($Q$2:Q40,1),"")
...

Sheet 환율_기준일
A1: 기준일 2026-08-31 환율(원) — d2_start.xlsx의 fx_at_ref 시트에서 그날 4행만
A2: 엔화(JPY100)는 100엔당 값입니다 — 1엔당 원은 노란 칸(÷100)
A3: 통화(표준) | B3: fx_at_ref ccy | C3: 단위 | D3: krw_close | E3: 1단위당 원(수식) | F3: 관측일
A4: USD | B4: USD | C4: KRW per 1 USD | D4: 1368.25 | E4: =IF(B4="JPY100",D4/100,D4) -> 1368.25 | F4: 46265
A5: EUR | B5: EUR | C5: KRW per 1 EUR | D5: 1589.5 | E5: =IF(B5="JPY100",D5/100,D5) -> 1589.5 | F5: 46265
A6: CNY | B6: CNY | C6: KRW per 1 CNY | D6: 203.62 | E6: =IF(B6="JPY100",D6/100,D6) -> 203.62 | F6: 46265
A7: JPY | B7: JPY100 | C7: KRW per 100 JPY | D7: 856.55 | E7: =IF(B7="JPY100",D7/100,D7) -> 8.5655 | F7: 46265

Sheet 뉴스_앞100행
A1: news_id | B1: buyer_id | C1: date | D1: lang | E1: 창_안(수식) | F1: 창_안_첫등장(수식) | G1: 9월(수식)
A2: N01395 | B2: B040 | C2: 46295 | D2: en | E2: =IF(AND(C2>DATE(2026,8,1),C2<=DATE(2026,8,31)),1,0) -> 0 | F2: =IF(E2=1,IF(COUNTIFS($B$2:B2,B2,$E$2:E2,1)=1,1,0),0) -> 0 | G2: =IF(AND(C2>DATE(2026,8,31),C2<=DATE(2026,9,30)),1,0) -> 1
A3: N01396 | B3: B141 | C3: 46295 | D3: ko | E3: =IF(AND(C3>DATE(2026,8,1),C3<=DATE(2026,8,31)),1,0) -> 0 | F3: =IF(E3=1,IF(COUNTIFS($B$2:B3,B3,$E$2:E3,1)=1,1,0),0) -> 0 | G3: =IF(AND(C3>DATE(2026,8,31),C3<=DATE(2026,9,30)),1,0) -> 1
A4: N01393 | B4: B053 | C4: 46291 | D4: en | E4: =IF(AND(C4>DATE(2026,8,1),C4<=DATE(2026,8,31)),1,0) -> 0 | F4: =IF(E4=1,IF(COUNTIFS($B$2:B4,B4,$E$2:E4,1)=1,1,0),0) -> 0 | G4: =IF(AND(C4>DATE(2026,8,31),C4<=DATE(2026,9,30)),1,0) -> 1
A5: N01394 | B5: B134 | C5: 46291 | D5: en | E5: =IF(AND(C5>DATE(2026,8,1),C5<=DATE(2026,8,31)),1,0) -> 0 | F5: =IF(E5=1,IF(COUNTIFS($B$2:B5,B5,$E$2:E5,1)=1,1,0),0) -> 0 | G5: =IF(AND(C5>DATE(2026,8,31),C5<=DATE(2026,9,30)),1,0) -> 1
A6: N01389 | B6: B046 | C6: 46290 | D6: ko | E6: =IF(AND(C6>DATE(2026,8,1),C6<=DATE(2026,8,31)),1,0) -> 0 | F6: =IF(E6=1,IF(COUNTIFS($B$2:B6,B6,$E$2:E6,1)=1,1,0),0) -> 0 | G6: =IF(AND(C6>DATE(2026,8,31),C6<=DATE(2026,9,30)),1,0) -> 1
A7: N01390 | B7: B113 | C7: 46290 | D7: en | E7: =IF(AND(C7>DATE(2026,8,1),C7<=DATE(2026,8,31)),1,0) -> 0 | F7: =IF(E7=1,IF(COUNTIFS($B$2:B7,B7,$E$2:E7,1)=1,1,0),0) -> 0 | G7: =IF(AND(C7>DATE(2026,8,31),C7<=DATE(2026,9,30)),1,0) -> 1
A8: N01391 | B8: B123 | C8: 46290 | D8: en | E8: =IF(AND(C8>DATE(2026,8,1),C8<=DATE(2026,8,31)),1,0) -> 0 | F8: =IF(E8=1,IF(COUNTIFS($B$2:B8,B8,$E$2:E8,1)=1,1,0),0) -> 0 | G8: =IF(AND(C8>DATE(2026,8,31),C8<=DATE(2026,9,30)),1,0) -> 1
A9: N01392 | B9: B131 | C9: 46290 | D9: en | E9: =IF(AND(C9>DATE(2026,8,1),C9<=DATE(2026,8,31)),1,0) -> 0 | F9: =IF(E9=1,IF(COUNTIFS($B$2:B9,B9,$E$2:E9,1)=1,1,0),0) -> 0 | G9: =IF(AND(C9>DATE(2026,8,31),C9<=DATE(2026,9,30)),1,0) -> 1
A10: N01387 | B10: B063 | C10: 46289 | D10: en | E10: =IF(AND(C10>DATE(2026,8,1),C10<=DATE(2026,8,31)),1,0) -> 0 | F10: =IF(E10=1,IF(COUNTIFS($B$2:B10,B10,$E$2:E10,1)=1,1,0),0) -> 0 | G10: =IF(AND(C10>DATE(2026,8,31),C10<=DATE(2026,9,30)),1,0) -> 1
A11: N01388 | B11: B065 | C11: 46289 | D11: ko | E11: =IF(AND(C11>DATE(2026,8,1),C11<=DATE(2026,8,31)),1,0) -> 0 | F11: =IF(E11=1,IF(COUNTIFS($B$2:B11,B11,$E$2:E11,1)=1,1,0),0) -> 0 | G11: =IF(AND(C11>DATE(2026,8,31),C11<=DATE(2026,9,30)),1,0) -> 1
A12: N01386 | B12: B111 | C12: 46288 | D12: ko | E12: =IF(AND(C12>DATE(2026,8,1),C12<=DATE(2026,8,31)),1,0) -> 0 | F12: =IF(E12=1,IF(COUNTIFS($B$2:B12,B12,$E$2:E12,1)=1,1,0),0) -> 0 | G12: =IF(AND(C12>DATE(2026,8,31),C12<=DATE(2026,9,30)),1,0) -> 1
A13: N01385 | B13: B058 | C13: 46286 | D13: en | E13: =IF(AND(C13>DATE(2026,8,1),C13<=DATE(2026,8,31)),1,0) -> 0 | F13: =IF(E13=1,IF(COUNTIFS($B$2:B13,B13,$E$2:E13,1)=1,1,0),0) -> 0 | G13: =IF(AND(C13>DATE(2026,8,31),C13<=DATE(2026,9,30)),1,0) -> 1
... A101: N01245 | B101: B062 | C101: 46195 | D101: en | E101: =IF(AND(C101>DATE(2026,8,1),C101<=DATE(2026,8,31)),1,0) -> 0 | F101: =IF(E101=1,IF(COUNTIFS($B$2:B101,B101,$E$2:E101,1)=1,1,0),0) -> 0 | G101: =IF(AND(C101>DATE(2026,8,31),C101<=DATE(2026,9,30)),1,0) -> 0
