Workbook

Sheet 안내
A1: d1_pivot_check.xlsx — 손 검산 완성 파일
A2: 1일차 실습 B-2 · 02 · 원천을 한 칸도 고치지 않고 결제방식별로 센 표와 막대 차트(정답이 아니라 기준선)
A4: 이 파일 | B4: 1일차 실습 B-2 · 02 '손 검산'용 완성 파일입니다. 엑셀 피벗 · 피벗 차트로 할 계산을 미리 해 두었습니다.
A5: 왜 | B5: AI(노트북)가 코드로 낸 숫자를 코드가 아닌 다른 길로 한 번 더 세어 맞춰 보려고. 실습 시간은 엑셀 조작이 아니라 AI 결과와 이 파일을 비교하고 원인을 찾는 데 씁니다.
A6: 무엇으로 | B6: data/day1/d1_buyers_raw.xlsx(원천)와 data/data_dictionary.xlsx의 결제조건 표기 → 표준 코드 표(42개 표기). 둘 다 과정 파일입니다.
A7: 어떻게 ① | B7: buyers 시트 = 원천을 한 칸도 고치지 않고 옮겼습니다. 원천에 어떤 문제가 있어도 그대로입니다.
A8: 어떻게 ② | B8: buyers 시트 X열 '표준코드' = 결제조건(I열)의 앞뒤 공백을 지우고 코드표 시트에서 찾았습니다. 없으면 '미분류'. 셀을 누르면 수식이 보입니다.
A9: 어떻게 ③ | B9: buyers 시트 Y열 '연체' = 연체일수(L열)가 0보다 크면 1, 0이면 0, 숫자로 읽히지 않으면 빈칸(판정 불가)입니다.
A10: 어떻게 ④ | B10: 결제방식_피벗 시트 = 표준 코드별 행 수 · 판정 불가 · 판정 가능 행 · 연체 바이어 · 비율(연체 ÷ 판정 가능 행). 피벗 테이블과 같은 계산을 COUNTIF · COUNTIFS · SUMIF 수식으로 했고, 오른쪽 막대가 피벗 차트 자리입니다.
A11: 쓰는 법 | B11: 노트북 차트 3(또는 d1_eda_notes.md의 결제방식별 표)에서 결제방식 하나를 골라 이 파일의 같은 줄과 비교합니다. 같으면 '맞았다'와 노트북이 한 처리를, 다르면 어디서 갈렸는지(코드표 · 같은 바이어 반복 · 숫자가 아닌 칸 · '검토 필요' 처리 · 정의)를 '손 검산' 절에 적습니다.
A12: 주의 | B12: 정답이 아니라 '고치지 않고 센 기준선'입니다. 다르면 틀린 것이 아니라 원인을 찾을 차례입니다. 정제한 숫자는 2일차에 만듭니다.
A13: 읽기만 | B13: 이 파일은 고치지 않습니다. 바꿔 보려면 workbench/day1/data/에 복사해서 씁니다. 엑셀로 열면 ~$로 시작하는 잠금 파일이 생기는데, 커밋하지 않습니다.
A14: 더 해 보기 | B14: 사본의 코드표 시트에 내 코드표(실습 B-1 · 03의 CSV)의 '원래 표기 · 표준 코드' 두 열을 붙이면 다시 계산됩니다. 결제방식_피벗 B14가 0인지 보세요.
A15: 다시 계산 | B15: 수식이 셀에 남아 있어 엑셀(2010 이후) · 웹용 Excel이 열 때 다시 계산합니다. AI 도구는 저장된 값을 읽습니다 — 둘은 같습니다.

Sheet 결제방식_피벗
A1: 결제방식별 연체 바이어 — 원천 그대로 단순 집계(피벗과 같은 계산)
A2: 행 = 표준코드(buyers!X) · 값 = 행 수(COUNTIF) · 판정 불가(COUNTIFS 빈칸) · 연체 합계(SUMIF) · 비율 = 연체 ÷ 판정 가능 행
A3: 표준 코드 | B3: 뜻 | C3: 바이어 행 수 | D3: 연체 판정 불가 | E3: 판정 가능 행 | F3: 연체 바이어 | G3: 연체 바이어 비율
A4: TT_ADV | B4: T/T 선수금 — 선적 전에 전액 | C4: =COUNTIF(buyers!$X$2:$X$154,A4) -> 12 | D4: =COUNTIFS(buyers!$X$2:$X$154,A4,buyers!$Y$2:$Y$154,"") -> 0 | E4: =C4-D4 -> 12 | F4: =SUMIF(buyers!$X$2:$X$154,A4,buyers!$Y$2:$Y$154) -> 0 | G4: =IF(E4=0,"",F4/E4) -> 0
A5: TT_SPLIT_30_70 | B5: 선수금 + 잔금 분할 | C5: =COUNTIF(buyers!$X$2:$X$154,A5) -> 8 | D5: =COUNTIFS(buyers!$X$2:$X$154,A5,buyers!$Y$2:$Y$154,"") -> 0 | E5: =C5-D5 -> 8 | F5: =SUMIF(buyers!$X$2:$X$154,A5,buyers!$Y$2:$Y$154) -> 1 | G5: =IF(E5=0,"",F5/E5) -> 0.125
A6: LC_SIGHT | B6: L/C 일람불 | C6: =COUNTIF(buyers!$X$2:$X$154,A6) -> 9 | D6: =COUNTIFS(buyers!$X$2:$X$154,A6,buyers!$Y$2:$Y$154,"") -> 0 | E6: =C6-D6 -> 9 | F6: =SUMIF(buyers!$X$2:$X$154,A6,buyers!$Y$2:$Y$154) -> 0 | G6: =IF(E6=0,"",F6/E6) -> 0
A7: LC_USANCE | B7: L/C 기한부 | C7: =COUNTIF(buyers!$X$2:$X$154,A7) -> 4 | D7: =COUNTIFS(buyers!$X$2:$X$154,A7,buyers!$Y$2:$Y$154,"") -> 0 | E7: =C7-D7 -> 4 | F7: =SUMIF(buyers!$X$2:$X$154,A7,buyers!$Y$2:$Y$154) -> 0 | G7: =IF(E7=0,"",F7/E7) -> 0
A8: DP | B8: D/P 지급인도 추심 | C8: =COUNTIF(buyers!$X$2:$X$154,A8) -> 4 | D8: =COUNTIFS(buyers!$X$2:$X$154,A8,buyers!$Y$2:$Y$154,"") -> 0 | E8: =C8-D8 -> 4 | F8: =SUMIF(buyers!$X$2:$X$154,A8,buyers!$Y$2:$Y$154) -> 0 | G8: =IF(E8=0,"",F8/E8) -> 0
A9: DA | B9: D/A 인수인도 추심 | C9: =COUNTIF(buyers!$X$2:$X$154,A9) -> 22 | D9: =COUNTIFS(buyers!$X$2:$X$154,A9,buyers!$Y$2:$Y$154,"") -> 2 | E9: =C9-D9 -> 20 | F9: =SUMIF(buyers!$X$2:$X$154,A9,buyers!$Y$2:$Y$154) -> 4 | G9: =IF(E9=0,"",F9/E9) -> 0.2
A10: OA | B10: O/A 사후송금(외상) | C10: =COUNTIF(buyers!$X$2:$X$154,A10) -> 81 | D10: =COUNTIFS(buyers!$X$2:$X$154,A10,buyers!$Y$2:$Y$154,"") -> 2 | E10: =C10-D10 -> 79 | F10: =SUMIF(buyers!$X$2:$X$154,A10,buyers!$Y$2:$Y$154) -> 14 | G10: =IF(E10=0,"",F10/E10) -> 0.17721519
A11: 미분류 | B11: 코드표에서 찾지 못한 표기 | C11: =COUNTIF(buyers!$X$2:$X$154,A11) -> 13 | D11: =COUNTIFS(buyers!$X$2:$X$154,A11,buyers!$Y$2:$Y$154,"") -> 0 | E11: =C11-D11 -> 13 | F11: =SUMIF(buyers!$X$2:$X$154,A11,buyers!$Y$2:$Y$154) -> 5 | G11: =IF(E11=0,"",F11/E11) -> 0.38461538
A12: 합계 | C12: =SUM(C4:C11) -> 153 | D12: =SUM(D4:D11) -> 4 | E12: =SUM(E4:E11) -> 149 | F12: =SUM(F4:F11) -> 24 | G12: =IF(E12=0,"",F12/E12) -> 0.16107383
A14: 표준 코드 8칸 밖으로 분류된 행 | B14: =COUNTA(buyers!$A$2:$A$154)-C12 -> 0 | C14: ← 0이어야 합니다. 코드표 시트를 내 코드표로 바꿨을 때 '검토 필요'처럼 8칸에 없는 값이 있으면 여기에 셉니다.
A16: 읽는 법 | B16: 비율의 분모는 '판정 가능 행'(연체일수가 숫자인 행)입니다. 같은 바이어가 두 줄이면 두 번 셉니다 — 원천 그대로 센 값이기 때문입니다.
B17: 노트북 숫자와 다르면 원인을 찾을 차례입니다: 코드표 차이 · 같은 바이어 반복 · 숫자가 아닌 연체일 · '검토 필요' 처리 · 정의(연체일 > 0).

Sheet buyers
A1: buyer_id | B1: buyer_name | C1: country | D1: country_code | E1: region | F1: industry | G1: segment | H1: buyer_type | I1: payment_terms_raw | J1: ar_balance | K1: ar_currency | L1: max_dpd_days | M1: overdue_amount | N1: pay_score | O1: oecd_crc | P1: ksure_insured | Q1: since_date | R1: fin_summary_text | S1: revenue_usd_fy2025 | T1: current_ratio_fy2025 | U1: debt_to_equity_fy2025 | V1: dso_fy2025 | W1: op_margin_fy2025 | X1: 표준코드 | Y1: 연체
A2: B001 | B2: Camano Meettechniek B.V. | C2: Netherlands | D2: NLD | E2: 서유럽 | F2: epc_contractor | G2: private | H2: PRIVATE | I2: T/T 90 DAYS AFTER B/L | J2: 23730 | K2: EUR | L2: 0 | M2: 0 | O2: - | P2: N | Q2: 2013.12.9 | R2: Revenue rose 2% YoY to USD 6.8M; operating margin 11.8%. | S2: 6846000 | T2: 1.631 | U2: 0.6007 | V2: 34.76 | W2: 0.1183 | X2: =IFERROR(INDEX('코드표'!$B$2:$B$500,MATCH(TRIM(I2),'코드표'!$A$2:$A$500,0)),"미분류") -> OA | Y2: =IFERROR(IF(--L2>0,1,0),"") -> 0
A3: B002 | B3: Hefei Belum Machinery Co., Ltd. | C3: China | D3: CHN | E3: 동아시아 | F3: oem_manufacturer | G3: private | H3: PRIVATE | I3: OA90 | J3: USD 10,070 | K3: USD | L3: 0 | M3: 0 | N3: 79 | O3: 2 | P3: N | Q3: 2020-09-14 | R3: Revenue rose 13% YoY to USD 8.2M; operating margin 6.7%. | S3: 8185000 | T3: 1.7722 | U3: 1.0233 | V3: 41.7 | W3: 0.0672 | X3: =IFERROR(INDEX('코드표'!$B$2:$B$500,MATCH(TRIM(I3),'코드표'!$A$2:$A$500,0)),"미분류") -> OA | Y3: =IFERROR(IF(--L3>0,1,0),"") -> 0
A4: B003 | B4: PT Delyn Instrumen Nusantara | C4: Indonesia | D4: IDN | E4: 동남아·남아 | F4: oem_manufacturer | G4: private | H4: PRIVATE | I4: D/A 90 | J4: 0 | K4: USD | L4: 0 | M4: 0 | N4: 78 | O4: 3 | P4: N | Q4: Jun 27 2018 | R4: Revenue fell 2% YoY to USD 5.3M; operating loss (-5.2% margin). Some line items were not disclosed. | S4: 5343000 | T4: 1.446 | V4: 80.68 | W4: -0.052 | X4: =IFERROR(INDEX('코드표'!$B$2:$B$500,MATCH(TRIM(I4),'코드표'!$A$2:$A$500,0)),"미분류") -> DA | Y4: =IFERROR(IF(--L4>0,1,0),"") -> 0
A5: B004 | B5: Eldum Automation S.A.E. | C5: Egypt | D5: EGY | E5: 중동·아프리카 | F5: oem_manufacturer | G5: private | H5: PRIVATE | I5: Confirmed L/C at sight | J5: 0 | K5: USD | L5: 0 | M5: 0 | O5: 6 | P5: N | Q5: Jun 20 2024 | R5: Revenue rose 9% YoY to USD 73.9M; operating margin 7.2%. | S5: 73932000 | T5: 2.1786 | U5: 1.323 | V5: 30.31 | W5: 0.0723 | X5: =IFERROR(INDEX('코드표'!$B$2:$B$500,MATCH(TRIM(I5),'코드표'!$A$2:$A$500,0)),"미분류") -> LC_SIGHT | Y5: =IFERROR(IF(--L5>0,1,0),"") -> 0
A6: B005 | B6: Xanolin Distribution Co., Ltd. | C6: Vietnam | D6: VNM | E6: 동남아·남아 | F6: distributor | G6: private | H6: PRIVATE | I6: T/T 90 days after B/L | J6: 346360 | K6: usd | L6: 13 | M6: 19920 | N6: 71 | O6: 3 | P6: Y | Q6: 2023.7.21 | R6: Revenue rose 11% YoY to USD 204.9M; operating margin 13.4%. Some line items were not disclosed. | S6: 204875000 | U6: 0.9715 | V6: 31.33 | W6: 0.1337 | X6: =IFERROR(INDEX('코드표'!$B$2:$B$500,MATCH(TRIM(I6),'코드표'!$A$2:$A$500,0)),"미분류") -> OA | Y6: =IFERROR(IF(--L6>0,1,0),"") -> 1
A7: B006 | B7: Zarum Machinery Sdn. Bhd. | C7: Malaysia | D7: MYS | E7: 동남아·남아 | F7: oem_manufacturer | G7: private | H7: PRIVATE | I7: O/A 30 | J7: 0 | K7: USD | L7: 0 | M7: 0 | O7: 2 | P7: Y | Q7: 29/04/2014 | R7: FY2025 financial statements not received. | X7: =IFERROR(INDEX('코드표'!$B$2:$B$500,MATCH(TRIM(I7),'코드표'!$A$2:$A$500,0)),"미분류") -> OA | Y7: =IFERROR(IF(--L7>0,1,0),"") -> 0
A8: B007 | B8: Quineth Handel B.V. | C8: Netherlands | D8: NLD | E8: 서유럽 | F8: distributor | G8: private | H8: PRIVATE | I8: O/A 90 | K8: EUR | L8: 0 | M8: 0 | N8: 60 | O8: - | P8: Y | Q8: Jan 20 2017 | R8: Revenue rose 14% YoY to USD 27.5M; operating margin 6.3%. | S8: 27528000 | T8: 2.3736 | U8: 0.4913 | V8: 55.17 | W8: 0.0631 | X8: =IFERROR(INDEX('코드표'!$B$2:$B$500,MATCH(TRIM(I8),'코드표'!$A$2:$A$500,0)),"미분류") -> OA | Y8: =IFERROR(IF(--L8>0,1,0),"") -> 0
A9: B008 | B9: Uleon Anlagenbau GmbH | C9: Germany | D9: DEU | E9: 서유럽 | F9: oem_manufacturer | G9: private | H9: PRIVATE | I9: 60 days O/A | K9: EUR | L9: 31 | M9: 약 7천 | N9: 82 | O9: - | P9: Y | Q9: 13/07/2025 | R9: Revenue rose 8% YoY to USD 14.1M; operating margin 8.4%. | S9: 14083000 | T9: 1.3349 | U9: 1.6475 | V9: 56.58 | W9: 0.0836 | X9: =IFERROR(INDEX('코드표'!$B$2:$B$500,MATCH(TRIM(I9),'코드표'!$A$2:$A$500,0)),"미분류") -> 미분류 | Y9: =IFERROR(IF(--L9>0,1,0),"") -> 1
A10: B009 | B10: Suzhou Delaro Supply Co., Ltd. | C10: China | D10: CHN | E10: 동아시아 | F10: distributor | G10: private | H10: PRIVATE | I10: D/A 90 | J10: 385600 | K10: CNY | L10: 0 | M10: 0 | O10: 2 | P10: Y | Q10: 2014-03-06 | R10: Revenue fell 4% YoY to USD 25.1M; operating margin 2.4%. | S10: 25116000 | T10: 1.0375 | U10: 5.7625 | V10: 82.02 | W10: 0.0236 | X10: =IFERROR(INDEX('코드표'!$B$2:$B$500,MATCH(TRIM(I10),'코드표'!$A$2:$A$500,0)),"미분류") -> DA | Y10: =IFERROR(IF(--L10>0,1,0),"") -> 0
A11: B010 | B11: Gorion Handel Sp. z o.o. | C11: Poland | D11: POL | E11: 중동부유럽 | F11: retail | G11: private | H11: PRIVATE | I11: TT | J11: 0 | K11: EUR | L11: 0 | M11: 0 | O11: - | P11: N | Q11: 2021.7.19 | R11: Revenue rose 1% YoY to USD 5.9M; operating margin 0.4%. | S11: 5926000 | T11: 1.1533 | U11: 2.7635 | V11: 70.89 | W11: 0.0035 | X11: =IFERROR(INDEX('코드표'!$B$2:$B$500,MATCH(TRIM(I11),'코드표'!$A$2:$A$500,0)),"미분류") -> TT_ADV | Y11: =IFERROR(IF(--L11>0,1,0),"") -> 0
A12: B011 | B12: Fenolin Utilities Ltd. | C12: India | D12: IND | E12: 동남아·남아 | F12: utility | G12: private | H12: PRIVATE | I12: Confirmed L/C at sight | J12: 0 | K12: USD | L12: 0 | M12: 0 | O12: 3 | P12: N | Q12: May 29 2017 | R12: Revenue rose 8% YoY to USD 7.7M. Some line items were not disclosed. | S12: 7731000 | T12: 1.1832 | U12: 4.8318 | X12: =IFERROR(INDEX('코드표'!$B$2:$B$500,MATCH(TRIM(I12),'코드표'!$A$2:$A$500,0)),"미분류") -> LC_SIGHT | Y12: =IFERROR(IF(--L12>0,1,0),"") -> 0
A13: B012 | B13: PT Varasta Sarana Industri | C13: Indonesia | D13: IDN | E13: 동남아·남아 | F13: oem_manufacturer | G13: private | H13: PRIVATE | I13: DP sight | J13: 0 | K13: USD | L13: 0 | M13: 0 | N13: 79 | O13: 3 | P13: N | Q13: 2014-08-15 | R13: Revenue fell 5% YoY to USD 10.5M; operating loss (-9.8% margin). Current ratio below 1.0 (0.96). Some line items were not disclosed. | S13: 10451000 | T13: 0.9616 | U13: 2.6465 | W13: -0.0977 | X13: =IFERROR(INDEX('코드표'!$B$2:$B$500,MATCH(TRIM(I13),'코드표'!$A$2:$A$500,0)),"미분류") -> DP | Y13: =IFERROR(IF(--L13>0,1,0),"") -> 0
A14: B013 | B14: Tianjin Wenum Manufacturing Co., Ltd. | C14: China | D14: CHN | E14: 동아시아 | F14: oem_manufacturer | G14: private | H14: PRIVATE | I14: 100% T/T before shipment | J14: 0 | K14: US$ | L14: 0 | M14: 0 | O14: 2 | P14: N | Q14: May 6 2023 | R14: Revenue fell 27% YoY to USD 46.5M; operating loss (-24.9% margin). Shareholders' equity is negative. Auditor flagged going-concern uncertainty. | S14: 46504000 | T14: 0.36 | U14: -7.2235 | V14: 86 | W14: -0.2487 | X14: =IFERROR(INDEX('코드표'!$B$2:$B$500,MATCH(TRIM(I14),'코드표'!$A$2:$A$500,0)),"미분류") -> TT_ADV | Y14: =IFERROR(IF(--L14>0,1,0),"") -> 0
A15: B014 | B15: Briion Projects Corp. | C15: United States | D15: USA | E15: 북미·중남미 | F15: epc_contractor | G15: private | H15: PRIVATE | I15: usance l/c 90 days | J15: 29910 | K15: USD | L15: 0 | M15: 0 | O15: - | P15: N | Q15: 22/07/2017 | R15: Revenue fell 3% YoY to USD 148.0M; operating margin 7.5%. | S15: 148025000 | T15: 1.6759 | U15: 0.5598 | V15: 51.68 | W15: 0.0754 | X15: =IFERROR(INDEX('코드표'!$B$2:$B$500,MATCH(TRIM(I15),'코드표'!$A$2:$A$500,0)),"미분류") -> LC_USANCE | Y15: =IFERROR(IF(--L15>0,1,0),"") -> 0
A16: B015 | B16: Pelant Automation Co., Ltd. | C16: Taiwan | D16: TWN | E16: 동아시아 | F16: oem_manufacturer | G16: private | H16: PRIVATE | I16: D/A 90 | J16: 7680 | K16: USD | L16: 0 | M16: 0 | N16: 74 | O16: 2 | P16: N | Q16: 01/06/2021 | R16: Revenue fell 23% YoY to USD 16.5M; operating margin 3.4%. | S16: 16500000 | T16: 1.4218 | U16: 1.0032 | V16: 48.73 | W16: 0.0342 | X16: =IFERROR(INDEX('코드표'!$B$2:$B$500,MATCH(TRIM(I16),'코드표'!$A$2:$A$500,0)),"미분류") -> DA | Y16: =IFERROR(IF(--L16>0,1,0),"") -> 0
A17: B016 | B17: Galova Machinery Ltd. | C17: India | D17: IND | E17: 동남아·남아 | F17: oem_manufacturer | G17: private | H17: PRIVATE | I17: 신용장 일람불 | J17: 0 | K17: USD | L17: 0 | M17: 0 | O17: 3 | P17: N | Q17: 2014-11-19 | R17: FY2025 financial statements not received. | X17: =IFERROR(INDEX('코드표'!$B$2:$B$500,MATCH(TRIM(I17),'코드표'!$A$2:$A$500,0)),"미분류") -> 미분류 | Y17: =IFERROR(IF(--L17>0,1,0),"") -> 0
A18: B017 | B18: Corasta Instruments S.A.E. | C18: Egypt | D18: EGY | E18: 중동·아프리카 | F18: distributor | G18: private | H18: PRIVATE | I18: o/a 90 | J18: 0 | K18: USD | L18: 0 | M18: 0 | N18: 70 | O18: 6 | P18: N | Q18: 2015-01-29 | R18: Revenue rose 0% YoY to USD 5.5M. Some line items were not disclosed. | S18: 5495000 | T18: 1.1668 | U18: 0.8533 | V18: 66.16 | X18: =IFERROR(INDEX('코드표'!$B$2:$B$500,MATCH(TRIM(I18),'코드표'!$A$2:$A$500,0)),"미분류") -> OA | Y18: =IFERROR(IF(--L18>0,1,0),"") -> 0
A19: B018 | B19: Corari Industrie B.V. | C19: Netherlands | D19: NLD | E19: 서유럽 | F19: oem_manufacturer | G19: private | H19: PRIVATE | I19: O/A 30 | J19: 2220 | K19: EUR | L19: 0 | M19: 0 | N19: 80 | O19: - | P19: Y | Q19: Oct 7 2018 | R19: Revenue rose 15% YoY to USD 31.9M; operating loss (-2.0% margin). | S19: 31866000 | T19: 1.5314 | U19: 1.8108 | V19: 69.85 | W19: -0.0199 | X19: =IFERROR(INDEX('코드표'!$B$2:$B$500,MATCH(TRIM(I19),'코드표'!$A$2:$A$500,0)),"미분류") -> OA | Y19: =IFERROR(IF(--L19>0,1,0),"") -> 0
A20: B019 | B20: Saryn Machinery Inc. | C20: United States | D20: USA | E20: 북미·중남미 | F20: oem_manufacturer | G20: private | H20: PRIVATE | I20: D/A 90 days | J20: 0 | K20: USD | L20: 0 | M20: 0 | N20: 74 | O20: - | P20: Y | Q20: 25/01/2015 | R20: Revenue fell 5% YoY to USD 13.3M; operating margin 12.5%. Some line items were not disclosed. | S20: 13268000 | T20: 1.8875 | U20: 1.2413 | W20: 0.1246 | X20: =IFERROR(INDEX('코드표'!$B$2:$B$500,MATCH(TRIM(I20),'코드표'!$A$2:$A$500,0)),"미분류") -> DA | Y20: =IFERROR(IF(--L20>0,1,0),"") -> 0
A21: B020 | B21: Velida Machinery Est. | C21: Saudi Arabia | D21: SAU | E21: 중동·아프리카 | F21: oem_manufacturer | G21: private | H21: PRIVATE | I21: T/T 30/70 | J21: 0 | K21: USD | L21: 0 | M21: 0 | O21: 2 | P21: Y | Q21: 01/12/2019 | R21: Revenue rose 12% YoY to USD 16.2M; operating loss (-6.3% margin). | S21: 16153000 | T21: 1.1525 | U21: 5.1695 | V21: 106.72 | W21: -0.0632 | X21: =IFERROR(INDEX('코드표'!$B$2:$B$500,MATCH(TRIM(I21),'코드표'!$A$2:$A$500,0)),"미분류") -> TT_SPLIT_30_70 | Y21: =IFERROR(IF(--L21>0,1,0),"") -> 0
A22: B021 | B22: Xiamen Rinant Engineering Co., Ltd. | C22: China | D22: CHN | E22: 동아시아 | F22: epc_contractor | G22: private | H22: PRIVATE | I22: Open account 60 days | J22: 538300 | K22: CNY | L22: 0 | M22: 0 | N22: 83 | O22: 2 | P22: N | Q22: 2016-01-20 | R22: Revenue rose 14% YoY to USD 49.4M; operating margin 4.3%. Some line items were not disclosed. | S22: 49384000 | T22: 1.2798 | U22: 0.8295 | W22: 0.0432 | X22: =IFERROR(INDEX('코드표'!$B$2:$B$500,MATCH(TRIM(I22),'코드표'!$A$2:$A$500,0)),"미분류") -> OA | Y22: =IFERROR(IF(--L22>0,1,0),"") -> 0
A23: B022 | B23: PT Kavrendo Instrumen Nusantara | C23: Indonesia | D23: IDN | E23: 동남아·남아 | G23: private | H23: PRIVATE | I23: open acct 90d | J23: 72,360 | K23: USD | L23: 3 | M23: 4330 | N23: 79 | O23: 3 | P23: Y | Q23: Jan 17 2020 | R23: Revenue of USD 169.3M; operating margin 8.7%. | S23: 169300000 | T23: 1.3591 | U23: 1.252 | V23: 35.86 | W23: 0.0868 | X23: =IFERROR(INDEX('코드표'!$B$2:$B$500,MATCH(TRIM(I23),'코드표'!$A$2:$A$500,0)),"미분류") -> 미분류 | Y23: =IFERROR(IF(--L23>0,1,0),"") -> 1
A24: B023 | B24: PT Morora Teknik Indonesia | C24: Indonesai | D24: IDN | E24: 동남아·남아 | F24: distributor | G24: private | H24: PRIVATE | I24: D/A 90 days | J24: 22410 | K24: USD | L24: 0 | M24: 0 | N24: 78 | O24: 3 | P24: Y | Q24: 2012-03-21 | R24: FY2025 financial statements not received. | X24: =IFERROR(INDEX('코드표'!$B$2:$B$500,MATCH(TRIM(I24),'코드표'!$A$2:$A$500,0)),"미분류") -> DA | Y24: =IFERROR(IF(--L24>0,1,0),"") -> 0
A25: B024 | B25: Praum Outlets Inc. | C25: United States | D25: USA | E25: 북미·중남미 | F25: retail | G25: private | H25: PRIVATE | I25: O/A 30 | J25: 0 | K25: USD | L25: 0 | M25: 0 | N25: 77 | O25: - | P25: Y | Q25: 2012-12-01 | R25: Revenue of USD 10.9M; operating margin 8.7%. | S25: 10854000 | T25: 1.1433 | U25: 2.599 | V25: 80.51 | W25: 0.0866 | X25: =IFERROR(INDEX('코드표'!$B$2:$B$500,MATCH(TRIM(I25),'코드표'!$A$2:$A$500,0)),"미분류") -> OA | Y25: =IFERROR(IF(--L25>0,1,0),"") -> 0
A26: B025 | B26: Junant Anlagenbau AG | C26: Germany | D26: DEU | E26: 서유럽 | F26: epc_contractor | G26: private | H26: PRIVATE | I26: T/T 60 DAYS AFTER B/L | J26: 1370 | K26: EUR | L26: 0 | M26: 0 | N26: 79 | O26: - | P26: Y | Q26: 2022-06-29 | R26: Revenue fell 8% YoY to USD 5.4M. Some line items were not disclosed. | S26: 5387000 | T26: 2.1219 | U26: 0.7072 | V26: 59.08 | X26: =IFERROR(INDEX('코드표'!$B$2:$B$500,MATCH(TRIM(I26),'코드표'!$A$2:$A$500,0)),"미분류") -> OA | Y26: =IFERROR(IF(--L26>0,1,0),"") -> 0
A27: B026 | B27: Nelova Engineering (Thailand) Co., Ltd. | C27: Thailand | D27: THA | E27: 동남아·남아 | F27: epc_contractor | G27: private | H27: PRIVATE | I27: O/A 60 | J27: 4860 | K27: USD | L27: 0 | M27: 0 | N27: 82 | O27: 3 | P27: Y | Q27: 2013-05-09 | R27: FY2025 financial statements not received. | X27: =IFERROR(INDEX('코드표'!$B$2:$B$500,MATCH(TRIM(I27),'코드표'!$A$2:$A$500,0)),"미분류") -> OA | Y27: =IFERROR(IF(--L27>0,1,0),"") -> 0
A28: B027 | B28: Ralant Water Services Co., Ltd. | C28: Vietnma | D28: VNM | E28: 동남아·남아 | F28: utility | G28: private | H28: PRIVATE | I28: T/T in advance | J28: 0 | K28: usd | L28: 0 | M28: 0 | O28: 3 | P28: N | Q28: 2023-05-06 | R28: FY2025 financial statements not received. | X28: =IFERROR(INDEX('코드표'!$B$2:$B$500,MATCH(TRIM(I28),'코드표'!$A$2:$A$500,0)),"미분류") -> TT_ADV | Y28: =IFERROR(IF(--L28>0,1,0),"") -> 0
A29: B028 | B29: Davura Kogyo Co., Ltd. | C29: Japan | D29: JPN | E29: 동아시아 | F29: distributor | G29: private | H29: PRIVATE | I29: Net 90 | J29: 35491000 | K29: JPY | L29: 0 | M29: 0 | N29: 83 | O29: - | P29: Y | Q29: 2018-03-06 | R29: Revenue rose 9% YoY to USD 160.7M; operating margin 13.7%. | S29: 160688000 | T29: 1.738 | U29: 0.5585 | V29: 38.16 | W29: 0.1375 | X29: =IFERROR(INDEX('코드표'!$B$2:$B$500,MATCH(TRIM(I29),'코드표'!$A$2:$A$500,0)),"미분류") -> 미분류 | Y29: =IFERROR(IF(--L29>0,1,0),"") -> 0
A30: B029 | B30: Dongguan Tarella Engineering Co., Ltd. | C30: China | D30: CHN | E30: 동아시아 | F30: epc_contractor | G30: private | H30: PRIVATE | I30: Open account 60 days | J30: 88940 | K30: USD | L30: 0 | M30: 0 | N30: 59 | O30: 2 | P30: Y | Q30: Jun 20 2017 | R30: Revenue fell 20% YoY to USD 437.3M; operating margin 10.2%. | S30: 437297000 | T30: 1.2413 | U30: 2.1817 | V30: 86.79 | W30: 0.1023 | X30: =IFERROR(INDEX('코드표'!$B$2:$B$500,MATCH(TRIM(I30),'코드표'!$A$2:$A$500,0)),"미분류") -> OA | Y30: =IFERROR(IF(--L30>0,1,0),"") -> 0
A31: B030 | B31: Calaro Endüstriyel Ölçüm A.Ş. | C31: Türkiye | D31: TUR | E31: 중동부유럽 | F31: epc_contractor | G31: private | H31: PRIVATE | I31: T/T 60 days after B/L | J31: 0 | K31: usd | L31: 0 | M31: 0 | N31: 80 | O31: 5 | P31: N | Q31: 2012.9.20 | R31: Revenue fell 0% YoY to USD 45.0M; operating loss (-8.2% margin). Current ratio below 1.0 (0.73). Some line items were not disclosed. | S31: 45005000 | T31: 0.728 | V31: 104.29 | W31: -0.0825 | X31: =IFERROR(INDEX('코드표'!$B$2:$B$500,MATCH(TRIM(I31),'코드표'!$A$2:$A$500,0)),"미분류") -> OA | Y31: =IFERROR(IF(--L31>0,1,0),"") -> 0
A32: B031 | B32: Kalaro Industrial S.A. de C.V. | C32: Mexico | D32: MEX | E32: 북미·중남미 | F32: oem_manufacturer | G32: private | H32: PRIVATE | I32: T/T 60days | J32: 70120 | K32: USD | L32: 36 | M32: 19200 | N32: 77 | O32: 3 | P32: Y | Q32: 2024.10.4 | R32: Revenue rose 1% YoY to USD 243.2M; operating margin 7.5%. Some line items were not disclosed. | S32: 243199000 | V32: 60.53 | W32: 0.0755 | X32: =IFERROR(INDEX('코드표'!$B$2:$B$500,MATCH(TRIM(I32),'코드표'!$A$2:$A$500,0)),"미분류") -> OA | Y32: =IFERROR(IF(--L32>0,1,0),"") -> 1
A33: B032 | B33: Nilora Water & Wastewater Authority | C33: Egypt | D33: EGY | E33: 중동·아프리카 | F33: public_agency | G33: public | H33: EM_GOV | I33: Net 30 days after receipt of invoice | J33: 0 | K33: US$ | L33: 0 | M33: 0 | N33: 80 | O33: 6 | P33: Y | Q33: 2019-04-10 | R33: Revenue rose 7% YoY to USD 138.8M. Some line items were not disclosed. | S33: 138829000 | U33: 1.899 | X33: =IFERROR(INDEX('코드표'!$B$2:$B$500,MATCH(TRIM(I33),'코드표'!$A$2:$A$500,0)),"미분류") -> OA | Y33: =IFERROR(IF(--L33>0,1,0),"") -> 0
A34: B033 | B34: Calum Contracting JSC | C34: Vietnam | D34: VNM | E34: 동남아·남아 | F34: epc_contractor | G34: private | H34: PRIVATE | I34: Confirmed L/C at sight | J34: 0 | K34: USD | L34: 0 | M34: 0 | O34: 3 | P34: N | Q34: 2020.10.6 | R34: Revenue rose 6% YoY to USD 21.4M. Some line items were not disclosed. | S34: 21381000 | T34: 2.1223 | X34: =IFERROR(INDEX('코드표'!$B$2:$B$500,MATCH(TRIM(I34),'코드표'!$A$2:$A$500,0)),"미분류") -> LC_SIGHT | Y34: =IFERROR(IF(--L34>0,1,0),"") -> 0
A35: B034 | B35: Helvara Humanitarian Supply Agency | C35: Germany | D35: DEU | E35: 서유럽 | F35: public_agency | G35: public | H35: UN | I35: Net 30 days after receipt of invoice | J35: 10080 | K35: EUR | L35: 0 | M35: 0 | N35: 77 | O35: - | P35: N | Q35: 2025-11-02 | R35: Revenue fell 6% YoY to USD 359.1M; operating margin 11.8%. | S35: 359145000 | T35: 2.1808 | U35: 0.4081 | V35: 43.36 | W35: 0.1184 | X35: =IFERROR(INDEX('코드표'!$B$2:$B$500,MATCH(TRIM(I35),'코드표'!$A$2:$A$500,0)),"미분류") -> OA | Y35: =IFERROR(IF(--L35>0,1,0),"") -> 0
A36: B035 | B36: Rinella Distribution Co., Ltd. | C36: Taiwan | D36: TWN | E36: 동아시아 | F36: distributor | G36: private | H36: PRIVATE | I36: T/T in advance | J36: 17,800 | K36: USD | L36: 0 | M36: 0 | O36: 2 | P36: N | Q36: 10/11/2017 | R36: Revenue rose 16% YoY to USD 18.0M; operating loss (-1.7% margin). Some line items were not disclosed. | S36: 17999000 | U36: 2.1336 | V36: 74.71 | W36: -0.0174 | X36: =IFERROR(INDEX('코드표'!$B$2:$B$500,MATCH(TRIM(I36),'코드표'!$A$2:$A$500,0)),"미분류") -> TT_ADV | Y36: =IFERROR(IF(--L36>0,1,0),"") -> 0
A37: B036 | B37: Quinano Trading JSC | C37: Vietnam | D37: VNM | E37: 동남아·남아 | F37: distributor | G37: private | H37: PRIVATE | I37: TT | J37: 0 | K37: USD | L37: 0 | M37: 0 | N37: 78 | O37: 3 | P37: N | Q37: 2023-06-16 | R37: FY2025 financial statements not received. | X37: =IFERROR(INDEX('코드표'!$B$2:$B$500,MATCH(TRIM(I37),'코드표'!$A$2:$A$500,0)),"미분류") -> TT_ADV | Y37: =IFERROR(IF(--L37>0,1,0),"") -> 0
A38: B037 | B38: Bexova Industries Est. | C38: KSA | D38: SAU | E38: 중동·아프리카 | F38: oem_manufacturer | G38: private | H38: PRIVATE | I38: DA90 | K38: usd | L38: 0 | M38: 0 | N38: 76 | O38: 2 | P38: Y | Q38: 02/10/2016 | R38: Revenue rose 9% YoY to USD 48.0M; operating margin 7.9%. Current ratio below 1.0 (0.73). | S38: 47961000 | T38: 0.7327 | U38: 0.9712 | V38: 49.46 | W38: 0.079 | X38: =IFERROR(INDEX('코드표'!$B$2:$B$500,MATCH(TRIM(I38),'코드표'!$A$2:$A$500,0)),"미분류") -> DA | Y38: =IFERROR(IF(--L38>0,1,0),"") -> 0
A39: B038 | B39: Varix Anlagenbau GmbH | C39: Germany | D39: DEU | E39: 서유럽 | F39: retail | G39: private | H39: PRIVATE | I39: tt | J39: 0 | K39: EUR | L39: 0 | M39: 0 | O39: - | P39: N | Q39: 2023.5.16 | R39: Revenue rose 3% YoY to USD 6.6M; operating loss (-5.3% margin). | S39: 6552000 | T39: 1.0521 | U39: 4.6103 | V39: 98.1 | W39: -0.0534 | X39: =IFERROR(INDEX('코드표'!$B$2:$B$500,MATCH(TRIM(I39),'코드표'!$A$2:$A$500,0)),"미분류") -> TT_ADV | Y39: =IFERROR(IF(--L39>0,1,0),"") -> 0
A40: B039 | B40: Zaryn Industries Est. | C40: Saudi Arabia | D40: SAU | E40: 중동·아프리카 | F40: oem_manufacturer | G40: private | H40: PRIVATE | I40: 30% T/T advance, 70% within 30 days after B/L | J40: 0 | K40: USD | L40: 0 | M40: 0 | N40: 72 | O40: 2 | P40: N | Q40: 2025-11-01 | R40: Revenue fell 7% YoY to USD 7.4M; operating margin 6.8%. Some line items were not disclosed. | S40: 7402000 | T40: 1.2788 | U40: 2.0451 | W40: 0.0675 | X40: =IFERROR(INDEX('코드표'!$B$2:$B$500,MATCH(TRIM(I40),'코드표'!$A$2:$A$500,0)),"미분류") -> TT_SPLIT_30_70 | Y40: =IFERROR(IF(--L40>0,1,0),"") -> 0
...

Sheet 코드표
A1: 원래 표기 | B1: 표준 코드 | C1: 메모
A2: T/T in advance | B2: TT_ADV
A3: TT ADVANCE | B3: TT_ADV
A4: 100% T/T before shipment | B4: TT_ADV
A5: T/T | B5: TT_ADV | C5: 표기만으로는 선적 전 · 후를 알 수 없다 — 공개 사전은 TT_ADV로 두었다. 원장(인보이스)에서 확인할 표기
A6: TT | B6: TT_ADV | C6: 표기만으로는 선적 전 · 후를 알 수 없다 — 공개 사전은 TT_ADV로 두었다. 원장(인보이스)에서 확인할 표기
A7: T/T 30/70 | B7: TT_SPLIT_30_70
A8: 30% T/T advance, 70% within 30 days after B/L | B8: TT_SPLIT_30_70
A9: T/T 30:70 | B9: TT_SPLIT_30_70
A10: O/A 30 | B10: OA
A11: OA 30 days | B11: OA
A12: O/A30 | B12: OA
A13: T/T 30 days after B/L | B13: OA
A14: O/A 60 | B14: OA
A15: O/A60 | B15: OA
A16: OA 60 days | B16: OA
A17: T/T 60days | B17: OA
A18: T/T 60 days after B/L | B18: OA
... A43: Usance L/C 90 days | B43: LC_USANCE
A45: 원천: data/data_dictionary.xlsx 시트 payment_terms_map(42개 표기) — 열 순서는 내 코드표 CSV의 앞 두 열(원래 표기 · 표준 코드)과 같습니다
