Workbook

Sheet README
A1: Day5 RAG 평가 시트 — 채팅(Claude · ChatGPT 프로젝트)으로 한 검색을 숫자로 잰다. 코드 길(eval.py)을 쓴 사람은 이 시트가 필요 없다 — rag_eval.csv가 같은 계산이다.
A2: 1) 프로젝트에는 규정 PDF만 올린다. 골든셋 파일(goldset_20.csv)은 올리지 않는다 — 정답 칸(gold_ids · expected_answer)이 있어 AI가 답을 보고 맞힌다.
A3: 2) rag/goldset_questions.csv의 20줄(질문 두 열)을 새 대화에 붙이고, 문항마다 근거 조항 ID 상위 5개를 표(열: q_id · r1–r5)로 받는다 — 프롬프트 페이지의 '채팅 경로' 문장.
A4: 3) 받은 표에서 r1–r5 다섯 열(20행)을 복사해 eval 탭의 F2에 '값만' 붙여 넣는다. 조항 ID는 조 단위(HB-27 · HB-별표1)로, 공백 없이.
A5: 4) 규정 PDF에 정답이 있는 10문항(흰 줄, 노란 칸)만 채점된다. 회색 줄은 약관 등 PDF에 없는 정답이거나 정답이 없는 기권 문항이다 — 건너뛴다.
A6: 5) summary 탭에 K = 1 · 3 · 5의 P@K · R@K · F1@K, Hit@3, MRR, Top-K가 계산된다. 고른 K와 이유 한 줄을 적는다(rag_report.md에도).
A7: 6) 개선 실험(A7): 지시문 한 줄을 바꿔 다시 받은 두 번째 결과를 eval_B 탭의 F2에 붙이면 summary가 전 · 후를 나란히 보여 준다.
A8: 정의: P@K = 상위 K개 안의 정답 조항 수 ÷ K · R@K = 상위 K개 안의 정답 조항 수 ÷ 정답 조항 수 · F1@K = 2PR ÷ (P + R) — P와 R 중 낮은 쪽에 끌려간다. F1이 가장 높은 K가 Top-K.
A9: Hit@3 = 상위 3개 안에 정답이 있는 문항 비율 · MRR(상위 5) = 첫 정답 순위의 역수 평균(채팅은 상위 5개만 받으므로 5위 밖은 0). 모두 규정 PDF에 정답이 있는 문항만의 평균이다.
A10: 조항 ID: HB-(가상 한빛정밀 여신관리규정) · 예) HB-27② → HB-27, 별표1 → HB-별표1. 약관(KS-) · 법령(LAW-)은 이 저장소에 없다.

Sheet eval
A1: q_id | B1: question | C1: kind | D1: gold_id1 | E1: gold_id2 | F1: r1 | G1: r2 | H1: r3 | I1: r4 | J1: r5 | K1: hit_at_3 | L1: rr | M1: p_at_1 | N1: r_at_1 | O1: f1_at_1 | P1: p_at_3 | Q1: r_at_3 | R1: f1_at_3 | S1: p_at_5 | T1: r_at_5 | U1: f1_at_5 | W1: ← 기준 결과의 r1–r5(20행)를 F2에 값만 붙여 넣는다
A2: Q01 | B2: 중소기업이 단기수출보험(선적후)에 가입하면 부보율은? | C2: 코퍼스 밖 | K2: =IF($C2<>"규정 정답","",IF(COUNTA($F2:$J2)=0,"",IF(IF(COUNTIF($F2:$H2,$D2)>0,1,0)+IF($E2="",0,IF(COUNTIF($F2:$H2,$E2)>0,1,0))>0,1,0))) | L2: =IF($C2<>"규정 정답","",IF(COUNTA($F2:$J2)=0,"",MAX(IFERROR(1/MATCH($D2,$F2:$J2,0),0),IF($E2="",0,IFERROR(1/MATCH($E2,$F2:$J2,0),0))))) | M2: =IF($C2<>"규정 정답","",IF(COUNTA($F2:$J2)=0,"",(IF(COUNTIF($F2:$F2,$D2)>0,1,0)+IF($E2="",0,IF(COUNTIF($F2:$F2,$E2)>0,1,0)))/1)) | N2: =IF($C2<>"규정 정답","",IF(COUNTA($F2:$J2)=0,"",(IF(COUNTIF($F2:$F2,$D2)>0,1,0)+IF($E2="",0,IF(COUNTIF($F2:$F2,$E2)>0,1,0)))/IF($E2="",1,2))) | O2: =IF($C2<>"규정 정답","",IF(COUNTA($F2:$J2)=0,"",IF(M2+N2=0,0,2*M2*N2/(M2+N2)))) | P2: =IF($C2<>"규정 정답","",IF(COUNTA($F2:$J2)=0,"",(IF(COUNTIF($F2:$H2,$D2)>0,1,0)+IF($E2="",0,IF(COUNTIF($F2:$H2,$E2)>0,1,0)))/3)) | Q2: =IF($C2<>"규정 정답","",IF(COUNTA($F2:$J2)=0,"",(IF(COUNTIF($F2:$H2,$D2)>0,1,0)+IF($E2="",0,IF(COUNTIF($F2:$H2,$E2)>0,1,0)))/IF($E2="",1,2))) | R2: =IF($C2<>"규정 정답","",IF(COUNTA($F2:$J2)=0,"",IF(P2+Q2=0,0,2*P2*Q2/(P2+Q2)))) | S2: =IF($C2<>"규정 정답","",IF(COUNTA($F2:$J2)=0,"",(IF(COUNTIF($F2:$J2,$D2)>0,1,0)+IF($E2="",0,IF(COUNTIF($F2:$J2,$E2)>0,1,0)))/5)) | T2: =IF($C2<>"규정 정답","",IF(COUNTA($F2:$J2)=0,"",(IF(COUNTIF($F2:$J2,$D2)>0,1,0)+IF($E2="",0,IF(COUNTIF($F2:$J2,$E2)>0,1,0)))/IF($E2="",1,2))) | U2: =IF($C2<>"규정 정답","",IF(COUNTA($F2:$J2)=0,"",IF(S2+T2=0,0,2*S2*T2/(S2+T2))))
A3: Q02 | B3: 보험금 청구 후 언제까지 지급되나? | C3: 코퍼스 밖 | K3: =IF($C3<>"규정 정답","",IF(COUNTA($F3:$J3)=0,"",IF(IF(COUNTIF($F3:$H3,$D3)>0,1,0)+IF($E3="",0,IF(COUNTIF($F3:$H3,$E3)>0,1,0))>0,1,0))) | L3: =IF($C3<>"규정 정답","",IF(COUNTA($F3:$J3)=0,"",MAX(IFERROR(1/MATCH($D3,$F3:$J3,0),0),IF($E3="",0,IFERROR(1/MATCH($E3,$F3:$J3,0),0))))) | M3: =IF($C3<>"규정 정답","",IF(COUNTA($F3:$J3)=0,"",(IF(COUNTIF($F3:$F3,$D3)>0,1,0)+IF($E3="",0,IF(COUNTIF($F3:$F3,$E3)>0,1,0)))/1)) | N3: =IF($C3<>"규정 정답","",IF(COUNTA($F3:$J3)=0,"",(IF(COUNTIF($F3:$F3,$D3)>0,1,0)+IF($E3="",0,IF(COUNTIF($F3:$F3,$E3)>0,1,0)))/IF($E3="",1,2))) | O3: =IF($C3<>"규정 정답","",IF(COUNTA($F3:$J3)=0,"",IF(M3+N3=0,0,2*M3*N3/(M3+N3)))) | P3: =IF($C3<>"규정 정답","",IF(COUNTA($F3:$J3)=0,"",(IF(COUNTIF($F3:$H3,$D3)>0,1,0)+IF($E3="",0,IF(COUNTIF($F3:$H3,$E3)>0,1,0)))/3)) | Q3: =IF($C3<>"규정 정답","",IF(COUNTA($F3:$J3)=0,"",(IF(COUNTIF($F3:$H3,$D3)>0,1,0)+IF($E3="",0,IF(COUNTIF($F3:$H3,$E3)>0,1,0)))/IF($E3="",1,2))) | R3: =IF($C3<>"규정 정답","",IF(COUNTA($F3:$J3)=0,"",IF(P3+Q3=0,0,2*P3*Q3/(P3+Q3)))) | S3: =IF($C3<>"규정 정답","",IF(COUNTA($F3:$J3)=0,"",(IF(COUNTIF($F3:$J3,$D3)>0,1,0)+IF($E3="",0,IF(COUNTIF($F3:$J3,$E3)>0,1,0)))/5)) | T3: =IF($C3<>"규정 정답","",IF(COUNTA($F3:$J3)=0,"",(IF(COUNTIF($F3:$J3,$D3)>0,1,0)+IF($E3="",0,IF(COUNTIF($F3:$J3,$E3)>0,1,0)))/IF($E3="",1,2))) | U3: =IF($C3<>"규정 정답","",IF(COUNTA($F3:$J3)=0,"",IF(S3+T3=0,0,2*S3*T3/(S3+T3))))
A4: Q03 | B4: 결제기일이 2026-09-15인 O/A 건이 미결제다. 사고발생통지 기한은? | C4: 규정 정답 | D4: HB-20 | K4: =IF($C4<>"규정 정답","",IF(COUNTA($F4:$J4)=0,"",IF(IF(COUNTIF($F4:$H4,$D4)>0,1,0)+IF($E4="",0,IF(COUNTIF($F4:$H4,$E4)>0,1,0))>0,1,0))) | L4: =IF($C4<>"규정 정답","",IF(COUNTA($F4:$J4)=0,"",MAX(IFERROR(1/MATCH($D4,$F4:$J4,0),0),IF($E4="",0,IFERROR(1/MATCH($E4,$F4:$J4,0),0))))) | M4: =IF($C4<>"규정 정답","",IF(COUNTA($F4:$J4)=0,"",(IF(COUNTIF($F4:$F4,$D4)>0,1,0)+IF($E4="",0,IF(COUNTIF($F4:$F4,$E4)>0,1,0)))/1)) | N4: =IF($C4<>"규정 정답","",IF(COUNTA($F4:$J4)=0,"",(IF(COUNTIF($F4:$F4,$D4)>0,1,0)+IF($E4="",0,IF(COUNTIF($F4:$F4,$E4)>0,1,0)))/IF($E4="",1,2))) | O4: =IF($C4<>"규정 정답","",IF(COUNTA($F4:$J4)=0,"",IF(M4+N4=0,0,2*M4*N4/(M4+N4)))) | P4: =IF($C4<>"규정 정답","",IF(COUNTA($F4:$J4)=0,"",(IF(COUNTIF($F4:$H4,$D4)>0,1,0)+IF($E4="",0,IF(COUNTIF($F4:$H4,$E4)>0,1,0)))/3)) | Q4: =IF($C4<>"규정 정답","",IF(COUNTA($F4:$J4)=0,"",(IF(COUNTIF($F4:$H4,$D4)>0,1,0)+IF($E4="",0,IF(COUNTIF($F4:$H4,$E4)>0,1,0)))/IF($E4="",1,2))) | R4: =IF($C4<>"규정 정답","",IF(COUNTA($F4:$J4)=0,"",IF(P4+Q4=0,0,2*P4*Q4/(P4+Q4)))) | S4: =IF($C4<>"규정 정답","",IF(COUNTA($F4:$J4)=0,"",(IF(COUNTIF($F4:$J4,$D4)>0,1,0)+IF($E4="",0,IF(COUNTIF($F4:$J4,$E4)>0,1,0)))/5)) | T4: =IF($C4<>"규정 정답","",IF(COUNTA($F4:$J4)=0,"",(IF(COUNTIF($F4:$J4,$D4)>0,1,0)+IF($E4="",0,IF(COUNTIF($F4:$J4,$E4)>0,1,0)))/IF($E4="",1,2))) | U4: =IF($C4<>"규정 정답","",IF(COUNTA($F4:$J4)=0,"",IF(S4+T4=0,0,2*S4*T4/(S4+T4))))
A5: Q04 | B5: 사고통지를 늦게 하면 무조건 15/1000 위약금을 내나? | C5: 코퍼스 밖 | K5: =IF($C5<>"규정 정답","",IF(COUNTA($F5:$J5)=0,"",IF(IF(COUNTIF($F5:$H5,$D5)>0,1,0)+IF($E5="",0,IF(COUNTIF($F5:$H5,$E5)>0,1,0))>0,1,0))) | L5: =IF($C5<>"규정 정답","",IF(COUNTA($F5:$J5)=0,"",MAX(IFERROR(1/MATCH($D5,$F5:$J5,0),0),IF($E5="",0,IFERROR(1/MATCH($E5,$F5:$J5,0),0))))) | M5: =IF($C5<>"규정 정답","",IF(COUNTA($F5:$J5)=0,"",(IF(COUNTIF($F5:$F5,$D5)>0,1,0)+IF($E5="",0,IF(COUNTIF($F5:$F5,$E5)>0,1,0)))/1)) | N5: =IF($C5<>"규정 정답","",IF(COUNTA($F5:$J5)=0,"",(IF(COUNTIF($F5:$F5,$D5)>0,1,0)+IF($E5="",0,IF(COUNTIF($F5:$F5,$E5)>0,1,0)))/IF($E5="",1,2))) | O5: =IF($C5<>"규정 정답","",IF(COUNTA($F5:$J5)=0,"",IF(M5+N5=0,0,2*M5*N5/(M5+N5)))) | P5: =IF($C5<>"규정 정답","",IF(COUNTA($F5:$J5)=0,"",(IF(COUNTIF($F5:$H5,$D5)>0,1,0)+IF($E5="",0,IF(COUNTIF($F5:$H5,$E5)>0,1,0)))/3)) | Q5: =IF($C5<>"규정 정답","",IF(COUNTA($F5:$J5)=0,"",(IF(COUNTIF($F5:$H5,$D5)>0,1,0)+IF($E5="",0,IF(COUNTIF($F5:$H5,$E5)>0,1,0)))/IF($E5="",1,2))) | R5: =IF($C5<>"규정 정답","",IF(COUNTA($F5:$J5)=0,"",IF(P5+Q5=0,0,2*P5*Q5/(P5+Q5)))) | S5: =IF($C5<>"규정 정답","",IF(COUNTA($F5:$J5)=0,"",(IF(COUNTIF($F5:$J5,$D5)>0,1,0)+IF($E5="",0,IF(COUNTIF($F5:$J5,$E5)>0,1,0)))/5)) | T5: =IF($C5<>"규정 정답","",IF(COUNTA($F5:$J5)=0,"",(IF(COUNTIF($F5:$J5,$D5)>0,1,0)+IF($E5="",0,IF(COUNTIF($F5:$J5,$E5)>0,1,0)))/IF($E5="",1,2))) | U5: =IF($C5<>"규정 정답","",IF(COUNTA($F5:$J5)=0,"",IF(S5+T5=0,0,2*S5*T5/(S5+T5))))
A6: Q05 | B6: 이전 대금이 결제기일 후 35일째 미결제인 O/A 바이어에게 추가 선적하면? | C6: 코퍼스 밖 | K6: =IF($C6<>"규정 정답","",IF(COUNTA($F6:$J6)=0,"",IF(IF(COUNTIF($F6:$H6,$D6)>0,1,0)+IF($E6="",0,IF(COUNTIF($F6:$H6,$E6)>0,1,0))>0,1,0))) | L6: =IF($C6<>"규정 정답","",IF(COUNTA($F6:$J6)=0,"",MAX(IFERROR(1/MATCH($D6,$F6:$J6,0),0),IF($E6="",0,IFERROR(1/MATCH($E6,$F6:$J6,0),0))))) | M6: =IF($C6<>"규정 정답","",IF(COUNTA($F6:$J6)=0,"",(IF(COUNTIF($F6:$F6,$D6)>0,1,0)+IF($E6="",0,IF(COUNTIF($F6:$F6,$E6)>0,1,0)))/1)) | N6: =IF($C6<>"규정 정답","",IF(COUNTA($F6:$J6)=0,"",(IF(COUNTIF($F6:$F6,$D6)>0,1,0)+IF($E6="",0,IF(COUNTIF($F6:$F6,$E6)>0,1,0)))/IF($E6="",1,2))) | O6: =IF($C6<>"규정 정답","",IF(COUNTA($F6:$J6)=0,"",IF(M6+N6=0,0,2*M6*N6/(M6+N6)))) | P6: =IF($C6<>"규정 정답","",IF(COUNTA($F6:$J6)=0,"",(IF(COUNTIF($F6:$H6,$D6)>0,1,0)+IF($E6="",0,IF(COUNTIF($F6:$H6,$E6)>0,1,0)))/3)) | Q6: =IF($C6<>"규정 정답","",IF(COUNTA($F6:$J6)=0,"",(IF(COUNTIF($F6:$H6,$D6)>0,1,0)+IF($E6="",0,IF(COUNTIF($F6:$H6,$E6)>0,1,0)))/IF($E6="",1,2))) | R6: =IF($C6<>"규정 정답","",IF(COUNTA($F6:$J6)=0,"",IF(P6+Q6=0,0,2*P6*Q6/(P6+Q6)))) | S6: =IF($C6<>"규정 정답","",IF(COUNTA($F6:$J6)=0,"",(IF(COUNTIF($F6:$J6,$D6)>0,1,0)+IF($E6="",0,IF(COUNTIF($F6:$J6,$E6)>0,1,0)))/5)) | T6: =IF($C6<>"규정 정답","",IF(COUNTA($F6:$J6)=0,"",(IF(COUNTIF($F6:$J6,$D6)>0,1,0)+IF($E6="",0,IF(COUNTIF($F6:$J6,$E6)>0,1,0)))/IF($E6="",1,2))) | U6: =IF($C6<>"규정 정답","",IF(COUNTA($F6:$J6)=0,"",IF(S6+T6=0,0,2*S6*T6/(S6+T6))))
A7: Q06 | B7: Q05와 같은 상황인데 신용장(L/C) 거래라면? | C7: 코퍼스 밖 | K7: =IF($C7<>"규정 정답","",IF(COUNTA($F7:$J7)=0,"",IF(IF(COUNTIF($F7:$H7,$D7)>0,1,0)+IF($E7="",0,IF(COUNTIF($F7:$H7,$E7)>0,1,0))>0,1,0))) | L7: =IF($C7<>"규정 정답","",IF(COUNTA($F7:$J7)=0,"",MAX(IFERROR(1/MATCH($D7,$F7:$J7,0),0),IF($E7="",0,IFERROR(1/MATCH($E7,$F7:$J7,0),0))))) | M7: =IF($C7<>"규정 정답","",IF(COUNTA($F7:$J7)=0,"",(IF(COUNTIF($F7:$F7,$D7)>0,1,0)+IF($E7="",0,IF(COUNTIF($F7:$F7,$E7)>0,1,0)))/1)) | N7: =IF($C7<>"규정 정답","",IF(COUNTA($F7:$J7)=0,"",(IF(COUNTIF($F7:$F7,$D7)>0,1,0)+IF($E7="",0,IF(COUNTIF($F7:$F7,$E7)>0,1,0)))/IF($E7="",1,2))) | O7: =IF($C7<>"규정 정답","",IF(COUNTA($F7:$J7)=0,"",IF(M7+N7=0,0,2*M7*N7/(M7+N7)))) | P7: =IF($C7<>"규정 정답","",IF(COUNTA($F7:$J7)=0,"",(IF(COUNTIF($F7:$H7,$D7)>0,1,0)+IF($E7="",0,IF(COUNTIF($F7:$H7,$E7)>0,1,0)))/3)) | Q7: =IF($C7<>"규정 정답","",IF(COUNTA($F7:$J7)=0,"",(IF(COUNTIF($F7:$H7,$D7)>0,1,0)+IF($E7="",0,IF(COUNTIF($F7:$H7,$E7)>0,1,0)))/IF($E7="",1,2))) | R7: =IF($C7<>"규정 정답","",IF(COUNTA($F7:$J7)=0,"",IF(P7+Q7=0,0,2*P7*Q7/(P7+Q7)))) | S7: =IF($C7<>"규정 정답","",IF(COUNTA($F7:$J7)=0,"",(IF(COUNTIF($F7:$J7,$D7)>0,1,0)+IF($E7="",0,IF(COUNTIF($F7:$J7,$E7)>0,1,0)))/5)) | T7: =IF($C7<>"규정 정답","",IF(COUNTA($F7:$J7)=0,"",(IF(COUNTIF($F7:$J7,$D7)>0,1,0)+IF($E7="",0,IF(COUNTIF($F7:$J7,$E7)>0,1,0)))/IF($E7="",1,2))) | U7: =IF($C7<>"규정 정답","",IF(COUNTA($F7:$J7)=0,"",IF(S7+T7=0,0,2*S7*T7/(S7+T7))))
A8: Q07 | B8: 사내 규정상 연체 40일 바이어에게 영업본부장 승인으로 선적해도 되나? | C8: 규정 정답 | D8: HB-27 | K8: =IF($C8<>"규정 정답","",IF(COUNTA($F8:$J8)=0,"",IF(IF(COUNTIF($F8:$H8,$D8)>0,1,0)+IF($E8="",0,IF(COUNTIF($F8:$H8,$E8)>0,1,0))>0,1,0))) | L8: =IF($C8<>"규정 정답","",IF(COUNTA($F8:$J8)=0,"",MAX(IFERROR(1/MATCH($D8,$F8:$J8,0),0),IF($E8="",0,IFERROR(1/MATCH($E8,$F8:$J8,0),0))))) | M8: =IF($C8<>"규정 정답","",IF(COUNTA($F8:$J8)=0,"",(IF(COUNTIF($F8:$F8,$D8)>0,1,0)+IF($E8="",0,IF(COUNTIF($F8:$F8,$E8)>0,1,0)))/1)) | N8: =IF($C8<>"규정 정답","",IF(COUNTA($F8:$J8)=0,"",(IF(COUNTIF($F8:$F8,$D8)>0,1,0)+IF($E8="",0,IF(COUNTIF($F8:$F8,$E8)>0,1,0)))/IF($E8="",1,2))) | O8: =IF($C8<>"규정 정답","",IF(COUNTA($F8:$J8)=0,"",IF(M8+N8=0,0,2*M8*N8/(M8+N8)))) | P8: =IF($C8<>"규정 정답","",IF(COUNTA($F8:$J8)=0,"",(IF(COUNTIF($F8:$H8,$D8)>0,1,0)+IF($E8="",0,IF(COUNTIF($F8:$H8,$E8)>0,1,0)))/3)) | Q8: =IF($C8<>"규정 정답","",IF(COUNTA($F8:$J8)=0,"",(IF(COUNTIF($F8:$H8,$D8)>0,1,0)+IF($E8="",0,IF(COUNTIF($F8:$H8,$E8)>0,1,0)))/IF($E8="",1,2))) | R8: =IF($C8<>"규정 정답","",IF(COUNTA($F8:$J8)=0,"",IF(P8+Q8=0,0,2*P8*Q8/(P8+Q8)))) | S8: =IF($C8<>"규정 정답","",IF(COUNTA($F8:$J8)=0,"",(IF(COUNTIF($F8:$J8,$D8)>0,1,0)+IF($E8="",0,IF(COUNTIF($F8:$J8,$E8)>0,1,0)))/5)) | T8: =IF($C8<>"규정 정답","",IF(COUNTA($F8:$J8)=0,"",(IF(COUNTIF($F8:$J8,$D8)>0,1,0)+IF($E8="",0,IF(COUNTIF($F8:$J8,$E8)>0,1,0)))/IF($E8="",1,2))) | U8: =IF($C8<>"규정 정답","",IF(COUNTA($F8:$J8)=0,"",IF(S8+T8=0,0,2*S8*T8/(S8+T8))))
A9: Q08 | B9: 바이어가 최근 인보이스부터 입금 처리해 달라고 한다. 사내 규정상 가능한가? | C9: 규정 정답 | D9: HB-21 | K9: =IF($C9<>"규정 정답","",IF(COUNTA($F9:$J9)=0,"",IF(IF(COUNTIF($F9:$H9,$D9)>0,1,0)+IF($E9="",0,IF(COUNTIF($F9:$H9,$E9)>0,1,0))>0,1,0))) | L9: =IF($C9<>"규정 정답","",IF(COUNTA($F9:$J9)=0,"",MAX(IFERROR(1/MATCH($D9,$F9:$J9,0),0),IF($E9="",0,IFERROR(1/MATCH($E9,$F9:$J9,0),0))))) | M9: =IF($C9<>"규정 정답","",IF(COUNTA($F9:$J9)=0,"",(IF(COUNTIF($F9:$F9,$D9)>0,1,0)+IF($E9="",0,IF(COUNTIF($F9:$F9,$E9)>0,1,0)))/1)) | N9: =IF($C9<>"규정 정답","",IF(COUNTA($F9:$J9)=0,"",(IF(COUNTIF($F9:$F9,$D9)>0,1,0)+IF($E9="",0,IF(COUNTIF($F9:$F9,$E9)>0,1,0)))/IF($E9="",1,2))) | O9: =IF($C9<>"규정 정답","",IF(COUNTA($F9:$J9)=0,"",IF(M9+N9=0,0,2*M9*N9/(M9+N9)))) | P9: =IF($C9<>"규정 정답","",IF(COUNTA($F9:$J9)=0,"",(IF(COUNTIF($F9:$H9,$D9)>0,1,0)+IF($E9="",0,IF(COUNTIF($F9:$H9,$E9)>0,1,0)))/3)) | Q9: =IF($C9<>"규정 정답","",IF(COUNTA($F9:$J9)=0,"",(IF(COUNTIF($F9:$H9,$D9)>0,1,0)+IF($E9="",0,IF(COUNTIF($F9:$H9,$E9)>0,1,0)))/IF($E9="",1,2))) | R9: =IF($C9<>"규정 정답","",IF(COUNTA($F9:$J9)=0,"",IF(P9+Q9=0,0,2*P9*Q9/(P9+Q9)))) | S9: =IF($C9<>"규정 정답","",IF(COUNTA($F9:$J9)=0,"",(IF(COUNTIF($F9:$J9,$D9)>0,1,0)+IF($E9="",0,IF(COUNTIF($F9:$J9,$E9)>0,1,0)))/5)) | T9: =IF($C9<>"규정 정답","",IF(COUNTA($F9:$J9)=0,"",(IF(COUNTIF($F9:$J9,$D9)>0,1,0)+IF($E9="",0,IF(COUNTIF($F9:$J9,$E9)>0,1,0)))/IF($E9="",1,2))) | U9: =IF($C9<>"규정 정답","",IF(COUNTA($F9:$J9)=0,"",IF(S9+T9=0,0,2*S9*T9/(S9+T9))))
A10: Q09 | B10: 바이어의 Chapter 11 신청 뉴스를 본 뒤 선적한 건도 보상되나? | C10: 규정 정답 | D10: HB-20 | K10: =IF($C10<>"규정 정답","",IF(COUNTA($F10:$J10)=0,"",IF(IF(COUNTIF($F10:$H10,$D10)>0,1,0)+IF($E10="",0,IF(COUNTIF($F10:$H10,$E10)>0,1,0))>0,1,0))) | L10: =IF($C10<>"규정 정답","",IF(COUNTA($F10:$J10)=0,"",MAX(IFERROR(1/MATCH($D10,$F10:$J10,0),0),IF($E10="",0,IFERROR(1/MATCH($E10,$F10:$J10,0),0))))) | M10: =IF($C10<>"규정 정답","",IF(COUNTA($F10:$J10)=0,"",(IF(COUNTIF($F10:$F10,$D10)>0,1,0)+IF($E10="",0,IF(COUNTIF($F10:$F10,$E10)>0,1,0)))/1)) | N10: =IF($C10<>"규정 정답","",IF(COUNTA($F10:$J10)=0,"",(IF(COUNTIF($F10:$F10,$D10)>0,1,0)+IF($E10="",0,IF(COUNTIF($F10:$F10,$E10)>0,1,0)))/IF($E10="",1,2))) | O10: =IF($C10<>"규정 정답","",IF(COUNTA($F10:$J10)=0,"",IF(M10+N10=0,0,2*M10*N10/(M10+N10)))) | P10: =IF($C10<>"규정 정답","",IF(COUNTA($F10:$J10)=0,"",(IF(COUNTIF($F10:$H10,$D10)>0,1,0)+IF($E10="",0,IF(COUNTIF($F10:$H10,$E10)>0,1,0)))/3)) | Q10: =IF($C10<>"규정 정답","",IF(COUNTA($F10:$J10)=0,"",(IF(COUNTIF($F10:$H10,$D10)>0,1,0)+IF($E10="",0,IF(COUNTIF($F10:$H10,$E10)>0,1,0)))/IF($E10="",1,2))) | R10: =IF($C10<>"규정 정답","",IF(COUNTA($F10:$J10)=0,"",IF(P10+Q10=0,0,2*P10*Q10/(P10+Q10)))) | S10: =IF($C10<>"규정 정답","",IF(COUNTA($F10:$J10)=0,"",(IF(COUNTIF($F10:$J10,$D10)>0,1,0)+IF($E10="",0,IF(COUNTIF($F10:$J10,$E10)>0,1,0)))/5)) | T10: =IF($C10<>"규정 정답","",IF(COUNTA($F10:$J10)=0,"",(IF(COUNTIF($F10:$J10,$D10)>0,1,0)+IF($E10="",0,IF(COUNTIF($F10:$J10,$E10)>0,1,0)))/IF($E10="",1,2))) | U10: =IF($C10<>"규정 정답","",IF(COUNTA($F10:$J10)=0,"",IF(S10+T10=0,0,2*S10*T10/(S10+T10))))
A11: Q10 | B11: 중소기업이 지급지체 사고로 보험금을 청구할 수 있는 시점은? | C11: 코퍼스 밖 | K11: =IF($C11<>"규정 정답","",IF(COUNTA($F11:$J11)=0,"",IF(IF(COUNTIF($F11:$H11,$D11)>0,1,0)+IF($E11="",0,IF(COUNTIF($F11:$H11,$E11)>0,1,0))>0,1,0))) | L11: =IF($C11<>"규정 정답","",IF(COUNTA($F11:$J11)=0,"",MAX(IFERROR(1/MATCH($D11,$F11:$J11,0),0),IF($E11="",0,IFERROR(1/MATCH($E11,$F11:$J11,0),0))))) | M11: =IF($C11<>"규정 정답","",IF(COUNTA($F11:$J11)=0,"",(IF(COUNTIF($F11:$F11,$D11)>0,1,0)+IF($E11="",0,IF(COUNTIF($F11:$F11,$E11)>0,1,0)))/1)) | N11: =IF($C11<>"규정 정답","",IF(COUNTA($F11:$J11)=0,"",(IF(COUNTIF($F11:$F11,$D11)>0,1,0)+IF($E11="",0,IF(COUNTIF($F11:$F11,$E11)>0,1,0)))/IF($E11="",1,2))) | O11: =IF($C11<>"규정 정답","",IF(COUNTA($F11:$J11)=0,"",IF(M11+N11=0,0,2*M11*N11/(M11+N11)))) | P11: =IF($C11<>"규정 정답","",IF(COUNTA($F11:$J11)=0,"",(IF(COUNTIF($F11:$H11,$D11)>0,1,0)+IF($E11="",0,IF(COUNTIF($F11:$H11,$E11)>0,1,0)))/3)) | Q11: =IF($C11<>"규정 정답","",IF(COUNTA($F11:$J11)=0,"",(IF(COUNTIF($F11:$H11,$D11)>0,1,0)+IF($E11="",0,IF(COUNTIF($F11:$H11,$E11)>0,1,0)))/IF($E11="",1,2))) | R11: =IF($C11<>"규정 정답","",IF(COUNTA($F11:$J11)=0,"",IF(P11+Q11=0,0,2*P11*Q11/(P11+Q11)))) | S11: =IF($C11<>"규정 정답","",IF(COUNTA($F11:$J11)=0,"",(IF(COUNTIF($F11:$J11,$D11)>0,1,0)+IF($E11="",0,IF(COUNTIF($F11:$J11,$E11)>0,1,0)))/5)) | T11: =IF($C11<>"규정 정답","",IF(COUNTA($F11:$J11)=0,"",(IF(COUNTIF($F11:$J11,$D11)>0,1,0)+IF($E11="",0,IF(COUNTIF($F11:$J11,$E11)>0,1,0)))/IF($E11="",1,2))) | U11: =IF($C11<>"규정 정답","",IF(COUNTA($F11:$J11)=0,"",IF(S11+T11=0,0,2*S11*T11/(S11+T11))))
A12: Q11 | B12: 분쟁 등으로 보험금 지급이 늦어질 때 가지급 한도는? | C12: 코퍼스 밖 | K12: =IF($C12<>"규정 정답","",IF(COUNTA($F12:$J12)=0,"",IF(IF(COUNTIF($F12:$H12,$D12)>0,1,0)+IF($E12="",0,IF(COUNTIF($F12:$H12,$E12)>0,1,0))>0,1,0))) | L12: =IF($C12<>"규정 정답","",IF(COUNTA($F12:$J12)=0,"",MAX(IFERROR(1/MATCH($D12,$F12:$J12,0),0),IF($E12="",0,IFERROR(1/MATCH($E12,$F12:$J12,0),0))))) | M12: =IF($C12<>"규정 정답","",IF(COUNTA($F12:$J12)=0,"",(IF(COUNTIF($F12:$F12,$D12)>0,1,0)+IF($E12="",0,IF(COUNTIF($F12:$F12,$E12)>0,1,0)))/1)) | N12: =IF($C12<>"규정 정답","",IF(COUNTA($F12:$J12)=0,"",(IF(COUNTIF($F12:$F12,$D12)>0,1,0)+IF($E12="",0,IF(COUNTIF($F12:$F12,$E12)>0,1,0)))/IF($E12="",1,2))) | O12: =IF($C12<>"규정 정답","",IF(COUNTA($F12:$J12)=0,"",IF(M12+N12=0,0,2*M12*N12/(M12+N12)))) | P12: =IF($C12<>"규정 정답","",IF(COUNTA($F12:$J12)=0,"",(IF(COUNTIF($F12:$H12,$D12)>0,1,0)+IF($E12="",0,IF(COUNTIF($F12:$H12,$E12)>0,1,0)))/3)) | Q12: =IF($C12<>"규정 정답","",IF(COUNTA($F12:$J12)=0,"",(IF(COUNTIF($F12:$H12,$D12)>0,1,0)+IF($E12="",0,IF(COUNTIF($F12:$H12,$E12)>0,1,0)))/IF($E12="",1,2))) | R12: =IF($C12<>"규정 정답","",IF(COUNTA($F12:$J12)=0,"",IF(P12+Q12=0,0,2*P12*Q12/(P12+Q12)))) | S12: =IF($C12<>"규정 정답","",IF(COUNTA($F12:$J12)=0,"",(IF(COUNTIF($F12:$J12,$D12)>0,1,0)+IF($E12="",0,IF(COUNTIF($F12:$J12,$E12)>0,1,0)))/5)) | T12: =IF($C12<>"규정 정답","",IF(COUNTA($F12:$J12)=0,"",(IF(COUNTIF($F12:$J12,$D12)>0,1,0)+IF($E12="",0,IF(COUNTIF($F12:$J12,$E12)>0,1,0)))/IF($E12="",1,2))) | U12: =IF($C12<>"규정 정답","",IF(COUNTA($F12:$J12)=0,"",IF(S12+T12=0,0,2*S12*T12/(S12+T12))))
A13: Q12 | B13: 보험금청구권의 소멸시효는? | C13: 코퍼스 밖 | K13: =IF($C13<>"규정 정답","",IF(COUNTA($F13:$J13)=0,"",IF(IF(COUNTIF($F13:$H13,$D13)>0,1,0)+IF($E13="",0,IF(COUNTIF($F13:$H13,$E13)>0,1,0))>0,1,0))) | L13: =IF($C13<>"규정 정답","",IF(COUNTA($F13:$J13)=0,"",MAX(IFERROR(1/MATCH($D13,$F13:$J13,0),0),IF($E13="",0,IFERROR(1/MATCH($E13,$F13:$J13,0),0))))) | M13: =IF($C13<>"규정 정답","",IF(COUNTA($F13:$J13)=0,"",(IF(COUNTIF($F13:$F13,$D13)>0,1,0)+IF($E13="",0,IF(COUNTIF($F13:$F13,$E13)>0,1,0)))/1)) | N13: =IF($C13<>"규정 정답","",IF(COUNTA($F13:$J13)=0,"",(IF(COUNTIF($F13:$F13,$D13)>0,1,0)+IF($E13="",0,IF(COUNTIF($F13:$F13,$E13)>0,1,0)))/IF($E13="",1,2))) | O13: =IF($C13<>"규정 정답","",IF(COUNTA($F13:$J13)=0,"",IF(M13+N13=0,0,2*M13*N13/(M13+N13)))) | P13: =IF($C13<>"규정 정답","",IF(COUNTA($F13:$J13)=0,"",(IF(COUNTIF($F13:$H13,$D13)>0,1,0)+IF($E13="",0,IF(COUNTIF($F13:$H13,$E13)>0,1,0)))/3)) | Q13: =IF($C13<>"규정 정답","",IF(COUNTA($F13:$J13)=0,"",(IF(COUNTIF($F13:$H13,$D13)>0,1,0)+IF($E13="",0,IF(COUNTIF($F13:$H13,$E13)>0,1,0)))/IF($E13="",1,2))) | R13: =IF($C13<>"규정 정답","",IF(COUNTA($F13:$J13)=0,"",IF(P13+Q13=0,0,2*P13*Q13/(P13+Q13)))) | S13: =IF($C13<>"규정 정답","",IF(COUNTA($F13:$J13)=0,"",(IF(COUNTIF($F13:$J13,$D13)>0,1,0)+IF($E13="",0,IF(COUNTIF($F13:$J13,$E13)>0,1,0)))/5)) | T13: =IF($C13<>"규정 정답","",IF(COUNTA($F13:$J13)=0,"",(IF(COUNTIF($F13:$J13,$D13)>0,1,0)+IF($E13="",0,IF(COUNTIF($F13:$J13,$E13)>0,1,0)))/IF($E13="",1,2))) | U13: =IF($C13<>"규정 정답","",IF(COUNTA($F13:$J13)=0,"",IF(S13+T13=0,0,2*S13*T13/(S13+T13))))
A14: Q13 | B14: 보험금을 받기 전에 일부 회수하면 언제까지 알려야 하나? | C14: 규정 정답 | D14: HB-20 | K14: =IF($C14<>"규정 정답","",IF(COUNTA($F14:$J14)=0,"",IF(IF(COUNTIF($F14:$H14,$D14)>0,1,0)+IF($E14="",0,IF(COUNTIF($F14:$H14,$E14)>0,1,0))>0,1,0))) | L14: =IF($C14<>"규정 정답","",IF(COUNTA($F14:$J14)=0,"",MAX(IFERROR(1/MATCH($D14,$F14:$J14,0),0),IF($E14="",0,IFERROR(1/MATCH($E14,$F14:$J14,0),0))))) | M14: =IF($C14<>"규정 정답","",IF(COUNTA($F14:$J14)=0,"",(IF(COUNTIF($F14:$F14,$D14)>0,1,0)+IF($E14="",0,IF(COUNTIF($F14:$F14,$E14)>0,1,0)))/1)) | N14: =IF($C14<>"규정 정답","",IF(COUNTA($F14:$J14)=0,"",(IF(COUNTIF($F14:$F14,$D14)>0,1,0)+IF($E14="",0,IF(COUNTIF($F14:$F14,$E14)>0,1,0)))/IF($E14="",1,2))) | O14: =IF($C14<>"규정 정답","",IF(COUNTA($F14:$J14)=0,"",IF(M14+N14=0,0,2*M14*N14/(M14+N14)))) | P14: =IF($C14<>"규정 정답","",IF(COUNTA($F14:$J14)=0,"",(IF(COUNTIF($F14:$H14,$D14)>0,1,0)+IF($E14="",0,IF(COUNTIF($F14:$H14,$E14)>0,1,0)))/3)) | Q14: =IF($C14<>"규정 정답","",IF(COUNTA($F14:$J14)=0,"",(IF(COUNTIF($F14:$H14,$D14)>0,1,0)+IF($E14="",0,IF(COUNTIF($F14:$H14,$E14)>0,1,0)))/IF($E14="",1,2))) | R14: =IF($C14<>"규정 정답","",IF(COUNTA($F14:$J14)=0,"",IF(P14+Q14=0,0,2*P14*Q14/(P14+Q14)))) | S14: =IF($C14<>"규정 정답","",IF(COUNTA($F14:$J14)=0,"",(IF(COUNTIF($F14:$J14,$D14)>0,1,0)+IF($E14="",0,IF(COUNTIF($F14:$J14,$E14)>0,1,0)))/5)) | T14: =IF($C14<>"규정 정답","",IF(COUNTA($F14:$J14)=0,"",(IF(COUNTIF($F14:$J14,$D14)>0,1,0)+IF($E14="",0,IF(COUNTIF($F14:$J14,$E14)>0,1,0)))/IF($E14="",1,2))) | U14: =IF($C14<>"규정 정답","",IF(COUNTA($F14:$J14)=0,"",IF(S14+T14=0,0,2*S14*T14/(S14+T14))))
A15: Q14 | B15: 바이어와 결제기일을 60일에서 90일로 연장하기로 했다. K-SURE에 무엇을 해야 하나? | C15: 규정 정답 | D15: HB-20 | K15: =IF($C15<>"규정 정답","",IF(COUNTA($F15:$J15)=0,"",IF(IF(COUNTIF($F15:$H15,$D15)>0,1,0)+IF($E15="",0,IF(COUNTIF($F15:$H15,$E15)>0,1,0))>0,1,0))) | L15: =IF($C15<>"규정 정답","",IF(COUNTA($F15:$J15)=0,"",MAX(IFERROR(1/MATCH($D15,$F15:$J15,0),0),IF($E15="",0,IFERROR(1/MATCH($E15,$F15:$J15,0),0))))) | M15: =IF($C15<>"규정 정답","",IF(COUNTA($F15:$J15)=0,"",(IF(COUNTIF($F15:$F15,$D15)>0,1,0)+IF($E15="",0,IF(COUNTIF($F15:$F15,$E15)>0,1,0)))/1)) | N15: =IF($C15<>"규정 정답","",IF(COUNTA($F15:$J15)=0,"",(IF(COUNTIF($F15:$F15,$D15)>0,1,0)+IF($E15="",0,IF(COUNTIF($F15:$F15,$E15)>0,1,0)))/IF($E15="",1,2))) | O15: =IF($C15<>"규정 정답","",IF(COUNTA($F15:$J15)=0,"",IF(M15+N15=0,0,2*M15*N15/(M15+N15)))) | P15: =IF($C15<>"규정 정답","",IF(COUNTA($F15:$J15)=0,"",(IF(COUNTIF($F15:$H15,$D15)>0,1,0)+IF($E15="",0,IF(COUNTIF($F15:$H15,$E15)>0,1,0)))/3)) | Q15: =IF($C15<>"규정 정답","",IF(COUNTA($F15:$J15)=0,"",(IF(COUNTIF($F15:$H15,$D15)>0,1,0)+IF($E15="",0,IF(COUNTIF($F15:$H15,$E15)>0,1,0)))/IF($E15="",1,2))) | R15: =IF($C15<>"규정 정답","",IF(COUNTA($F15:$J15)=0,"",IF(P15+Q15=0,0,2*P15*Q15/(P15+Q15)))) | S15: =IF($C15<>"규정 정답","",IF(COUNTA($F15:$J15)=0,"",(IF(COUNTIF($F15:$J15,$D15)>0,1,0)+IF($E15="",0,IF(COUNTIF($F15:$J15,$E15)>0,1,0)))/5)) | T15: =IF($C15<>"규정 정답","",IF(COUNTA($F15:$J15)=0,"",(IF(COUNTIF($F15:$J15,$D15)>0,1,0)+IF($E15="",0,IF(COUNTIF($F15:$J15,$E15)>0,1,0)))/IF($E15="",1,2))) | U15: =IF($C15<>"규정 정답","",IF(COUNTA($F15:$J15)=0,"",IF(S15+T15=0,0,2*S15*T15/(S15+T15))))
A16: Q15 | B16: 사내 규정상 C등급 바이어에게 허용되는 결제조건은? | C16: 규정 정답 | D16: HB-10 | K16: =IF($C16<>"규정 정답","",IF(COUNTA($F16:$J16)=0,"",IF(IF(COUNTIF($F16:$H16,$D16)>0,1,0)+IF($E16="",0,IF(COUNTIF($F16:$H16,$E16)>0,1,0))>0,1,0))) | L16: =IF($C16<>"규정 정답","",IF(COUNTA($F16:$J16)=0,"",MAX(IFERROR(1/MATCH($D16,$F16:$J16,0),0),IF($E16="",0,IFERROR(1/MATCH($E16,$F16:$J16,0),0))))) | M16: =IF($C16<>"규정 정답","",IF(COUNTA($F16:$J16)=0,"",(IF(COUNTIF($F16:$F16,$D16)>0,1,0)+IF($E16="",0,IF(COUNTIF($F16:$F16,$E16)>0,1,0)))/1)) | N16: =IF($C16<>"규정 정답","",IF(COUNTA($F16:$J16)=0,"",(IF(COUNTIF($F16:$F16,$D16)>0,1,0)+IF($E16="",0,IF(COUNTIF($F16:$F16,$E16)>0,1,0)))/IF($E16="",1,2))) | O16: =IF($C16<>"규정 정답","",IF(COUNTA($F16:$J16)=0,"",IF(M16+N16=0,0,2*M16*N16/(M16+N16)))) | P16: =IF($C16<>"규정 정답","",IF(COUNTA($F16:$J16)=0,"",(IF(COUNTIF($F16:$H16,$D16)>0,1,0)+IF($E16="",0,IF(COUNTIF($F16:$H16,$E16)>0,1,0)))/3)) | Q16: =IF($C16<>"규정 정답","",IF(COUNTA($F16:$J16)=0,"",(IF(COUNTIF($F16:$H16,$D16)>0,1,0)+IF($E16="",0,IF(COUNTIF($F16:$H16,$E16)>0,1,0)))/IF($E16="",1,2))) | R16: =IF($C16<>"규정 정답","",IF(COUNTA($F16:$J16)=0,"",IF(P16+Q16=0,0,2*P16*Q16/(P16+Q16)))) | S16: =IF($C16<>"규정 정답","",IF(COUNTA($F16:$J16)=0,"",(IF(COUNTIF($F16:$J16,$D16)>0,1,0)+IF($E16="",0,IF(COUNTIF($F16:$J16,$E16)>0,1,0)))/5)) | T16: =IF($C16<>"규정 정답","",IF(COUNTA($F16:$J16)=0,"",(IF(COUNTIF($F16:$J16,$D16)>0,1,0)+IF($E16="",0,IF(COUNTIF($F16:$J16,$E16)>0,1,0)))/IF($E16="",1,2))) | U16: =IF($C16<>"규정 정답","",IF(COUNTA($F16:$J16)=0,"",IF(S16+T16=0,0,2*S16*T16/(S16+T16))))
A17: Q16 | B17: 사내 규정상 바이어 한도 US$150,000 신규 설정의 전결권자는? | C17: 규정 정답 | D17: HB-6 | K17: =IF($C17<>"규정 정답","",IF(COUNTA($F17:$J17)=0,"",IF(IF(COUNTIF($F17:$H17,$D17)>0,1,0)+IF($E17="",0,IF(COUNTIF($F17:$H17,$E17)>0,1,0))>0,1,0))) | L17: =IF($C17<>"규정 정답","",IF(COUNTA($F17:$J17)=0,"",MAX(IFERROR(1/MATCH($D17,$F17:$J17,0),0),IF($E17="",0,IFERROR(1/MATCH($E17,$F17:$J17,0),0))))) | M17: =IF($C17<>"규정 정답","",IF(COUNTA($F17:$J17)=0,"",(IF(COUNTIF($F17:$F17,$D17)>0,1,0)+IF($E17="",0,IF(COUNTIF($F17:$F17,$E17)>0,1,0)))/1)) | N17: =IF($C17<>"규정 정답","",IF(COUNTA($F17:$J17)=0,"",(IF(COUNTIF($F17:$F17,$D17)>0,1,0)+IF($E17="",0,IF(COUNTIF($F17:$F17,$E17)>0,1,0)))/IF($E17="",1,2))) | O17: =IF($C17<>"규정 정답","",IF(COUNTA($F17:$J17)=0,"",IF(M17+N17=0,0,2*M17*N17/(M17+N17)))) | P17: =IF($C17<>"규정 정답","",IF(COUNTA($F17:$J17)=0,"",(IF(COUNTIF($F17:$H17,$D17)>0,1,0)+IF($E17="",0,IF(COUNTIF($F17:$H17,$E17)>0,1,0)))/3)) | Q17: =IF($C17<>"규정 정답","",IF(COUNTA($F17:$J17)=0,"",(IF(COUNTIF($F17:$H17,$D17)>0,1,0)+IF($E17="",0,IF(COUNTIF($F17:$H17,$E17)>0,1,0)))/IF($E17="",1,2))) | R17: =IF($C17<>"규정 정답","",IF(COUNTA($F17:$J17)=0,"",IF(P17+Q17=0,0,2*P17*Q17/(P17+Q17)))) | S17: =IF($C17<>"규정 정답","",IF(COUNTA($F17:$J17)=0,"",(IF(COUNTIF($F17:$J17,$D17)>0,1,0)+IF($E17="",0,IF(COUNTIF($F17:$J17,$E17)>0,1,0)))/5)) | T17: =IF($C17<>"규정 정답","",IF(COUNTA($F17:$J17)=0,"",(IF(COUNTIF($F17:$J17,$D17)>0,1,0)+IF($E17="",0,IF(COUNTIF($F17:$J17,$E17)>0,1,0)))/IF($E17="",1,2))) | U17: =IF($C17<>"규정 정답","",IF(COUNTA($F17:$J17)=0,"",IF(S17+T17=0,0,2*S17*T17/(S17+T17))))
A18: Q17 | B18: 수출채권 대손을 세무상 인정받을 수 있는 K-SURE 관련 사유는? | C18: 규정 정답 | D18: HB-34 | K18: =IF($C18<>"규정 정답","",IF(COUNTA($F18:$J18)=0,"",IF(IF(COUNTIF($F18:$H18,$D18)>0,1,0)+IF($E18="",0,IF(COUNTIF($F18:$H18,$E18)>0,1,0))>0,1,0))) | L18: =IF($C18<>"규정 정답","",IF(COUNTA($F18:$J18)=0,"",MAX(IFERROR(1/MATCH($D18,$F18:$J18,0),0),IF($E18="",0,IFERROR(1/MATCH($E18,$F18:$J18,0),0))))) | M18: =IF($C18<>"규정 정답","",IF(COUNTA($F18:$J18)=0,"",(IF(COUNTIF($F18:$F18,$D18)>0,1,0)+IF($E18="",0,IF(COUNTIF($F18:$F18,$E18)>0,1,0)))/1)) | N18: =IF($C18<>"규정 정답","",IF(COUNTA($F18:$J18)=0,"",(IF(COUNTIF($F18:$F18,$D18)>0,1,0)+IF($E18="",0,IF(COUNTIF($F18:$F18,$E18)>0,1,0)))/IF($E18="",1,2))) | O18: =IF($C18<>"규정 정답","",IF(COUNTA($F18:$J18)=0,"",IF(M18+N18=0,0,2*M18*N18/(M18+N18)))) | P18: =IF($C18<>"규정 정답","",IF(COUNTA($F18:$J18)=0,"",(IF(COUNTIF($F18:$H18,$D18)>0,1,0)+IF($E18="",0,IF(COUNTIF($F18:$H18,$E18)>0,1,0)))/3)) | Q18: =IF($C18<>"규정 정답","",IF(COUNTA($F18:$J18)=0,"",(IF(COUNTIF($F18:$H18,$D18)>0,1,0)+IF($E18="",0,IF(COUNTIF($F18:$H18,$E18)>0,1,0)))/IF($E18="",1,2))) | R18: =IF($C18<>"규정 정답","",IF(COUNTA($F18:$J18)=0,"",IF(P18+Q18=0,0,2*P18*Q18/(P18+Q18)))) | S18: =IF($C18<>"규정 정답","",IF(COUNTA($F18:$J18)=0,"",(IF(COUNTIF($F18:$J18,$D18)>0,1,0)+IF($E18="",0,IF(COUNTIF($F18:$J18,$E18)>0,1,0)))/5)) | T18: =IF($C18<>"규정 정답","",IF(COUNTA($F18:$J18)=0,"",(IF(COUNTIF($F18:$J18,$D18)>0,1,0)+IF($E18="",0,IF(COUNTIF($F18:$J18,$E18)>0,1,0)))/IF($E18="",1,2))) | U18: =IF($C18<>"규정 정답","",IF(COUNTA($F18:$J18)=0,"",IF(S18+T18=0,0,2*S18*T18/(S18+T18))))
A19: Q18 | B19: 중소기업 외상매출금은 회수기일이 얼마나 지나야 대손 사유가 되나? | C19: 규정 정답 | D19: HB-34 | K19: =IF($C19<>"규정 정답","",IF(COUNTA($F19:$J19)=0,"",IF(IF(COUNTIF($F19:$H19,$D19)>0,1,0)+IF($E19="",0,IF(COUNTIF($F19:$H19,$E19)>0,1,0))>0,1,0))) | L19: =IF($C19<>"규정 정답","",IF(COUNTA($F19:$J19)=0,"",MAX(IFERROR(1/MATCH($D19,$F19:$J19,0),0),IF($E19="",0,IFERROR(1/MATCH($E19,$F19:$J19,0),0))))) | M19: =IF($C19<>"규정 정답","",IF(COUNTA($F19:$J19)=0,"",(IF(COUNTIF($F19:$F19,$D19)>0,1,0)+IF($E19="",0,IF(COUNTIF($F19:$F19,$E19)>0,1,0)))/1)) | N19: =IF($C19<>"규정 정답","",IF(COUNTA($F19:$J19)=0,"",(IF(COUNTIF($F19:$F19,$D19)>0,1,0)+IF($E19="",0,IF(COUNTIF($F19:$F19,$E19)>0,1,0)))/IF($E19="",1,2))) | O19: =IF($C19<>"규정 정답","",IF(COUNTA($F19:$J19)=0,"",IF(M19+N19=0,0,2*M19*N19/(M19+N19)))) | P19: =IF($C19<>"규정 정답","",IF(COUNTA($F19:$J19)=0,"",(IF(COUNTIF($F19:$H19,$D19)>0,1,0)+IF($E19="",0,IF(COUNTIF($F19:$H19,$E19)>0,1,0)))/3)) | Q19: =IF($C19<>"규정 정답","",IF(COUNTA($F19:$J19)=0,"",(IF(COUNTIF($F19:$H19,$D19)>0,1,0)+IF($E19="",0,IF(COUNTIF($F19:$H19,$E19)>0,1,0)))/IF($E19="",1,2))) | R19: =IF($C19<>"규정 정답","",IF(COUNTA($F19:$J19)=0,"",IF(P19+Q19=0,0,2*P19*Q19/(P19+Q19)))) | S19: =IF($C19<>"규정 정답","",IF(COUNTA($F19:$J19)=0,"",(IF(COUNTIF($F19:$J19,$D19)>0,1,0)+IF($E19="",0,IF(COUNTIF($F19:$J19,$E19)>0,1,0)))/5)) | T19: =IF($C19<>"규정 정답","",IF(COUNTA($F19:$J19)=0,"",(IF(COUNTIF($F19:$J19,$D19)>0,1,0)+IF($E19="",0,IF(COUNTIF($F19:$J19,$E19)>0,1,0)))/IF($E19="",1,2))) | U19: =IF($C19<>"규정 정답","",IF(COUNTA($F19:$J19)=0,"",IF(S19+T19=0,0,2*S19*T19/(S19+T19))))
A20: Q19 | B20: UCP 600 제14조의 서류심사 기간은? | C20: 기권 | K20: =IF($C20<>"규정 정답","",IF(COUNTA($F20:$J20)=0,"",IF(IF(COUNTIF($F20:$H20,$D20)>0,1,0)+IF($E20="",0,IF(COUNTIF($F20:$H20,$E20)>0,1,0))>0,1,0))) | L20: =IF($C20<>"규정 정답","",IF(COUNTA($F20:$J20)=0,"",MAX(IFERROR(1/MATCH($D20,$F20:$J20,0),0),IF($E20="",0,IFERROR(1/MATCH($E20,$F20:$J20,0),0))))) | M20: =IF($C20<>"규정 정답","",IF(COUNTA($F20:$J20)=0,"",(IF(COUNTIF($F20:$F20,$D20)>0,1,0)+IF($E20="",0,IF(COUNTIF($F20:$F20,$E20)>0,1,0)))/1)) | N20: =IF($C20<>"규정 정답","",IF(COUNTA($F20:$J20)=0,"",(IF(COUNTIF($F20:$F20,$D20)>0,1,0)+IF($E20="",0,IF(COUNTIF($F20:$F20,$E20)>0,1,0)))/IF($E20="",1,2))) | O20: =IF($C20<>"규정 정답","",IF(COUNTA($F20:$J20)=0,"",IF(M20+N20=0,0,2*M20*N20/(M20+N20)))) | P20: =IF($C20<>"규정 정답","",IF(COUNTA($F20:$J20)=0,"",(IF(COUNTIF($F20:$H20,$D20)>0,1,0)+IF($E20="",0,IF(COUNTIF($F20:$H20,$E20)>0,1,0)))/3)) | Q20: =IF($C20<>"규정 정답","",IF(COUNTA($F20:$J20)=0,"",(IF(COUNTIF($F20:$H20,$D20)>0,1,0)+IF($E20="",0,IF(COUNTIF($F20:$H20,$E20)>0,1,0)))/IF($E20="",1,2))) | R20: =IF($C20<>"규정 정답","",IF(COUNTA($F20:$J20)=0,"",IF(P20+Q20=0,0,2*P20*Q20/(P20+Q20)))) | S20: =IF($C20<>"규정 정답","",IF(COUNTA($F20:$J20)=0,"",(IF(COUNTIF($F20:$J20,$D20)>0,1,0)+IF($E20="",0,IF(COUNTIF($F20:$J20,$E20)>0,1,0)))/5)) | T20: =IF($C20<>"규정 정답","",IF(COUNTA($F20:$J20)=0,"",(IF(COUNTIF($F20:$J20,$D20)>0,1,0)+IF($E20="",0,IF(COUNTIF($F20:$J20,$E20)>0,1,0)))/IF($E20="",1,2))) | U20: =IF($C20<>"규정 정답","",IF(COUNTA($F20:$J20)=0,"",IF(S20+T20=0,0,2*S20*T20/(S20+T20))))
A21: Q20 | B21: K-SURE 개별보험에서 B등급 수입자·90일 조건의 보험요율은? | C21: 기권 | K21: =IF($C21<>"규정 정답","",IF(COUNTA($F21:$J21)=0,"",IF(IF(COUNTIF($F21:$H21,$D21)>0,1,0)+IF($E21="",0,IF(COUNTIF($F21:$H21,$E21)>0,1,0))>0,1,0))) | L21: =IF($C21<>"규정 정답","",IF(COUNTA($F21:$J21)=0,"",MAX(IFERROR(1/MATCH($D21,$F21:$J21,0),0),IF($E21="",0,IFERROR(1/MATCH($E21,$F21:$J21,0),0))))) | M21: =IF($C21<>"규정 정답","",IF(COUNTA($F21:$J21)=0,"",(IF(COUNTIF($F21:$F21,$D21)>0,1,0)+IF($E21="",0,IF(COUNTIF($F21:$F21,$E21)>0,1,0)))/1)) | N21: =IF($C21<>"규정 정답","",IF(COUNTA($F21:$J21)=0,"",(IF(COUNTIF($F21:$F21,$D21)>0,1,0)+IF($E21="",0,IF(COUNTIF($F21:$F21,$E21)>0,1,0)))/IF($E21="",1,2))) | O21: =IF($C21<>"규정 정답","",IF(COUNTA($F21:$J21)=0,"",IF(M21+N21=0,0,2*M21*N21/(M21+N21)))) | P21: =IF($C21<>"규정 정답","",IF(COUNTA($F21:$J21)=0,"",(IF(COUNTIF($F21:$H21,$D21)>0,1,0)+IF($E21="",0,IF(COUNTIF($F21:$H21,$E21)>0,1,0)))/3)) | Q21: =IF($C21<>"규정 정답","",IF(COUNTA($F21:$J21)=0,"",(IF(COUNTIF($F21:$H21,$D21)>0,1,0)+IF($E21="",0,IF(COUNTIF($F21:$H21,$E21)>0,1,0)))/IF($E21="",1,2))) | R21: =IF($C21<>"규정 정답","",IF(COUNTA($F21:$J21)=0,"",IF(P21+Q21=0,0,2*P21*Q21/(P21+Q21)))) | S21: =IF($C21<>"규정 정답","",IF(COUNTA($F21:$J21)=0,"",(IF(COUNTIF($F21:$J21,$D21)>0,1,0)+IF($E21="",0,IF(COUNTIF($F21:$J21,$E21)>0,1,0)))/5)) | T21: =IF($C21<>"규정 정답","",IF(COUNTA($F21:$J21)=0,"",(IF(COUNTIF($F21:$J21,$D21)>0,1,0)+IF($E21="",0,IF(COUNTIF($F21:$J21,$E21)>0,1,0)))/IF($E21="",1,2))) | U21: =IF($C21<>"규정 정답","",IF(COUNTA($F21:$J21)=0,"",IF(S21+T21=0,0,2*S21*T21/(S21+T21))))

Sheet eval_B
A1: q_id | B1: question | C1: kind | D1: gold_id1 | E1: gold_id2 | F1: r1 | G1: r2 | H1: r3 | I1: r4 | J1: r5 | K1: hit_at_3 | L1: rr | M1: p_at_1 | N1: r_at_1 | O1: f1_at_1 | P1: p_at_3 | Q1: r_at_3 | R1: f1_at_3 | S1: p_at_5 | T1: r_at_5 | U1: f1_at_5 | W1: ← 실험 후 결과의 r1–r5(20행)를 F2에 값만 붙여 넣는다
A2: Q01 | B2: 중소기업이 단기수출보험(선적후)에 가입하면 부보율은? | C2: 코퍼스 밖 | K2: =IF($C2<>"규정 정답","",IF(COUNTA($F2:$J2)=0,"",IF(IF(COUNTIF($F2:$H2,$D2)>0,1,0)+IF($E2="",0,IF(COUNTIF($F2:$H2,$E2)>0,1,0))>0,1,0))) | L2: =IF($C2<>"규정 정답","",IF(COUNTA($F2:$J2)=0,"",MAX(IFERROR(1/MATCH($D2,$F2:$J2,0),0),IF($E2="",0,IFERROR(1/MATCH($E2,$F2:$J2,0),0))))) | M2: =IF($C2<>"규정 정답","",IF(COUNTA($F2:$J2)=0,"",(IF(COUNTIF($F2:$F2,$D2)>0,1,0)+IF($E2="",0,IF(COUNTIF($F2:$F2,$E2)>0,1,0)))/1)) | N2: =IF($C2<>"규정 정답","",IF(COUNTA($F2:$J2)=0,"",(IF(COUNTIF($F2:$F2,$D2)>0,1,0)+IF($E2="",0,IF(COUNTIF($F2:$F2,$E2)>0,1,0)))/IF($E2="",1,2))) | O2: =IF($C2<>"규정 정답","",IF(COUNTA($F2:$J2)=0,"",IF(M2+N2=0,0,2*M2*N2/(M2+N2)))) | P2: =IF($C2<>"규정 정답","",IF(COUNTA($F2:$J2)=0,"",(IF(COUNTIF($F2:$H2,$D2)>0,1,0)+IF($E2="",0,IF(COUNTIF($F2:$H2,$E2)>0,1,0)))/3)) | Q2: =IF($C2<>"규정 정답","",IF(COUNTA($F2:$J2)=0,"",(IF(COUNTIF($F2:$H2,$D2)>0,1,0)+IF($E2="",0,IF(COUNTIF($F2:$H2,$E2)>0,1,0)))/IF($E2="",1,2))) | R2: =IF($C2<>"규정 정답","",IF(COUNTA($F2:$J2)=0,"",IF(P2+Q2=0,0,2*P2*Q2/(P2+Q2)))) | S2: =IF($C2<>"규정 정답","",IF(COUNTA($F2:$J2)=0,"",(IF(COUNTIF($F2:$J2,$D2)>0,1,0)+IF($E2="",0,IF(COUNTIF($F2:$J2,$E2)>0,1,0)))/5)) | T2: =IF($C2<>"규정 정답","",IF(COUNTA($F2:$J2)=0,"",(IF(COUNTIF($F2:$J2,$D2)>0,1,0)+IF($E2="",0,IF(COUNTIF($F2:$J2,$E2)>0,1,0)))/IF($E2="",1,2))) | U2: =IF($C2<>"규정 정답","",IF(COUNTA($F2:$J2)=0,"",IF(S2+T2=0,0,2*S2*T2/(S2+T2))))
A3: Q02 | B3: 보험금 청구 후 언제까지 지급되나? | C3: 코퍼스 밖 | K3: =IF($C3<>"규정 정답","",IF(COUNTA($F3:$J3)=0,"",IF(IF(COUNTIF($F3:$H3,$D3)>0,1,0)+IF($E3="",0,IF(COUNTIF($F3:$H3,$E3)>0,1,0))>0,1,0))) | L3: =IF($C3<>"규정 정답","",IF(COUNTA($F3:$J3)=0,"",MAX(IFERROR(1/MATCH($D3,$F3:$J3,0),0),IF($E3="",0,IFERROR(1/MATCH($E3,$F3:$J3,0),0))))) | M3: =IF($C3<>"규정 정답","",IF(COUNTA($F3:$J3)=0,"",(IF(COUNTIF($F3:$F3,$D3)>0,1,0)+IF($E3="",0,IF(COUNTIF($F3:$F3,$E3)>0,1,0)))/1)) | N3: =IF($C3<>"규정 정답","",IF(COUNTA($F3:$J3)=0,"",(IF(COUNTIF($F3:$F3,$D3)>0,1,0)+IF($E3="",0,IF(COUNTIF($F3:$F3,$E3)>0,1,0)))/IF($E3="",1,2))) | O3: =IF($C3<>"규정 정답","",IF(COUNTA($F3:$J3)=0,"",IF(M3+N3=0,0,2*M3*N3/(M3+N3)))) | P3: =IF($C3<>"규정 정답","",IF(COUNTA($F3:$J3)=0,"",(IF(COUNTIF($F3:$H3,$D3)>0,1,0)+IF($E3="",0,IF(COUNTIF($F3:$H3,$E3)>0,1,0)))/3)) | Q3: =IF($C3<>"규정 정답","",IF(COUNTA($F3:$J3)=0,"",(IF(COUNTIF($F3:$H3,$D3)>0,1,0)+IF($E3="",0,IF(COUNTIF($F3:$H3,$E3)>0,1,0)))/IF($E3="",1,2))) | R3: =IF($C3<>"규정 정답","",IF(COUNTA($F3:$J3)=0,"",IF(P3+Q3=0,0,2*P3*Q3/(P3+Q3)))) | S3: =IF($C3<>"규정 정답","",IF(COUNTA($F3:$J3)=0,"",(IF(COUNTIF($F3:$J3,$D3)>0,1,0)+IF($E3="",0,IF(COUNTIF($F3:$J3,$E3)>0,1,0)))/5)) | T3: =IF($C3<>"규정 정답","",IF(COUNTA($F3:$J3)=0,"",(IF(COUNTIF($F3:$J3,$D3)>0,1,0)+IF($E3="",0,IF(COUNTIF($F3:$J3,$E3)>0,1,0)))/IF($E3="",1,2))) | U3: =IF($C3<>"규정 정답","",IF(COUNTA($F3:$J3)=0,"",IF(S3+T3=0,0,2*S3*T3/(S3+T3))))
A4: Q03 | B4: 결제기일이 2026-09-15인 O/A 건이 미결제다. 사고발생통지 기한은? | C4: 규정 정답 | D4: HB-20 | K4: =IF($C4<>"규정 정답","",IF(COUNTA($F4:$J4)=0,"",IF(IF(COUNTIF($F4:$H4,$D4)>0,1,0)+IF($E4="",0,IF(COUNTIF($F4:$H4,$E4)>0,1,0))>0,1,0))) | L4: =IF($C4<>"규정 정답","",IF(COUNTA($F4:$J4)=0,"",MAX(IFERROR(1/MATCH($D4,$F4:$J4,0),0),IF($E4="",0,IFERROR(1/MATCH($E4,$F4:$J4,0),0))))) | M4: =IF($C4<>"규정 정답","",IF(COUNTA($F4:$J4)=0,"",(IF(COUNTIF($F4:$F4,$D4)>0,1,0)+IF($E4="",0,IF(COUNTIF($F4:$F4,$E4)>0,1,0)))/1)) | N4: =IF($C4<>"규정 정답","",IF(COUNTA($F4:$J4)=0,"",(IF(COUNTIF($F4:$F4,$D4)>0,1,0)+IF($E4="",0,IF(COUNTIF($F4:$F4,$E4)>0,1,0)))/IF($E4="",1,2))) | O4: =IF($C4<>"규정 정답","",IF(COUNTA($F4:$J4)=0,"",IF(M4+N4=0,0,2*M4*N4/(M4+N4)))) | P4: =IF($C4<>"규정 정답","",IF(COUNTA($F4:$J4)=0,"",(IF(COUNTIF($F4:$H4,$D4)>0,1,0)+IF($E4="",0,IF(COUNTIF($F4:$H4,$E4)>0,1,0)))/3)) | Q4: =IF($C4<>"규정 정답","",IF(COUNTA($F4:$J4)=0,"",(IF(COUNTIF($F4:$H4,$D4)>0,1,0)+IF($E4="",0,IF(COUNTIF($F4:$H4,$E4)>0,1,0)))/IF($E4="",1,2))) | R4: =IF($C4<>"규정 정답","",IF(COUNTA($F4:$J4)=0,"",IF(P4+Q4=0,0,2*P4*Q4/(P4+Q4)))) | S4: =IF($C4<>"규정 정답","",IF(COUNTA($F4:$J4)=0,"",(IF(COUNTIF($F4:$J4,$D4)>0,1,0)+IF($E4="",0,IF(COUNTIF($F4:$J4,$E4)>0,1,0)))/5)) | T4: =IF($C4<>"규정 정답","",IF(COUNTA($F4:$J4)=0,"",(IF(COUNTIF($F4:$J4,$D4)>0,1,0)+IF($E4="",0,IF(COUNTIF($F4:$J4,$E4)>0,1,0)))/IF($E4="",1,2))) | U4: =IF($C4<>"규정 정답","",IF(COUNTA($F4:$J4)=0,"",IF(S4+T4=0,0,2*S4*T4/(S4+T4))))
A5: Q04 | B5: 사고통지를 늦게 하면 무조건 15/1000 위약금을 내나? | C5: 코퍼스 밖 | K5: =IF($C5<>"규정 정답","",IF(COUNTA($F5:$J5)=0,"",IF(IF(COUNTIF($F5:$H5,$D5)>0,1,0)+IF($E5="",0,IF(COUNTIF($F5:$H5,$E5)>0,1,0))>0,1,0))) | L5: =IF($C5<>"규정 정답","",IF(COUNTA($F5:$J5)=0,"",MAX(IFERROR(1/MATCH($D5,$F5:$J5,0),0),IF($E5="",0,IFERROR(1/MATCH($E5,$F5:$J5,0),0))))) | M5: =IF($C5<>"규정 정답","",IF(COUNTA($F5:$J5)=0,"",(IF(COUNTIF($F5:$F5,$D5)>0,1,0)+IF($E5="",0,IF(COUNTIF($F5:$F5,$E5)>0,1,0)))/1)) | N5: =IF($C5<>"규정 정답","",IF(COUNTA($F5:$J5)=0,"",(IF(COUNTIF($F5:$F5,$D5)>0,1,0)+IF($E5="",0,IF(COUNTIF($F5:$F5,$E5)>0,1,0)))/IF($E5="",1,2))) | O5: =IF($C5<>"규정 정답","",IF(COUNTA($F5:$J5)=0,"",IF(M5+N5=0,0,2*M5*N5/(M5+N5)))) | P5: =IF($C5<>"규정 정답","",IF(COUNTA($F5:$J5)=0,"",(IF(COUNTIF($F5:$H5,$D5)>0,1,0)+IF($E5="",0,IF(COUNTIF($F5:$H5,$E5)>0,1,0)))/3)) | Q5: =IF($C5<>"규정 정답","",IF(COUNTA($F5:$J5)=0,"",(IF(COUNTIF($F5:$H5,$D5)>0,1,0)+IF($E5="",0,IF(COUNTIF($F5:$H5,$E5)>0,1,0)))/IF($E5="",1,2))) | R5: =IF($C5<>"규정 정답","",IF(COUNTA($F5:$J5)=0,"",IF(P5+Q5=0,0,2*P5*Q5/(P5+Q5)))) | S5: =IF($C5<>"규정 정답","",IF(COUNTA($F5:$J5)=0,"",(IF(COUNTIF($F5:$J5,$D5)>0,1,0)+IF($E5="",0,IF(COUNTIF($F5:$J5,$E5)>0,1,0)))/5)) | T5: =IF($C5<>"규정 정답","",IF(COUNTA($F5:$J5)=0,"",(IF(COUNTIF($F5:$J5,$D5)>0,1,0)+IF($E5="",0,IF(COUNTIF($F5:$J5,$E5)>0,1,0)))/IF($E5="",1,2))) | U5: =IF($C5<>"규정 정답","",IF(COUNTA($F5:$J5)=0,"",IF(S5+T5=0,0,2*S5*T5/(S5+T5))))
A6: Q05 | B6: 이전 대금이 결제기일 후 35일째 미결제인 O/A 바이어에게 추가 선적하면? | C6: 코퍼스 밖 | K6: =IF($C6<>"규정 정답","",IF(COUNTA($F6:$J6)=0,"",IF(IF(COUNTIF($F6:$H6,$D6)>0,1,0)+IF($E6="",0,IF(COUNTIF($F6:$H6,$E6)>0,1,0))>0,1,0))) | L6: =IF($C6<>"규정 정답","",IF(COUNTA($F6:$J6)=0,"",MAX(IFERROR(1/MATCH($D6,$F6:$J6,0),0),IF($E6="",0,IFERROR(1/MATCH($E6,$F6:$J6,0),0))))) | M6: =IF($C6<>"규정 정답","",IF(COUNTA($F6:$J6)=0,"",(IF(COUNTIF($F6:$F6,$D6)>0,1,0)+IF($E6="",0,IF(COUNTIF($F6:$F6,$E6)>0,1,0)))/1)) | N6: =IF($C6<>"규정 정답","",IF(COUNTA($F6:$J6)=0,"",(IF(COUNTIF($F6:$F6,$D6)>0,1,0)+IF($E6="",0,IF(COUNTIF($F6:$F6,$E6)>0,1,0)))/IF($E6="",1,2))) | O6: =IF($C6<>"규정 정답","",IF(COUNTA($F6:$J6)=0,"",IF(M6+N6=0,0,2*M6*N6/(M6+N6)))) | P6: =IF($C6<>"규정 정답","",IF(COUNTA($F6:$J6)=0,"",(IF(COUNTIF($F6:$H6,$D6)>0,1,0)+IF($E6="",0,IF(COUNTIF($F6:$H6,$E6)>0,1,0)))/3)) | Q6: =IF($C6<>"규정 정답","",IF(COUNTA($F6:$J6)=0,"",(IF(COUNTIF($F6:$H6,$D6)>0,1,0)+IF($E6="",0,IF(COUNTIF($F6:$H6,$E6)>0,1,0)))/IF($E6="",1,2))) | R6: =IF($C6<>"규정 정답","",IF(COUNTA($F6:$J6)=0,"",IF(P6+Q6=0,0,2*P6*Q6/(P6+Q6)))) | S6: =IF($C6<>"규정 정답","",IF(COUNTA($F6:$J6)=0,"",(IF(COUNTIF($F6:$J6,$D6)>0,1,0)+IF($E6="",0,IF(COUNTIF($F6:$J6,$E6)>0,1,0)))/5)) | T6: =IF($C6<>"규정 정답","",IF(COUNTA($F6:$J6)=0,"",(IF(COUNTIF($F6:$J6,$D6)>0,1,0)+IF($E6="",0,IF(COUNTIF($F6:$J6,$E6)>0,1,0)))/IF($E6="",1,2))) | U6: =IF($C6<>"규정 정답","",IF(COUNTA($F6:$J6)=0,"",IF(S6+T6=0,0,2*S6*T6/(S6+T6))))
A7: Q06 | B7: Q05와 같은 상황인데 신용장(L/C) 거래라면? | C7: 코퍼스 밖 | K7: =IF($C7<>"규정 정답","",IF(COUNTA($F7:$J7)=0,"",IF(IF(COUNTIF($F7:$H7,$D7)>0,1,0)+IF($E7="",0,IF(COUNTIF($F7:$H7,$E7)>0,1,0))>0,1,0))) | L7: =IF($C7<>"규정 정답","",IF(COUNTA($F7:$J7)=0,"",MAX(IFERROR(1/MATCH($D7,$F7:$J7,0),0),IF($E7="",0,IFERROR(1/MATCH($E7,$F7:$J7,0),0))))) | M7: =IF($C7<>"규정 정답","",IF(COUNTA($F7:$J7)=0,"",(IF(COUNTIF($F7:$F7,$D7)>0,1,0)+IF($E7="",0,IF(COUNTIF($F7:$F7,$E7)>0,1,0)))/1)) | N7: =IF($C7<>"규정 정답","",IF(COUNTA($F7:$J7)=0,"",(IF(COUNTIF($F7:$F7,$D7)>0,1,0)+IF($E7="",0,IF(COUNTIF($F7:$F7,$E7)>0,1,0)))/IF($E7="",1,2))) | O7: =IF($C7<>"규정 정답","",IF(COUNTA($F7:$J7)=0,"",IF(M7+N7=0,0,2*M7*N7/(M7+N7)))) | P7: =IF($C7<>"규정 정답","",IF(COUNTA($F7:$J7)=0,"",(IF(COUNTIF($F7:$H7,$D7)>0,1,0)+IF($E7="",0,IF(COUNTIF($F7:$H7,$E7)>0,1,0)))/3)) | Q7: =IF($C7<>"규정 정답","",IF(COUNTA($F7:$J7)=0,"",(IF(COUNTIF($F7:$H7,$D7)>0,1,0)+IF($E7="",0,IF(COUNTIF($F7:$H7,$E7)>0,1,0)))/IF($E7="",1,2))) | R7: =IF($C7<>"규정 정답","",IF(COUNTA($F7:$J7)=0,"",IF(P7+Q7=0,0,2*P7*Q7/(P7+Q7)))) | S7: =IF($C7<>"규정 정답","",IF(COUNTA($F7:$J7)=0,"",(IF(COUNTIF($F7:$J7,$D7)>0,1,0)+IF($E7="",0,IF(COUNTIF($F7:$J7,$E7)>0,1,0)))/5)) | T7: =IF($C7<>"규정 정답","",IF(COUNTA($F7:$J7)=0,"",(IF(COUNTIF($F7:$J7,$D7)>0,1,0)+IF($E7="",0,IF(COUNTIF($F7:$J7,$E7)>0,1,0)))/IF($E7="",1,2))) | U7: =IF($C7<>"규정 정답","",IF(COUNTA($F7:$J7)=0,"",IF(S7+T7=0,0,2*S7*T7/(S7+T7))))
A8: Q07 | B8: 사내 규정상 연체 40일 바이어에게 영업본부장 승인으로 선적해도 되나? | C8: 규정 정답 | D8: HB-27 | K8: =IF($C8<>"규정 정답","",IF(COUNTA($F8:$J8)=0,"",IF(IF(COUNTIF($F8:$H8,$D8)>0,1,0)+IF($E8="",0,IF(COUNTIF($F8:$H8,$E8)>0,1,0))>0,1,0))) | L8: =IF($C8<>"규정 정답","",IF(COUNTA($F8:$J8)=0,"",MAX(IFERROR(1/MATCH($D8,$F8:$J8,0),0),IF($E8="",0,IFERROR(1/MATCH($E8,$F8:$J8,0),0))))) | M8: =IF($C8<>"규정 정답","",IF(COUNTA($F8:$J8)=0,"",(IF(COUNTIF($F8:$F8,$D8)>0,1,0)+IF($E8="",0,IF(COUNTIF($F8:$F8,$E8)>0,1,0)))/1)) | N8: =IF($C8<>"규정 정답","",IF(COUNTA($F8:$J8)=0,"",(IF(COUNTIF($F8:$F8,$D8)>0,1,0)+IF($E8="",0,IF(COUNTIF($F8:$F8,$E8)>0,1,0)))/IF($E8="",1,2))) | O8: =IF($C8<>"규정 정답","",IF(COUNTA($F8:$J8)=0,"",IF(M8+N8=0,0,2*M8*N8/(M8+N8)))) | P8: =IF($C8<>"규정 정답","",IF(COUNTA($F8:$J8)=0,"",(IF(COUNTIF($F8:$H8,$D8)>0,1,0)+IF($E8="",0,IF(COUNTIF($F8:$H8,$E8)>0,1,0)))/3)) | Q8: =IF($C8<>"규정 정답","",IF(COUNTA($F8:$J8)=0,"",(IF(COUNTIF($F8:$H8,$D8)>0,1,0)+IF($E8="",0,IF(COUNTIF($F8:$H8,$E8)>0,1,0)))/IF($E8="",1,2))) | R8: =IF($C8<>"규정 정답","",IF(COUNTA($F8:$J8)=0,"",IF(P8+Q8=0,0,2*P8*Q8/(P8+Q8)))) | S8: =IF($C8<>"규정 정답","",IF(COUNTA($F8:$J8)=0,"",(IF(COUNTIF($F8:$J8,$D8)>0,1,0)+IF($E8="",0,IF(COUNTIF($F8:$J8,$E8)>0,1,0)))/5)) | T8: =IF($C8<>"규정 정답","",IF(COUNTA($F8:$J8)=0,"",(IF(COUNTIF($F8:$J8,$D8)>0,1,0)+IF($E8="",0,IF(COUNTIF($F8:$J8,$E8)>0,1,0)))/IF($E8="",1,2))) | U8: =IF($C8<>"규정 정답","",IF(COUNTA($F8:$J8)=0,"",IF(S8+T8=0,0,2*S8*T8/(S8+T8))))
A9: Q08 | B9: 바이어가 최근 인보이스부터 입금 처리해 달라고 한다. 사내 규정상 가능한가? | C9: 규정 정답 | D9: HB-21 | K9: =IF($C9<>"규정 정답","",IF(COUNTA($F9:$J9)=0,"",IF(IF(COUNTIF($F9:$H9,$D9)>0,1,0)+IF($E9="",0,IF(COUNTIF($F9:$H9,$E9)>0,1,0))>0,1,0))) | L9: =IF($C9<>"규정 정답","",IF(COUNTA($F9:$J9)=0,"",MAX(IFERROR(1/MATCH($D9,$F9:$J9,0),0),IF($E9="",0,IFERROR(1/MATCH($E9,$F9:$J9,0),0))))) | M9: =IF($C9<>"규정 정답","",IF(COUNTA($F9:$J9)=0,"",(IF(COUNTIF($F9:$F9,$D9)>0,1,0)+IF($E9="",0,IF(COUNTIF($F9:$F9,$E9)>0,1,0)))/1)) | N9: =IF($C9<>"규정 정답","",IF(COUNTA($F9:$J9)=0,"",(IF(COUNTIF($F9:$F9,$D9)>0,1,0)+IF($E9="",0,IF(COUNTIF($F9:$F9,$E9)>0,1,0)))/IF($E9="",1,2))) | O9: =IF($C9<>"규정 정답","",IF(COUNTA($F9:$J9)=0,"",IF(M9+N9=0,0,2*M9*N9/(M9+N9)))) | P9: =IF($C9<>"규정 정답","",IF(COUNTA($F9:$J9)=0,"",(IF(COUNTIF($F9:$H9,$D9)>0,1,0)+IF($E9="",0,IF(COUNTIF($F9:$H9,$E9)>0,1,0)))/3)) | Q9: =IF($C9<>"규정 정답","",IF(COUNTA($F9:$J9)=0,"",(IF(COUNTIF($F9:$H9,$D9)>0,1,0)+IF($E9="",0,IF(COUNTIF($F9:$H9,$E9)>0,1,0)))/IF($E9="",1,2))) | R9: =IF($C9<>"규정 정답","",IF(COUNTA($F9:$J9)=0,"",IF(P9+Q9=0,0,2*P9*Q9/(P9+Q9)))) | S9: =IF($C9<>"규정 정답","",IF(COUNTA($F9:$J9)=0,"",(IF(COUNTIF($F9:$J9,$D9)>0,1,0)+IF($E9="",0,IF(COUNTIF($F9:$J9,$E9)>0,1,0)))/5)) | T9: =IF($C9<>"규정 정답","",IF(COUNTA($F9:$J9)=0,"",(IF(COUNTIF($F9:$J9,$D9)>0,1,0)+IF($E9="",0,IF(COUNTIF($F9:$J9,$E9)>0,1,0)))/IF($E9="",1,2))) | U9: =IF($C9<>"규정 정답","",IF(COUNTA($F9:$J9)=0,"",IF(S9+T9=0,0,2*S9*T9/(S9+T9))))
A10: Q09 | B10: 바이어의 Chapter 11 신청 뉴스를 본 뒤 선적한 건도 보상되나? | C10: 규정 정답 | D10: HB-20 | K10: =IF($C10<>"규정 정답","",IF(COUNTA($F10:$J10)=0,"",IF(IF(COUNTIF($F10:$H10,$D10)>0,1,0)+IF($E10="",0,IF(COUNTIF($F10:$H10,$E10)>0,1,0))>0,1,0))) | L10: =IF($C10<>"규정 정답","",IF(COUNTA($F10:$J10)=0,"",MAX(IFERROR(1/MATCH($D10,$F10:$J10,0),0),IF($E10="",0,IFERROR(1/MATCH($E10,$F10:$J10,0),0))))) | M10: =IF($C10<>"규정 정답","",IF(COUNTA($F10:$J10)=0,"",(IF(COUNTIF($F10:$F10,$D10)>0,1,0)+IF($E10="",0,IF(COUNTIF($F10:$F10,$E10)>0,1,0)))/1)) | N10: =IF($C10<>"규정 정답","",IF(COUNTA($F10:$J10)=0,"",(IF(COUNTIF($F10:$F10,$D10)>0,1,0)+IF($E10="",0,IF(COUNTIF($F10:$F10,$E10)>0,1,0)))/IF($E10="",1,2))) | O10: =IF($C10<>"규정 정답","",IF(COUNTA($F10:$J10)=0,"",IF(M10+N10=0,0,2*M10*N10/(M10+N10)))) | P10: =IF($C10<>"규정 정답","",IF(COUNTA($F10:$J10)=0,"",(IF(COUNTIF($F10:$H10,$D10)>0,1,0)+IF($E10="",0,IF(COUNTIF($F10:$H10,$E10)>0,1,0)))/3)) | Q10: =IF($C10<>"규정 정답","",IF(COUNTA($F10:$J10)=0,"",(IF(COUNTIF($F10:$H10,$D10)>0,1,0)+IF($E10="",0,IF(COUNTIF($F10:$H10,$E10)>0,1,0)))/IF($E10="",1,2))) | R10: =IF($C10<>"규정 정답","",IF(COUNTA($F10:$J10)=0,"",IF(P10+Q10=0,0,2*P10*Q10/(P10+Q10)))) | S10: =IF($C10<>"규정 정답","",IF(COUNTA($F10:$J10)=0,"",(IF(COUNTIF($F10:$J10,$D10)>0,1,0)+IF($E10="",0,IF(COUNTIF($F10:$J10,$E10)>0,1,0)))/5)) | T10: =IF($C10<>"규정 정답","",IF(COUNTA($F10:$J10)=0,"",(IF(COUNTIF($F10:$J10,$D10)>0,1,0)+IF($E10="",0,IF(COUNTIF($F10:$J10,$E10)>0,1,0)))/IF($E10="",1,2))) | U10: =IF($C10<>"규정 정답","",IF(COUNTA($F10:$J10)=0,"",IF(S10+T10=0,0,2*S10*T10/(S10+T10))))
A11: Q10 | B11: 중소기업이 지급지체 사고로 보험금을 청구할 수 있는 시점은? | C11: 코퍼스 밖 | K11: =IF($C11<>"규정 정답","",IF(COUNTA($F11:$J11)=0,"",IF(IF(COUNTIF($F11:$H11,$D11)>0,1,0)+IF($E11="",0,IF(COUNTIF($F11:$H11,$E11)>0,1,0))>0,1,0))) | L11: =IF($C11<>"규정 정답","",IF(COUNTA($F11:$J11)=0,"",MAX(IFERROR(1/MATCH($D11,$F11:$J11,0),0),IF($E11="",0,IFERROR(1/MATCH($E11,$F11:$J11,0),0))))) | M11: =IF($C11<>"규정 정답","",IF(COUNTA($F11:$J11)=0,"",(IF(COUNTIF($F11:$F11,$D11)>0,1,0)+IF($E11="",0,IF(COUNTIF($F11:$F11,$E11)>0,1,0)))/1)) | N11: =IF($C11<>"규정 정답","",IF(COUNTA($F11:$J11)=0,"",(IF(COUNTIF($F11:$F11,$D11)>0,1,0)+IF($E11="",0,IF(COUNTIF($F11:$F11,$E11)>0,1,0)))/IF($E11="",1,2))) | O11: =IF($C11<>"규정 정답","",IF(COUNTA($F11:$J11)=0,"",IF(M11+N11=0,0,2*M11*N11/(M11+N11)))) | P11: =IF($C11<>"규정 정답","",IF(COUNTA($F11:$J11)=0,"",(IF(COUNTIF($F11:$H11,$D11)>0,1,0)+IF($E11="",0,IF(COUNTIF($F11:$H11,$E11)>0,1,0)))/3)) | Q11: =IF($C11<>"규정 정답","",IF(COUNTA($F11:$J11)=0,"",(IF(COUNTIF($F11:$H11,$D11)>0,1,0)+IF($E11="",0,IF(COUNTIF($F11:$H11,$E11)>0,1,0)))/IF($E11="",1,2))) | R11: =IF($C11<>"규정 정답","",IF(COUNTA($F11:$J11)=0,"",IF(P11+Q11=0,0,2*P11*Q11/(P11+Q11)))) | S11: =IF($C11<>"규정 정답","",IF(COUNTA($F11:$J11)=0,"",(IF(COUNTIF($F11:$J11,$D11)>0,1,0)+IF($E11="",0,IF(COUNTIF($F11:$J11,$E11)>0,1,0)))/5)) | T11: =IF($C11<>"규정 정답","",IF(COUNTA($F11:$J11)=0,"",(IF(COUNTIF($F11:$J11,$D11)>0,1,0)+IF($E11="",0,IF(COUNTIF($F11:$J11,$E11)>0,1,0)))/IF($E11="",1,2))) | U11: =IF($C11<>"규정 정답","",IF(COUNTA($F11:$J11)=0,"",IF(S11+T11=0,0,2*S11*T11/(S11+T11))))
A12: Q11 | B12: 분쟁 등으로 보험금 지급이 늦어질 때 가지급 한도는? | C12: 코퍼스 밖 | K12: =IF($C12<>"규정 정답","",IF(COUNTA($F12:$J12)=0,"",IF(IF(COUNTIF($F12:$H12,$D12)>0,1,0)+IF($E12="",0,IF(COUNTIF($F12:$H12,$E12)>0,1,0))>0,1,0))) | L12: =IF($C12<>"규정 정답","",IF(COUNTA($F12:$J12)=0,"",MAX(IFERROR(1/MATCH($D12,$F12:$J12,0),0),IF($E12="",0,IFERROR(1/MATCH($E12,$F12:$J12,0),0))))) | M12: =IF($C12<>"규정 정답","",IF(COUNTA($F12:$J12)=0,"",(IF(COUNTIF($F12:$F12,$D12)>0,1,0)+IF($E12="",0,IF(COUNTIF($F12:$F12,$E12)>0,1,0)))/1)) | N12: =IF($C12<>"규정 정답","",IF(COUNTA($F12:$J12)=0,"",(IF(COUNTIF($F12:$F12,$D12)>0,1,0)+IF($E12="",0,IF(COUNTIF($F12:$F12,$E12)>0,1,0)))/IF($E12="",1,2))) | O12: =IF($C12<>"규정 정답","",IF(COUNTA($F12:$J12)=0,"",IF(M12+N12=0,0,2*M12*N12/(M12+N12)))) | P12: =IF($C12<>"규정 정답","",IF(COUNTA($F12:$J12)=0,"",(IF(COUNTIF($F12:$H12,$D12)>0,1,0)+IF($E12="",0,IF(COUNTIF($F12:$H12,$E12)>0,1,0)))/3)) | Q12: =IF($C12<>"규정 정답","",IF(COUNTA($F12:$J12)=0,"",(IF(COUNTIF($F12:$H12,$D12)>0,1,0)+IF($E12="",0,IF(COUNTIF($F12:$H12,$E12)>0,1,0)))/IF($E12="",1,2))) | R12: =IF($C12<>"규정 정답","",IF(COUNTA($F12:$J12)=0,"",IF(P12+Q12=0,0,2*P12*Q12/(P12+Q12)))) | S12: =IF($C12<>"규정 정답","",IF(COUNTA($F12:$J12)=0,"",(IF(COUNTIF($F12:$J12,$D12)>0,1,0)+IF($E12="",0,IF(COUNTIF($F12:$J12,$E12)>0,1,0)))/5)) | T12: =IF($C12<>"규정 정답","",IF(COUNTA($F12:$J12)=0,"",(IF(COUNTIF($F12:$J12,$D12)>0,1,0)+IF($E12="",0,IF(COUNTIF($F12:$J12,$E12)>0,1,0)))/IF($E12="",1,2))) | U12: =IF($C12<>"규정 정답","",IF(COUNTA($F12:$J12)=0,"",IF(S12+T12=0,0,2*S12*T12/(S12+T12))))
A13: Q12 | B13: 보험금청구권의 소멸시효는? | C13: 코퍼스 밖 | K13: =IF($C13<>"규정 정답","",IF(COUNTA($F13:$J13)=0,"",IF(IF(COUNTIF($F13:$H13,$D13)>0,1,0)+IF($E13="",0,IF(COUNTIF($F13:$H13,$E13)>0,1,0))>0,1,0))) | L13: =IF($C13<>"규정 정답","",IF(COUNTA($F13:$J13)=0,"",MAX(IFERROR(1/MATCH($D13,$F13:$J13,0),0),IF($E13="",0,IFERROR(1/MATCH($E13,$F13:$J13,0),0))))) | M13: =IF($C13<>"규정 정답","",IF(COUNTA($F13:$J13)=0,"",(IF(COUNTIF($F13:$F13,$D13)>0,1,0)+IF($E13="",0,IF(COUNTIF($F13:$F13,$E13)>0,1,0)))/1)) | N13: =IF($C13<>"규정 정답","",IF(COUNTA($F13:$J13)=0,"",(IF(COUNTIF($F13:$F13,$D13)>0,1,0)+IF($E13="",0,IF(COUNTIF($F13:$F13,$E13)>0,1,0)))/IF($E13="",1,2))) | O13: =IF($C13<>"규정 정답","",IF(COUNTA($F13:$J13)=0,"",IF(M13+N13=0,0,2*M13*N13/(M13+N13)))) | P13: =IF($C13<>"규정 정답","",IF(COUNTA($F13:$J13)=0,"",(IF(COUNTIF($F13:$H13,$D13)>0,1,0)+IF($E13="",0,IF(COUNTIF($F13:$H13,$E13)>0,1,0)))/3)) | Q13: =IF($C13<>"규정 정답","",IF(COUNTA($F13:$J13)=0,"",(IF(COUNTIF($F13:$H13,$D13)>0,1,0)+IF($E13="",0,IF(COUNTIF($F13:$H13,$E13)>0,1,0)))/IF($E13="",1,2))) | R13: =IF($C13<>"규정 정답","",IF(COUNTA($F13:$J13)=0,"",IF(P13+Q13=0,0,2*P13*Q13/(P13+Q13)))) | S13: =IF($C13<>"규정 정답","",IF(COUNTA($F13:$J13)=0,"",(IF(COUNTIF($F13:$J13,$D13)>0,1,0)+IF($E13="",0,IF(COUNTIF($F13:$J13,$E13)>0,1,0)))/5)) | T13: =IF($C13<>"규정 정답","",IF(COUNTA($F13:$J13)=0,"",(IF(COUNTIF($F13:$J13,$D13)>0,1,0)+IF($E13="",0,IF(COUNTIF($F13:$J13,$E13)>0,1,0)))/IF($E13="",1,2))) | U13: =IF($C13<>"규정 정답","",IF(COUNTA($F13:$J13)=0,"",IF(S13+T13=0,0,2*S13*T13/(S13+T13))))
A14: Q13 | B14: 보험금을 받기 전에 일부 회수하면 언제까지 알려야 하나? | C14: 규정 정답 | D14: HB-20 | K14: =IF($C14<>"규정 정답","",IF(COUNTA($F14:$J14)=0,"",IF(IF(COUNTIF($F14:$H14,$D14)>0,1,0)+IF($E14="",0,IF(COUNTIF($F14:$H14,$E14)>0,1,0))>0,1,0))) | L14: =IF($C14<>"규정 정답","",IF(COUNTA($F14:$J14)=0,"",MAX(IFERROR(1/MATCH($D14,$F14:$J14,0),0),IF($E14="",0,IFERROR(1/MATCH($E14,$F14:$J14,0),0))))) | M14: =IF($C14<>"규정 정답","",IF(COUNTA($F14:$J14)=0,"",(IF(COUNTIF($F14:$F14,$D14)>0,1,0)+IF($E14="",0,IF(COUNTIF($F14:$F14,$E14)>0,1,0)))/1)) | N14: =IF($C14<>"규정 정답","",IF(COUNTA($F14:$J14)=0,"",(IF(COUNTIF($F14:$F14,$D14)>0,1,0)+IF($E14="",0,IF(COUNTIF($F14:$F14,$E14)>0,1,0)))/IF($E14="",1,2))) | O14: =IF($C14<>"규정 정답","",IF(COUNTA($F14:$J14)=0,"",IF(M14+N14=0,0,2*M14*N14/(M14+N14)))) | P14: =IF($C14<>"규정 정답","",IF(COUNTA($F14:$J14)=0,"",(IF(COUNTIF($F14:$H14,$D14)>0,1,0)+IF($E14="",0,IF(COUNTIF($F14:$H14,$E14)>0,1,0)))/3)) | Q14: =IF($C14<>"규정 정답","",IF(COUNTA($F14:$J14)=0,"",(IF(COUNTIF($F14:$H14,$D14)>0,1,0)+IF($E14="",0,IF(COUNTIF($F14:$H14,$E14)>0,1,0)))/IF($E14="",1,2))) | R14: =IF($C14<>"규정 정답","",IF(COUNTA($F14:$J14)=0,"",IF(P14+Q14=0,0,2*P14*Q14/(P14+Q14)))) | S14: =IF($C14<>"규정 정답","",IF(COUNTA($F14:$J14)=0,"",(IF(COUNTIF($F14:$J14,$D14)>0,1,0)+IF($E14="",0,IF(COUNTIF($F14:$J14,$E14)>0,1,0)))/5)) | T14: =IF($C14<>"규정 정답","",IF(COUNTA($F14:$J14)=0,"",(IF(COUNTIF($F14:$J14,$D14)>0,1,0)+IF($E14="",0,IF(COUNTIF($F14:$J14,$E14)>0,1,0)))/IF($E14="",1,2))) | U14: =IF($C14<>"규정 정답","",IF(COUNTA($F14:$J14)=0,"",IF(S14+T14=0,0,2*S14*T14/(S14+T14))))
A15: Q14 | B15: 바이어와 결제기일을 60일에서 90일로 연장하기로 했다. K-SURE에 무엇을 해야 하나? | C15: 규정 정답 | D15: HB-20 | K15: =IF($C15<>"규정 정답","",IF(COUNTA($F15:$J15)=0,"",IF(IF(COUNTIF($F15:$H15,$D15)>0,1,0)+IF($E15="",0,IF(COUNTIF($F15:$H15,$E15)>0,1,0))>0,1,0))) | L15: =IF($C15<>"규정 정답","",IF(COUNTA($F15:$J15)=0,"",MAX(IFERROR(1/MATCH($D15,$F15:$J15,0),0),IF($E15="",0,IFERROR(1/MATCH($E15,$F15:$J15,0),0))))) | M15: =IF($C15<>"규정 정답","",IF(COUNTA($F15:$J15)=0,"",(IF(COUNTIF($F15:$F15,$D15)>0,1,0)+IF($E15="",0,IF(COUNTIF($F15:$F15,$E15)>0,1,0)))/1)) | N15: =IF($C15<>"규정 정답","",IF(COUNTA($F15:$J15)=0,"",(IF(COUNTIF($F15:$F15,$D15)>0,1,0)+IF($E15="",0,IF(COUNTIF($F15:$F15,$E15)>0,1,0)))/IF($E15="",1,2))) | O15: =IF($C15<>"규정 정답","",IF(COUNTA($F15:$J15)=0,"",IF(M15+N15=0,0,2*M15*N15/(M15+N15)))) | P15: =IF($C15<>"규정 정답","",IF(COUNTA($F15:$J15)=0,"",(IF(COUNTIF($F15:$H15,$D15)>0,1,0)+IF($E15="",0,IF(COUNTIF($F15:$H15,$E15)>0,1,0)))/3)) | Q15: =IF($C15<>"규정 정답","",IF(COUNTA($F15:$J15)=0,"",(IF(COUNTIF($F15:$H15,$D15)>0,1,0)+IF($E15="",0,IF(COUNTIF($F15:$H15,$E15)>0,1,0)))/IF($E15="",1,2))) | R15: =IF($C15<>"규정 정답","",IF(COUNTA($F15:$J15)=0,"",IF(P15+Q15=0,0,2*P15*Q15/(P15+Q15)))) | S15: =IF($C15<>"규정 정답","",IF(COUNTA($F15:$J15)=0,"",(IF(COUNTIF($F15:$J15,$D15)>0,1,0)+IF($E15="",0,IF(COUNTIF($F15:$J15,$E15)>0,1,0)))/5)) | T15: =IF($C15<>"규정 정답","",IF(COUNTA($F15:$J15)=0,"",(IF(COUNTIF($F15:$J15,$D15)>0,1,0)+IF($E15="",0,IF(COUNTIF($F15:$J15,$E15)>0,1,0)))/IF($E15="",1,2))) | U15: =IF($C15<>"규정 정답","",IF(COUNTA($F15:$J15)=0,"",IF(S15+T15=0,0,2*S15*T15/(S15+T15))))
A16: Q15 | B16: 사내 규정상 C등급 바이어에게 허용되는 결제조건은? | C16: 규정 정답 | D16: HB-10 | K16: =IF($C16<>"규정 정답","",IF(COUNTA($F16:$J16)=0,"",IF(IF(COUNTIF($F16:$H16,$D16)>0,1,0)+IF($E16="",0,IF(COUNTIF($F16:$H16,$E16)>0,1,0))>0,1,0))) | L16: =IF($C16<>"규정 정답","",IF(COUNTA($F16:$J16)=0,"",MAX(IFERROR(1/MATCH($D16,$F16:$J16,0),0),IF($E16="",0,IFERROR(1/MATCH($E16,$F16:$J16,0),0))))) | M16: =IF($C16<>"규정 정답","",IF(COUNTA($F16:$J16)=0,"",(IF(COUNTIF($F16:$F16,$D16)>0,1,0)+IF($E16="",0,IF(COUNTIF($F16:$F16,$E16)>0,1,0)))/1)) | N16: =IF($C16<>"규정 정답","",IF(COUNTA($F16:$J16)=0,"",(IF(COUNTIF($F16:$F16,$D16)>0,1,0)+IF($E16="",0,IF(COUNTIF($F16:$F16,$E16)>0,1,0)))/IF($E16="",1,2))) | O16: =IF($C16<>"규정 정답","",IF(COUNTA($F16:$J16)=0,"",IF(M16+N16=0,0,2*M16*N16/(M16+N16)))) | P16: =IF($C16<>"규정 정답","",IF(COUNTA($F16:$J16)=0,"",(IF(COUNTIF($F16:$H16,$D16)>0,1,0)+IF($E16="",0,IF(COUNTIF($F16:$H16,$E16)>0,1,0)))/3)) | Q16: =IF($C16<>"규정 정답","",IF(COUNTA($F16:$J16)=0,"",(IF(COUNTIF($F16:$H16,$D16)>0,1,0)+IF($E16="",0,IF(COUNTIF($F16:$H16,$E16)>0,1,0)))/IF($E16="",1,2))) | R16: =IF($C16<>"규정 정답","",IF(COUNTA($F16:$J16)=0,"",IF(P16+Q16=0,0,2*P16*Q16/(P16+Q16)))) | S16: =IF($C16<>"규정 정답","",IF(COUNTA($F16:$J16)=0,"",(IF(COUNTIF($F16:$J16,$D16)>0,1,0)+IF($E16="",0,IF(COUNTIF($F16:$J16,$E16)>0,1,0)))/5)) | T16: =IF($C16<>"규정 정답","",IF(COUNTA($F16:$J16)=0,"",(IF(COUNTIF($F16:$J16,$D16)>0,1,0)+IF($E16="",0,IF(COUNTIF($F16:$J16,$E16)>0,1,0)))/IF($E16="",1,2))) | U16: =IF($C16<>"규정 정답","",IF(COUNTA($F16:$J16)=0,"",IF(S16+T16=0,0,2*S16*T16/(S16+T16))))
A17: Q16 | B17: 사내 규정상 바이어 한도 US$150,000 신규 설정의 전결권자는? | C17: 규정 정답 | D17: HB-6 | K17: =IF($C17<>"규정 정답","",IF(COUNTA($F17:$J17)=0,"",IF(IF(COUNTIF($F17:$H17,$D17)>0,1,0)+IF($E17="",0,IF(COUNTIF($F17:$H17,$E17)>0,1,0))>0,1,0))) | L17: =IF($C17<>"규정 정답","",IF(COUNTA($F17:$J17)=0,"",MAX(IFERROR(1/MATCH($D17,$F17:$J17,0),0),IF($E17="",0,IFERROR(1/MATCH($E17,$F17:$J17,0),0))))) | M17: =IF($C17<>"규정 정답","",IF(COUNTA($F17:$J17)=0,"",(IF(COUNTIF($F17:$F17,$D17)>0,1,0)+IF($E17="",0,IF(COUNTIF($F17:$F17,$E17)>0,1,0)))/1)) | N17: =IF($C17<>"규정 정답","",IF(COUNTA($F17:$J17)=0,"",(IF(COUNTIF($F17:$F17,$D17)>0,1,0)+IF($E17="",0,IF(COUNTIF($F17:$F17,$E17)>0,1,0)))/IF($E17="",1,2))) | O17: =IF($C17<>"규정 정답","",IF(COUNTA($F17:$J17)=0,"",IF(M17+N17=0,0,2*M17*N17/(M17+N17)))) | P17: =IF($C17<>"규정 정답","",IF(COUNTA($F17:$J17)=0,"",(IF(COUNTIF($F17:$H17,$D17)>0,1,0)+IF($E17="",0,IF(COUNTIF($F17:$H17,$E17)>0,1,0)))/3)) | Q17: =IF($C17<>"규정 정답","",IF(COUNTA($F17:$J17)=0,"",(IF(COUNTIF($F17:$H17,$D17)>0,1,0)+IF($E17="",0,IF(COUNTIF($F17:$H17,$E17)>0,1,0)))/IF($E17="",1,2))) | R17: =IF($C17<>"규정 정답","",IF(COUNTA($F17:$J17)=0,"",IF(P17+Q17=0,0,2*P17*Q17/(P17+Q17)))) | S17: =IF($C17<>"규정 정답","",IF(COUNTA($F17:$J17)=0,"",(IF(COUNTIF($F17:$J17,$D17)>0,1,0)+IF($E17="",0,IF(COUNTIF($F17:$J17,$E17)>0,1,0)))/5)) | T17: =IF($C17<>"규정 정답","",IF(COUNTA($F17:$J17)=0,"",(IF(COUNTIF($F17:$J17,$D17)>0,1,0)+IF($E17="",0,IF(COUNTIF($F17:$J17,$E17)>0,1,0)))/IF($E17="",1,2))) | U17: =IF($C17<>"규정 정답","",IF(COUNTA($F17:$J17)=0,"",IF(S17+T17=0,0,2*S17*T17/(S17+T17))))
A18: Q17 | B18: 수출채권 대손을 세무상 인정받을 수 있는 K-SURE 관련 사유는? | C18: 규정 정답 | D18: HB-34 | K18: =IF($C18<>"규정 정답","",IF(COUNTA($F18:$J18)=0,"",IF(IF(COUNTIF($F18:$H18,$D18)>0,1,0)+IF($E18="",0,IF(COUNTIF($F18:$H18,$E18)>0,1,0))>0,1,0))) | L18: =IF($C18<>"규정 정답","",IF(COUNTA($F18:$J18)=0,"",MAX(IFERROR(1/MATCH($D18,$F18:$J18,0),0),IF($E18="",0,IFERROR(1/MATCH($E18,$F18:$J18,0),0))))) | M18: =IF($C18<>"규정 정답","",IF(COUNTA($F18:$J18)=0,"",(IF(COUNTIF($F18:$F18,$D18)>0,1,0)+IF($E18="",0,IF(COUNTIF($F18:$F18,$E18)>0,1,0)))/1)) | N18: =IF($C18<>"규정 정답","",IF(COUNTA($F18:$J18)=0,"",(IF(COUNTIF($F18:$F18,$D18)>0,1,0)+IF($E18="",0,IF(COUNTIF($F18:$F18,$E18)>0,1,0)))/IF($E18="",1,2))) | O18: =IF($C18<>"규정 정답","",IF(COUNTA($F18:$J18)=0,"",IF(M18+N18=0,0,2*M18*N18/(M18+N18)))) | P18: =IF($C18<>"규정 정답","",IF(COUNTA($F18:$J18)=0,"",(IF(COUNTIF($F18:$H18,$D18)>0,1,0)+IF($E18="",0,IF(COUNTIF($F18:$H18,$E18)>0,1,0)))/3)) | Q18: =IF($C18<>"규정 정답","",IF(COUNTA($F18:$J18)=0,"",(IF(COUNTIF($F18:$H18,$D18)>0,1,0)+IF($E18="",0,IF(COUNTIF($F18:$H18,$E18)>0,1,0)))/IF($E18="",1,2))) | R18: =IF($C18<>"규정 정답","",IF(COUNTA($F18:$J18)=0,"",IF(P18+Q18=0,0,2*P18*Q18/(P18+Q18)))) | S18: =IF($C18<>"규정 정답","",IF(COUNTA($F18:$J18)=0,"",(IF(COUNTIF($F18:$J18,$D18)>0,1,0)+IF($E18="",0,IF(COUNTIF($F18:$J18,$E18)>0,1,0)))/5)) | T18: =IF($C18<>"규정 정답","",IF(COUNTA($F18:$J18)=0,"",(IF(COUNTIF($F18:$J18,$D18)>0,1,0)+IF($E18="",0,IF(COUNTIF($F18:$J18,$E18)>0,1,0)))/IF($E18="",1,2))) | U18: =IF($C18<>"규정 정답","",IF(COUNTA($F18:$J18)=0,"",IF(S18+T18=0,0,2*S18*T18/(S18+T18))))
A19: Q18 | B19: 중소기업 외상매출금은 회수기일이 얼마나 지나야 대손 사유가 되나? | C19: 규정 정답 | D19: HB-34 | K19: =IF($C19<>"규정 정답","",IF(COUNTA($F19:$J19)=0,"",IF(IF(COUNTIF($F19:$H19,$D19)>0,1,0)+IF($E19="",0,IF(COUNTIF($F19:$H19,$E19)>0,1,0))>0,1,0))) | L19: =IF($C19<>"규정 정답","",IF(COUNTA($F19:$J19)=0,"",MAX(IFERROR(1/MATCH($D19,$F19:$J19,0),0),IF($E19="",0,IFERROR(1/MATCH($E19,$F19:$J19,0),0))))) | M19: =IF($C19<>"규정 정답","",IF(COUNTA($F19:$J19)=0,"",(IF(COUNTIF($F19:$F19,$D19)>0,1,0)+IF($E19="",0,IF(COUNTIF($F19:$F19,$E19)>0,1,0)))/1)) | N19: =IF($C19<>"규정 정답","",IF(COUNTA($F19:$J19)=0,"",(IF(COUNTIF($F19:$F19,$D19)>0,1,0)+IF($E19="",0,IF(COUNTIF($F19:$F19,$E19)>0,1,0)))/IF($E19="",1,2))) | O19: =IF($C19<>"규정 정답","",IF(COUNTA($F19:$J19)=0,"",IF(M19+N19=0,0,2*M19*N19/(M19+N19)))) | P19: =IF($C19<>"규정 정답","",IF(COUNTA($F19:$J19)=0,"",(IF(COUNTIF($F19:$H19,$D19)>0,1,0)+IF($E19="",0,IF(COUNTIF($F19:$H19,$E19)>0,1,0)))/3)) | Q19: =IF($C19<>"규정 정답","",IF(COUNTA($F19:$J19)=0,"",(IF(COUNTIF($F19:$H19,$D19)>0,1,0)+IF($E19="",0,IF(COUNTIF($F19:$H19,$E19)>0,1,0)))/IF($E19="",1,2))) | R19: =IF($C19<>"규정 정답","",IF(COUNTA($F19:$J19)=0,"",IF(P19+Q19=0,0,2*P19*Q19/(P19+Q19)))) | S19: =IF($C19<>"규정 정답","",IF(COUNTA($F19:$J19)=0,"",(IF(COUNTIF($F19:$J19,$D19)>0,1,0)+IF($E19="",0,IF(COUNTIF($F19:$J19,$E19)>0,1,0)))/5)) | T19: =IF($C19<>"규정 정답","",IF(COUNTA($F19:$J19)=0,"",(IF(COUNTIF($F19:$J19,$D19)>0,1,0)+IF($E19="",0,IF(COUNTIF($F19:$J19,$E19)>0,1,0)))/IF($E19="",1,2))) | U19: =IF($C19<>"규정 정답","",IF(COUNTA($F19:$J19)=0,"",IF(S19+T19=0,0,2*S19*T19/(S19+T19))))
A20: Q19 | B20: UCP 600 제14조의 서류심사 기간은? | C20: 기권 | K20: =IF($C20<>"규정 정답","",IF(COUNTA($F20:$J20)=0,"",IF(IF(COUNTIF($F20:$H20,$D20)>0,1,0)+IF($E20="",0,IF(COUNTIF($F20:$H20,$E20)>0,1,0))>0,1,0))) | L20: =IF($C20<>"규정 정답","",IF(COUNTA($F20:$J20)=0,"",MAX(IFERROR(1/MATCH($D20,$F20:$J20,0),0),IF($E20="",0,IFERROR(1/MATCH($E20,$F20:$J20,0),0))))) | M20: =IF($C20<>"규정 정답","",IF(COUNTA($F20:$J20)=0,"",(IF(COUNTIF($F20:$F20,$D20)>0,1,0)+IF($E20="",0,IF(COUNTIF($F20:$F20,$E20)>0,1,0)))/1)) | N20: =IF($C20<>"규정 정답","",IF(COUNTA($F20:$J20)=0,"",(IF(COUNTIF($F20:$F20,$D20)>0,1,0)+IF($E20="",0,IF(COUNTIF($F20:$F20,$E20)>0,1,0)))/IF($E20="",1,2))) | O20: =IF($C20<>"규정 정답","",IF(COUNTA($F20:$J20)=0,"",IF(M20+N20=0,0,2*M20*N20/(M20+N20)))) | P20: =IF($C20<>"규정 정답","",IF(COUNTA($F20:$J20)=0,"",(IF(COUNTIF($F20:$H20,$D20)>0,1,0)+IF($E20="",0,IF(COUNTIF($F20:$H20,$E20)>0,1,0)))/3)) | Q20: =IF($C20<>"규정 정답","",IF(COUNTA($F20:$J20)=0,"",(IF(COUNTIF($F20:$H20,$D20)>0,1,0)+IF($E20="",0,IF(COUNTIF($F20:$H20,$E20)>0,1,0)))/IF($E20="",1,2))) | R20: =IF($C20<>"규정 정답","",IF(COUNTA($F20:$J20)=0,"",IF(P20+Q20=0,0,2*P20*Q20/(P20+Q20)))) | S20: =IF($C20<>"규정 정답","",IF(COUNTA($F20:$J20)=0,"",(IF(COUNTIF($F20:$J20,$D20)>0,1,0)+IF($E20="",0,IF(COUNTIF($F20:$J20,$E20)>0,1,0)))/5)) | T20: =IF($C20<>"규정 정답","",IF(COUNTA($F20:$J20)=0,"",(IF(COUNTIF($F20:$J20,$D20)>0,1,0)+IF($E20="",0,IF(COUNTIF($F20:$J20,$E20)>0,1,0)))/IF($E20="",1,2))) | U20: =IF($C20<>"규정 정답","",IF(COUNTA($F20:$J20)=0,"",IF(S20+T20=0,0,2*S20*T20/(S20+T20))))
